Workbook

Sheet LDC, LS
C1: BAU | D1: BAU | E1: BAU | F1: BAU | G1: BAU | H1: BAU | I1: BAU | J1: BAU | K1: BAU | L1: BAU | M1: BAU | N1: BAU | O1: BAU | P1: BAU | Q1: BAU | R1: BAU | S1: BAU | X1: BAU | Y1: BAU | AD1: BAU | AE1: BAU | AF1: BAU | AG1: BAU | AH1: BAU | AI1: BAU | AJ1: BAU | AK1: BAU | AL1: BAU | AM1: BAU | AN1: BAU | AO1: BAU | AP1: BAU | AQ1: BAU | AR1: BAU | AS1: BAU | AT1: BAU | AU1: BAU | AV1: BAU | AW1: BAU | AX1: BAU | AY1: BAU | AZ1: BAU | BA1: BAU | BB1: BAU | BC1: BAU | BD1: BAU | BE1: BAU | BF1: BAU | BG1: BAU | BH1: BAU
C2: 01_KOR | D2: 02_CHN | E2: 03_JPN | F2: 04_RUS | G2: 05_MNG | H2: 06_PRK | I2: 07_NAM | J2: 08_LAM | K2: 09_WEU | L2: 10_EEU | M2: 11_FSU | N2: 12_MEA | O2: 13_AFR | P2: 14_CPA | Q2: 15_SAS | R2: 16_PAS | S2: 17_PAO | X2: slab | Y2: ulab | AD2: 01_AGRICULT | AE2: 02_COAL | AF2: 03_OIL | AG2: 04_GAS | AH2: 05_MINING | AI2: 06_FOODPRO | AJ2: 07_TEXTILES | AK2: 08_WOODPRO | AL2: 09_PAPERPRO | AM2: 10_PETROLCOAL | AN2: 11_CHEMICAL | AO2: 12_NONMET | AP2: 13_IRONSTL | AQ2: 14_NONFERR | AR2: 15_MACHINE | AS2: 16_TRANSEQ | AT2: 17_OTHERIND | AU2: 18_TnD | AV2: 19_eNuclear | AW2: 20_eCoal | AX2: 21_eGas | AY2: 22_eOil | AZ2: 23_eWind | BA2: 24_eSolar | BB2: 25_eHydro | BC2: 26_eOther | BD2: 27_CONSTRUC | BE2: 28_LTRP | BF2: 29_WTRP | BG2: 30_ATRP | BH2: 31_SER
A3: 01_AGRICULT | B3: 2019 | C3: 0.440175 | D3: 43.5895 | E3: 1.6019 | F3: 1.75284 | G3: 0.033983 | H3: 0.00854196 | I3: 8.6774 | J3: 11.7065 | K3: 11.3611 | L3: 1.69085 | M3: 1.50016 | N3: 6.29866 | O3: 8.97314 | P3: 2.81987 | Q3: 29.2409 | R3: 9.15073 | S3: 1.69772 | V3: 01_KOR | W3: 2019 | X3: 25.5668 | Y3: 36.7789 | Z3: =SUM(X3:Y3) -> 62.3457 | AA3: =SUM(AD3:BH3) -> 62.345767 | AB3: 01_KOR | AC3: 2019 | AD3: 0.440175 | AE3: 0.00165974 | AF3: 0.00070134 | AG3: 0.0003889 | AH3: 0.0766909 | AI3: 0.83691 | AJ3: 0.470144 | AK3: 0.0928994 | AL3: 0.402361 | AM3: 0.0467312 | AN3: 1.85435 | AO3: 0.463743 | AP3: 0.563138 | AQ3: 0.202717 | AR3: 6.61521 | AS3: 1.67099 | AT3: 1.76074 | AU3: 0.238141 | AV3: 0.0548726 | AW3: 0.0348225 | AX3: 0.0140013 | AY3: 0.00612731 | AZ3: 0.00121878 | BA3: 0.00126117 | BB3: 0.000733773 | BC3: 0.00964824 | BD3: 5.71719 | BE3: 1.35888 | BF3: 0.14005 | BG3: 0.181871 | BH3: 39.0874
A4: 02_COAL | B4: 2019 | C4: 0.00165974 | D4: 3.91579 | E4: 0.00082798 | F4: 0.27798 | G4: 0.0171248 | H4: 0.000753945 | I4: 0.551015 | J4: 0.0478805 | K4: 0.154394 | L4: 0.189621 | M4: 0.207522 | N4: 0.00592343 | O4: 0.237505 | P4: 0.0801764 | Q4: 0.554255 | R4: 0.247218 | S4: 0.340665 | V4: 01_KOR | W4: 2020 | X4: 25.6129 | Y4: 36.8452 | Z4: =SUM(X4:Y4) -> 62.4581 | AA4: =SUM(AD4:BH4) -> 62.45807 | AB4: 01_KOR | AC4: 2020 | AD4: 0.447465 | AE4: 0.00139447 | AF4: 0.000703667 | AG4: 0.000280681 | AH4: 0.0797432 | AI4: 0.832721 | AJ4: 0.457258 | AK4: 0.0928648 | AL4: 0.401605 | AM4: 0.0453999 | AN4: 1.85986 | AO4: 0.457906 | AP4: 0.546302 | AQ4: 0.195768 | AR4: 6.63829 | AS4: 1.63623 | AT4: 1.75922 | AU4: 0.235865 | AV4: 0.054484 | AW4: 0.0371968 | AX4: 0.0112144 | AY4: 0.0054789 | AZ4: 0.0012203 | BA4: 0.0012654 | BB4: 0.000735878 | BC4: 0.00938731 | BD4: 5.76175 | BE4: 1.395 | BF4: 0.14268 | BG4: 0.18468 | BH4: 39.1641
A5: 03_OIL | B5: 2019 | C5: 0.00070134 | D5: 0.643703 | E5: 0.00129403 | F5: 0.573652 | G5: 0.000533954 | H5: 5.7828e-06 | I5: 1.43004 | J5: 0.800561 | K5: 0.225663 | L5: 0.0464969 | M5: 0.828935 | N5: 3.89586 | O5: 0.174868 | P5: 0.025074 | Q5: 0.157942 | R5: 0.363669 | S5: 0.0282261 | V5: 01_KOR | W5: 2021 | X5: 25.5776 | Y5: 36.7944 | Z5: =SUM(X5:Y5) -> 62.372 | AA5: =SUM(AD5:BH5) -> 62.371905 | AB5: 01_KOR | AC5: 2021 | AD5: 0.449235 | AE5: 0.00135891 | AF5: 0.000702603 | AG5: 0.000218352 | AH5: 0.080803 | AI5: 0.826286 | AJ5: 0.445067 | AK5: 0.0924487 | AL5: 0.396745 | AM5: 0.0440858 | AN5: 1.84631 | AO5: 0.457208 | AP5: 0.539735 | AQ5: 0.196843 | AR5: 6.61919 | AS5: 1.62635 | AT5: 1.75244 | AU5: 0.234116 | AV5: 0.0540966 | AW5: 0.0373727 | AX5: 0.00913757 | AY5: 0.00473762 | AZ5: 0.00121851 | BA5: 0.00126538 | BB5: 0.000735627 | BC5: 0.0091703 | BD5: 5.81317 | BE5: 1.41925 | BF5: 0.140689 | BG5: 0.184819 | BH5: 39.0871
A6: 04_GAS | B6: 2019 | C6: 0.0003889 | D6: 0.0253322 | E6: 0.0104823 | F6: 0.936983 | G6: 4.12498e-05 | H6: 9.81417e-06 | I6: 1.15656 | J6: 0.263857 | K6: 0.25412 | L6: 0.0498759 | M6: 0.435706 | N6: 1.15267 | O6: 0.0569995 | P6: 0.141865 | Q6: 0.189527 | R6: 0.391953 | S6: 0.230928 | V6: 01_KOR | W6: 2022 | X6: 25.5422 | Y6: 36.7436 | Z6: =SUM(X6:Y6) -> 62.2858 | AA6: =SUM(AD6:BH6) -> 62.285751 | AB6: 01_KOR | AC6: 2022 | AD6: 0.451413 | AE6: 0.0013112 | AF6: 0.000695764 | AG6: 0.000178681 | AH6: 0.081954 | AI6: 0.819354 | AJ6: 0.432992 | AK6: 0.0902492 | AL6: 0.392097 | AM6: 0.0431915 | AN6: 1.82104 | AO6: 0.454102 | AP6: 0.532615 | AQ6: 0.197213 | AR6: 6.58959 | AS6: 1.61598 | AT6: 1.74245 | AU6: 0.225966 | AV6: 0.0551146 | AW6: 0.03686 | AX6: 0.00973613 | AY6: 0.00459137 | AZ6: 0.00123865 | BA6: 0.0012858 | BB6: 0.000747564 | BC6: 0.00930064 | BD6: 5.87904 | BE6: 1.43365 | BF6: 0.13776 | BG6: 0.183834 | BH6: 39.0402
A7: 05_MINING | B7: 2019 | C7: 0.0766909 | D7: 5.01341 | E7: 0.159033 | F7: 0.881809 | G7: 0.0187789 | H7: 0.00662343 | I7: 4.74157 | J7: 1.55128 | K7: 1.24613 | L7: 0.210104 | M7: 0.418168 | N7: 0.939147 | O7: 1.28045 | P7: 0.12207 | Q7: 0.713603 | R7: 0.971427 | S7: 1.31307 | V7: 01_KOR | W7: 2023 | X7: 25.5069 | Y7: 36.6928 | Z7: =SUM(X7:Y7) -> 62.1997 | AA7: =SUM(AD7:BH7) -> 62.199659 | AB7: 01_KOR | AC7: 2023 | AD7: 0.453988 | AE7: 0.0013285 | AF7: 0.000695992 | AG7: 0.000180375 | AH7: 0.0831698 | AI7: 0.812538 | AJ7: 0.422999 | AK7: 0.0885018 | AL7: 0.388231 | AM7: 0.0429761 | AN7: 1.79895 | AO7: 0.451191 | AP7: 0.529836 | AQ7: 0.197466 | AR7: 6.57562 | AS7: 1.61167 | AT7: 1.73452 | AU7: 0.220035 | AV7: 0.0561014 | AW7: 0.036567 | AX7: 0.0109464 | AY7: 0.00475828 | AZ7: 0.00125883 | BA7: 0.0013064 | BB7: 0.00075959 | BC7: 0.0094578 | BD7: 5.94408 | BE7: 1.42949 | BF7: 0.135233 | BG7: 0.182604 | BH7: 38.9732
A8: 06_FOODPRO | B8: 2019 | C8: 0.83691 | D8: 18.598 | E8: 2.69025 | F8: 1.11899 | G8: 0.00302606 | H8: 0.0158267 | I8: 14.32 | J8: 7.61495 | K8: 13.3836 | L8: 1.33125 | M8: 0.620943 | N8: 4.63319 | O8: 7.11826 | P8: 0.30335 | Q8: 4.31589 | R8: 3.88338 | S8: 2.01862 | V8: 01_KOR | W8: 2024 | X8: 25.4716 | Y8: 36.6419 | Z8: =SUM(X8:Y8) -> 62.1135 | AA8: =SUM(AD8:BH8) -> 62.113452 | AB8: 01_KOR | AC8: 2024 | AD8: 0.456729 | AE8: 0.00133038 | AF8: 0.000695906 | AG8: 0.000185692 | AH8: 0.084317 | AI8: 0.806195 | AJ8: 0.414209 | AK8: 0.0869699 | AL8: 0.384637 | AM8: 0.0427497 | AN8: 1.77776 | AO8: 0.448234 | AP8: 0.527152 | AQ8: 0.197669 | AR8: 6.56153 | AS8: 1.60754 | AT8: 1.72748 | AU8: 0.216007 | AV8: 0.0569004 | AW8: 0.0363421 | AX8: 0.0117307 | AY8: 0.00485479 | AZ8: 0.00127668 | BA8: 0.001325 | BB8: 0.000770405 | BC8: 0.00958429 | BD8: 6.00512 | BE8: 1.42547 | BF8: 0.132588 | BG8: 0.181399 | BH8: 38.9047
A9: 07_TEXTILES | B9: 2019 | C9: 0.470144 | D9: 16.9434 | E9: 0.690811 | F9: 0.17021 | G9: 0.00218675 | H9: 0.0165746 | I9: 2.63783 | J9: 3.02333 | K9: 4.93716 | L9: 0.815476 | M9: 0.165806 | N9: 2.27336 | O9: 0.925128 | P9: 2.38194 | Q9: 5.76461 | R9: 1.23344 | S9: 0.130337 | V9: 01_KOR | W9: 2025 | X9: 25.4362 | Y9: 36.5911 | Z9: =SUM(X9:Y9) -> 62.0273 | AA9: =SUM(AD9:BH9) -> 62.027261 | AB9: 01_KOR | AC9: 2025 | AD9: 0.459621 | AE9: 0.00132356 | AF9: 0.000695584 | AG9: 0.000192496 | AH9: 0.085486 | AI9: 0.800293 | AJ9: 0.406346 | AK9: 0.0856131 | AL9: 0.38128 | AM9: 0.0425209 | AN9: 1.75759 | AO9: 0.445274 | AP9: 0.524803 | AQ9: 0.197655 | AR9: 6.5477 | AS9: 1.60382 | AT9: 1.72132 | AU9: 0.213648 | AV9: 0.0574449 | AW9: 0.0361659 | AX9: 0.0121109 | AY9: 0.00489876 | AZ9: 0.00129104 | BA9: 0.00134052 | BB9: 0.000779356 | BC9: 0.00966649 | BD9: 6.06179 | BE9: 1.42167 | BF9: 0.129865 | BG9: 0.180256 | BH9: 38.8348
A10: 08_WOODPRO | B10: 2019 | C10: 0.0928994 | D10: 2.60861 | E10: 0.26078 | F10: 0.169817 | G10: 0.000398777 | H10: 0.00125404 | I10: 2.11606 | J10: 0.809639 | K10: 1.90051 | L10: 0.247871 | M10: 0.0637124 | N10: 0.460689 | O10: 0.341023 | P10: 0.155088 | Q10: 0.15845 | R10: 0.462443 | S10: 0.353197 | V10: 01_KOR | W10: 2026 | X10: 25.385 | Y10: 36.5174 | Z10: =SUM(X10:Y10) -> 61.9024 | AA10: =SUM(AD10:BH10) -> 61.902244 | AB10: 01_KOR | AC10: 2026 | AD10: 0.462015 | AE10: 0.00130768 | AF10: 0.000691252 | AG10: 0.000205935 | AH10: 0.0861013 | AI10: 0.793816 | AJ10: 0.400214 | AK10: 0.0845743 | AL10: 0.377925 | AM10: 0.0421366 | AN10: 1.73438 | AO10: 0.442394 | AP10: 0.521569 | AQ10: 0.197582 | AR10: 6.53994 | AS10: 1.59368 | AT10: 1.71667 | AU10: 0.212539 | AV10: 0.0576136 | AW10: 0.0360897 | AX10: 0.012275 | AY10: 0.00496782 | AZ10: 0.00129971 | BA10: 0.00135082 | BB10: 0.000785191 | BC10: 0.00971622 | BD10: 6.1131 | BE10: 1.4149 | BF10: 0.126347 | BG10: 0.178258 | BH10: 38.7378
A11: 09_PAPERPRO | B11: 2019 | C11: 0.402361 | D11: 5.91946 | E11: 1.45793 | F11: 0.169783 | G11: 5.17363e-09 | H11: 0.00310656 | I11: 6.30131 | J11: 1.57498 | K11: 5.7594 | L11: 0.42776 | M11: 0.0540814 | N11: 0.561953 | O11: 0.337438 | P11: 0.138173 | Q11: 0.7938 | R11: 0.871888 | S11: 0.284235 | V11: 01_KOR | W11: 2027 | X11: 25.3337 | Y11: 36.4436 | Z11: =SUM(X11:Y11) -> 61.7773 | AA11: =SUM(AD11:BH11) -> 61.777216 | AB11: 01_KOR | AC11: 2027 | AD11: 0.4647 | AE11: 0.00129015 | AF11: 0.000687027 | AG11: 0.000216919 | AH11: 0.0870238 | AI11: 0.787777 | AJ11: 0.394409 | AK11: 0.0836452 | AL11: 0.374886 | AM11: 0.0417782 | AN11: 1.71334 | AO11: 0.439476 | AP11: 0.519235 | AQ11: 0.196446 | AR11: 6.53163 | AS11: 1.58557 | AT11: 1.71288 | AU11: 0.211969 | AV11: 0.0576073 | AW11: 0.0360407 | AX11: 0.0122137 | AY11: 0.00501514 | AZ11: 0.00130613 | BA11: 0.00135926 | BB11: 0.000789875 | BC11: 0.00973173 | BD11: 6.1578 | BE11: 1.40899 | BF11: 0.123151 | BG11: 0.176552 | BH11: 38.6397
A12: 10_PETROLCOAL | B12: 2019 | C12: 0.0467312 | D12: 1.09989 | E12: 0.083342 | F12: 0.0637007 | G12: 0.000124296 | H12: 8.22039e-05 | I12: 0.489602 | J12: 0.245588 | K12: 0.262545 | L12: 0.0373025 | M12: 0.120082 | N12: 0.948088 | O12: 0.0592825 | P12: 0.0841938 | Q12: 0.156593 | R12: 0.197508 | S12: 0.0304933 | V12: 01_KOR | W12: 2028 | X12: 25.2825 | Y12: 36.3699 | Z12: =SUM(X12:Y12) -> 61.6524 | AA12: =SUM(AD12:BH12) -> 61.652206 | AB12: 01_KOR | AC12: 2028 | AD12: 0.467572 | AE12: 0.00127253 | AF12: 0.000683025 | AG12: 0.00022502 | AH12: 0.0879975 | AI12: 0.782132 | AJ12: 0.389187 | AK12: 0.082836 | AL12: 0.372079 | AM12: 0.0414383 | AN12: 1.69414 | AO12: 0.436745 | AP12: 0.517357 | AQ12: 0.195335 | AR12: 6.52194 | AS12: 1.57846 | AT12: 1.70985 | AU12: 0.211423 | AV12: 0.0575412 | AW12: 0.036017 | AX12: 0.0120758 | AY12: 0.00505626 | AZ12: 0.00131198 | BA12: 0.00136734 | BB12: 0.000794326 | BC12: 0.00973296 | BD12: 6.19832 | BE12: 1.40389 | BF12: 0.120172 | BG12: 0.175055 | BH12: 38.5402
A13: 11_CHEMICAL | B13: 2019 | C13: 1.85435 | D13: 18.8812 | E13: 3.30516 | F13: 0.465715 | G13: 3.76093e-07 | H13: 0.00386203 | I13: 12.7283 | J13: 4.12578 | K13: 16.1462 | L13: 1.2255 | M13: 0.233895 | N13: 2.36489 | O13: 0.783305 | P13: 0.605672 | Q13: 2.85924 | R13: 2.85847 | S13: 0.753781 | V13: 01_KOR | W13: 2029 | X13: 25.2312 | Y13: 36.2961 | Z13: =SUM(X13:Y13) -> 61.5273 | AA13: =SUM(AD13:BH13) -> 61.527245 | AB13: 01_KOR | AC13: 2029 | AD13: 0.470591 | AE13: 0.00125528 | AF13: 0.000679246 | AG13: 0.000230481 | AH13: 0.0890537 | AI13: 0.776871 | AJ13: 0.384431 | AK13: 0.0821285 | AL13: 0.369491 | AM13: 0.0411115 | AN13: 1.67657 | AO13: 0.434204 | AP13: 0.515959 | AQ13: 0.194216 | AR13: 6.51109 | AS13: 1.57227 | AT13: 1.70745 | AU13: 0.210727 | AV13: 0.0574593 | AW13: 0.0360197 | AX13: 0.0119175 | AY13: 0.0050939 | AZ13: 0.00131794 | BA13: 0.00137572 | BB13: 0.000798922 | BC13: 0.00972822 | BD13: 6.23476 | BE13: 1.39951 | BF13: 0.117393 | BG13: 0.173742 | BH13: 38.4398
A14: 12_NONMET | B14: 2019 | C14: 0.463743 | D14: 12.8771 | E14: 0.99185 | F14: 0.300887 | G14: 0.00109854 | H14: 0.00148075 | I14: 2.72235 | J14: 1.1433 | K14: 3.88593 | L14: 0.387358 | M14: 0.131434 | N14: 1.58032 | O14: 0.258633 | P14: 0.276076 | Q14: 0.754123 | R14: 0.70175 | S14: 0.304018 | V14: 01_KOR | W14: 2030 | X14: 25.1799 | Y14: 36.2224 | Z14: =SUM(X14:Y14) -> 61.4023 | AA14: =SUM(AD14:BH14) -> 61.402233 | AB14: 01_KOR | AC14: 2030 | AD14: 0.473728 | AE14: 0.00123874 | AF14: 0.000675688 | AG14: 0.000233705 | AH14: 0.0901898 | AI14: 0.771961 | AJ14: 0.380083 | AK14: 0.0815093 | AL14: 0.367103 | AM14: 0.040794 | AN14: 1.66049 | AO14: 0.431856 | AP14: 0.515013 | AQ14: 0.19313 | AR14: 6.49925 | AS14: 1.56686 | AT14: 1.7056 | AU14: 0.209863 | AV14: 0.0573793 | AW14: 0.036043 | AX14: 0.0117575 | AY14: 0.0051271 | AZ14: 0.00132427 | BA14: 0.00138462 | BB14: 0.000803805 | BC14: 0.00972079 | BD14: 6.26739 | BE14: 1.39574 | BF14: 0.114794 | BG14: 0.17259 | BH14: 38.3386
... A33: 31_SER | B33: 2019 | C33: 39.0874 | D33: 372.968 | E33: 100.299 | F33: 32.864 | G33: 0.150226 | H33: 0.582145 | I33: 767.622 | J33: 132.605 | K33: 424.867 | L33: 24.1411 | M33: 11.6056 | N33: 66.453 | O33: 45.9478 | P33: 6.1663 | Q33: 81.7552 | R33: 66.5476 | S33: 57.6305 | V33: 01_KOR | W33: 2049 | X33: 23.0925 | Y33: 33.2195 | Z33: =SUM(X33:Y33) -> 56.312 | AA33: =SUM(AD33:BH33) -> 56.311326 | AB33: 01_KOR | AC33: 2049 | AD33: 0.49622 | AE33: 0.000933534 | AF33: 0.000553223 | AG33: 0.00020893 | AH33: 0.100873 | AI33: 0.673582 | AJ33: 0.320108 | AK33: 0.0690394 | AL33: 0.310588 | AM33: 0.0345262 | AN33: 1.33948 | AO33: 0.377837 | AP33: 0.48714 | AQ33: 0.168625 | AR33: 5.84786 | AS33: 1.45906 | AT33: 1.61614 | AU33: 0.189138 | AV33: 0.04706 | AW33: 0.0376721 | AX33: 0.0109155 | AY33: 0.00575027 | AZ33: 0.00125842 | BA33: 0.00137552 | BB33: 0.000790698 | BC33: 0.00847337 | BD33: 6.34447 | BE33: 1.25584 | BF33: 0.072561 | BG33: 0.143147 | BH33: 34.8901
C34: =SUM(C3:C33) -> 62.345767 | D34: =SUM(D3:D33) -> 679.70348 | E34: =SUM(E3:E33) -> 152.55293 | F34: =SUM(F3:F33) -> 51.705614 | G34: =SUM(G3:G33) -> 0.30777153 | H34: =SUM(H3:H33) -> 0.73674037 | I34: =SUM(I3:I33) -> 991.60065 | J34: =SUM(J3:J33) -> 199.64107 | ... S34: =SUM(S3:S33) -> 77.699618 | V34: 01_KOR | W34: 2050 | X34: 22.9484 | Y34: 33.0123 | Z34: =SUM(X34:Y34) -> 55.9607 | AA34: =SUM(AD34:BH34) -> 55.960023 | AB34: 01_KOR | AC34: 2050 | AD34: 0.496033 | AE34: 0.000921946 | AF34: 0.000548082 | AG34: 0.00020613 | AH34: 0.101159 | AI34: 0.668821 | AJ34: 0.317449 | AK34: 0.0684381 | AL34: 0.307766 | AM34: 0.0342196 | AN34: 1.32613 | AO34: 0.374838 | AP34: 0.48492 | AQ34: 0.166978 | AR34: 5.8082 | AS34: 1.45089 | AT34: 1.60869 | AU34: 0.187425 | AV34: 0.0465652 | AW34: 0.0376503 | AX34: 0.0108096 | AY34: 0.00573703 | AZ34: 0.00125352 | BA34: 0.00137328 | BB34: 0.000789002 | BC34: 0.00839954 | BD34: 6.32156 | BE34: 1.24823 | BF34: 0.0711326 | BG34: 0.14189 | BH34: 34.661
C36: BAU | D36: BAU | E36: BAU | F36: BAU | G36: BAU | H36: BAU | I36: BAU | J36: BAU | K36: BAU | L36: BAU | M36: BAU | N36: BAU | O36: BAU | P36: BAU | Q36: BAU | R36: BAU | S36: BAU
C37: 01_KOR | D37: 02_CHN | E37: 03_JPN | F37: 04_RUS | G37: 05_MNG | H37: 06_PRK | I37: 07_NAM | J37: 08_LAM | K37: 09_WEU | L37: 10_EEU | M37: 11_FSU | N37: 12_MEA | O37: 13_AFR | P37: 14_CPA | Q37: 15_SAS | R37: 16_PAS | S37: 17_PAO
A38: slab | B38: 2019 | C38: 25.5668 | D38: 197.832 | E38: 67.9679 | F38: 26.7475 | G38: 0.0955991 | H38: 0.248591 | I38: 609.729 | J38: 92.6998 | K38: 341.372 | L38: 21.9096 | M38: 8.72615 | N38: 50.6086 | O38: 28.7828 | P38: 6.72724 | Q38: 75.274 | R38: 46.865 | S38: 48.5862
A39: ulab | B39: 2019 | C39: 36.7789 | D39: 481.872 | E39: 84.5846 | F39: 24.9581 | G39: 0.212172 | H39: 0.488149 | I39: 381.872 | J39: 106.941 | K39: 265.863 | L39: 18.6701 | M39: 13.0131 | N39: 67.9329 | O39: 47.446 | P39: 10.8222 | Q39: 97.2275 | R39: 65.3741 | S39: 29.1135
C40: =SUM(C38:C39) -> 62.3457 | D40: =SUM(D38:D39) -> 679.704 | E40: =SUM(E38:E39) -> 152.5525 | F40: =SUM(F38:F39) -> 51.7056 | G40: =SUM(G38:G39) -> 0.3077711 | H40: =SUM(H38:H39) -> 0.73674 | I40: =SUM(I38:I39) -> 991.601 | J40: =SUM(J38:J39) -> 199.6408 | ... S40: =SUM(S38:S39) -> 77.6997

Sheet Employment_NEA
A1: Employment by sex, age and economic activity (thousands) | J1: 01_KOR | K1: 02_CHN | L1: 03_JPN | M1: 04_RUS | N1: 05_MNG | O1: 06_PRK | R1: 01_KOR | S1: 02_CHN | T1: 03_JPN | U1: 04_RUS | V1: 05_MNG | W1: 06_PRK | Z1: 01_KOR | AA1: 02_CHN | AB1: 03_JPN | AC1: 04_RUS | AD1: 05_MNG | AE1: 06_PRK
B2: KOR | C2: CHN | D2: JPN | E2: RUS | F2: MNG | G2: PRK | I2: 01_AGRICULT | J2: 0.440175 | K2: 43.5895 | L2: 1.6019 | M2: 1.75284 | N2: 0.033983 | O2: 0.00854196 | Q2: 01_AGRICULT | Y2: 01_AGRICULT | Z2: =B3 -> 1394.918 | AA2: =C3 -> 182943.04 | AB2: =D3 -> 2180.45 | AC2: =E3 -> 4131.296 | AD2: =F3 -> 330.051 | AE2: =G3 -> 6849.6113
A3: A. Agriculture; forestry and fishing | B3: 1394.918 | C3: ='R17'!I3 -> 182943.04 | D3: 2180.45 | E3: 4131.296 | F3: 330.051 | G3: ='R17'!I7 -> 6849.6113 | I3: 02_COAL | J3: 0.00165974 | K3: 3.91579 | L3: 0.00082798 | M3: 0.27798 | N3: 0.0171248 | O3: 0.000753945 | Q3: 02_COAL | R3: =J3/SUM(J$3:J$6) -> 0.02089277 | S3: =K3/SUM(K$3:K$6) -> 0.40796979 | T3: =L3/SUM(L$3:L$6) -> 0.0048240094 | U3: =M3/SUM(M$3:M$6) -> 0.10409583 | V3: =N3/SUM(N$3:N$6) -> 0.46944393 | W3: =O3/SUM(O$3:O$6) -> 0.10198131 | Y3: 02_COAL | Z3: =B$4*R3 -> 0.30298694 | AA3: =$C$4*O37 -> 3842.3183 | AB3: =D$4*T3 -> 0.1102865 | AC3: =E$4*U3 -> 166.58809 | AD3: =F$4*V3 -> 27.191601 | AE3: =$G$4*K37 -> 13.399308
A4: B. Mining and quarrying | B4: 14.502 | C4: ='R17'!J3 -> 230111.23 | D4: 22.862 | E4: 1600.334 | F4: 57.923 | G4: ='R17'!J7 -> 1899.8952 | I4: 03_OIL | J4: 0.00070134 | K4: 0.643703 | L4: 0.00129403 | M4: 0.573652 | N4: 0.000533954 | O4: 5.7828e-06 | Q4: 03_OIL | R4: =J4/SUM(J$3:J$6) -> 0.0088284521 | S4: =K4/SUM(K$3:K$6) -> 0.067064725 | T4: =L4/SUM(L$3:L$6) -> 0.0075393281 | U4: =M4/SUM(M$3:M$6) -> 0.21481682 | V4: =N4/SUM(N$3:N$6) -> 0.014637337 | W4: =O4/SUM(O$3:O$6) -> 0.00078220234 | Y4: 03_OIL | Z4: =B$4*R4 -> 0.12803021 | AA4: =$C$4*O38 -> 631.62525 | AB4: =D$4*T4 -> 0.17236412 | AC4: =E$4*U4 -> 343.77867 | AD4: =F$4*V4 -> 0.84783846 | AE4: =$G$4*K38 -> 0.10277344
A5: C. Manufacturing | B5: 4429.121 | D5: 10606.694 | E5: 9935.694 | F5: 90.255 | I5: 04_GAS | J5: 0.0003889 | K5: 0.0253322 | L5: 0.0104823 | M5: 0.936983 | N5: 4.12498e-05 | O5: 9.81417e-06 | Q5: 04_GAS | R5: =J5/SUM(J$3:J$6) -> 0.0048954644 | S5: =K5/SUM(K$3:K$6) -> 0.002639256 | T5: =L5/SUM(L$3:L$6) -> 0.061072386 | U5: =M5/SUM(M$3:M$6) -> 0.35087424 | V5: =N5/SUM(N$3:N$6) -> 0.0011307851 | W5: =O5/SUM(O$3:O$6) -> 0.0013275 | Y5: 04_GAS | Z5: =B$4*R5 -> 0.070994025 | AA5: =$C$4*O39 -> 24.856894 | AB5: =D$4*T5 -> 1.3962369 | AC5: =E$4*U5 -> 561.51598 | AD5: =F$4*V5 -> 0.065498464 | AE5: =$G$4*K39 -> 0.17442001
A6: D. Electricity; gas, steam and air conditioning supply | B6: 67.916 | D6: 278.508 | E6: 1822.22 | F6: 19.348 | I6: 05_MINING | J6: 0.0766909 | K6: 5.01341 | L6: 0.159033 | M6: 0.881809 | N6: 0.0187789 | O6: 0.00662343 | Q6: 05_MINING | R6: =J6/SUM(J$3:J$6) -> 0.96538331 | S6: =K6/SUM(K$3:K$6) -> 0.52232623 | T6: =L6/SUM(L$3:L$6) -> 0.92656428 | U6: =M6/SUM(M$3:M$6) -> 0.3302131 | V6: =N6/SUM(N$3:N$6) -> 0.51478795 | W6: =O6/SUM(O$3:O$6) -> 0.89590898 | Y6: 05_MINING | Z6: =B$4*R6 -> 13.999989 | AA6: =$C$4*O40 -> 4919.3438 | AB6: =D$4*T6 -> 21.183112 | AC6: =E$4*U6 -> 528.45126 | AD6: =F$4*V6 -> 29.818062 | AE6: =$G$4*K40 -> 117.71334
A7: E. Water supply; sewerage, waste management and remediation activities | B7: 135.117 | D7: 322.791 | E7: 501.995 | F7: 10.786 | I7: 06_FOODPRO | J7: 0.83691 | K7: 18.598 | L7: 2.69025 | M7: 1.11899 | N7: 0.00302606 | O7: 0.0158267 | Q7: 06_FOODPRO | R7: =J7/SUM(J$7:J$18) -> 0.055868739 | S7: =K7/SUM(K$7:K$18) -> 0.12123415 | T7: =L7/SUM(L$7:L$18) -> 0.093236985 | U7: =M7/SUM(M$7:M$18) -> 0.19176902 | V7: =N7/SUM(N$7:N$18) -> 0.19951071 | W7: =O7/SUM(O$7:O$18) -> 0.27915495 | Y7: 06_FOODPRO | Z7: =B$5*R7 -> 247.4494 | AA7: =$C$4*O41 -> 18249.047 | AB7: =D$5*T7 -> 988.93617 | AC7: =E$5*U7 -> 1905.3583 | AD7: =F$5*V7 -> 18.006839 | AE7: =$G$4*K41 -> 281.27627
A8: F. Construction | B8: 2019.588 | D8: 4960.678 | E8: 4842.88 | F8: 68.848 | I8: 07_TEXTILES | J8: 0.470144 | K8: 16.9434 | L8: 0.690811 | M8: 0.17021 | N8: 0.00218675 | O8: 0.0165746 | Q8: 07_TEXTILES | R8: =J8/SUM(J$7:J$18) -> 0.031384919 | S8: =K8/SUM(K$7:K$18) -> 0.11044837 | T8: =L8/SUM(L$7:L$18) -> 0.023941691 | U8: =M8/SUM(M$7:M$18) -> 0.029170059 | V8: =N8/SUM(N$7:N$18) -> 0.14417428 | W8: =O8/SUM(O$7:O$18) -> 0.29234658 | Y8: 07_TEXTILES | Z8: =B$5*R8 -> 139.0076 | AA8: =$C$4*O42 -> 16625.492 | AB8: =D$5*T8 -> 253.94219 | AC8: =E$5*U8 -> 289.82478 | AD8: =F$5*V8 -> 13.01245 | AE8: =$G$4*K42 -> 294.56814
A9: G. Wholesale and retail trade; repair of motor vehicles and motorcycles | B9: 3662.602 | C9: ='R17'!K3 -> 330795.38 | D9: 11080.678 | E9: 10883.44 | F9: 160.405 | G9: ='R17'!K7 -> 6338.7902 | I9: 08_WOODPRO | J9: 0.0928994 | K9: 2.60861 | L9: 0.26078 | M9: 0.169817 | N9: 0.000398777 | O9: 0.00125404 | Q9: 08_WOODPRO | R9: =J9/SUM(J$7:J$18) -> 0.0062015896 | S9: =K9/SUM(K$7:K$18) -> 0.017004657 | T9: =L9/SUM(L$7:L$18) -> 0.0090379485 | U9: =M9/SUM(M$7:M$18) -> 0.029102708 | V9: =N9/SUM(N$7:N$18) -> 0.026291706 | W9: =O9/SUM(O$7:O$18) -> 0.022119044 | Y9: 08_WOODPRO | Z9: =B$5*R9 -> 27.467591 | AA9: =$C$4*O43 -> 2559.6648 | AB9: =D$5*T9 -> 95.862755 | AC9: =E$5*U9 -> 289.1556 | AD9: =F$5*V9 -> 2.3729579 | AE9: =$G$4*K43 -> 22.287128
A10: H. Transportation and storage | B10: 1431.36 | D10: 3723.131 | E10: 6141.016 | F10: 61.123 | I10: 09_PAPERPRO | J10: 0.402361 | K10: 5.91946 | L10: 1.45793 | M10: 0.169783 | N10: 5.17363e-09 | O10: 0.00310656 | Q10: 09_PAPERPRO | R10: =J10/SUM(J$7:J$18) -> 0.026859999 | S10: =K10/SUM(K$7:K$18) -> 0.038586983 | T10: =L10/SUM(L$7:L$18) -> 0.050528017 | U10: =M10/SUM(M$7:M$18) -> 0.029096881 | V10: =N10/SUM(N$7:N$18) -> 3.4110182e-07 | W10: =O10/SUM(O$7:O$18) -> 0.054794214 | Y10: 09_PAPERPRO | Z10: =B$5*R10 -> 118.96619 | AA10: =$C$4*O44 -> 5808.3936 | AB10: =D$5*T10 -> 535.93522 | AC10: =E$5*U10 -> 289.09771 | AD10: =F$5*V10 -> 3.0786145e-05 | AE10: =$G$4*K44 -> 55.2106
A11: I. Accommodation and food service activities | B11: 2303.41 | D11: 4183.713 | E11: 1844.204 | F11: 36.281 | I11: 10_PETROLCOAL | J11: 0.0467312 | K11: 1.09989 | L11: 0.083342 | M11: 0.0637007 | N11: 0.000124296 | O11: 8.22039e-05 | Q11: 10_PETROLCOAL | R11: =J11/SUM(J$7:J$18) -> 0.0031195866 | S11: =K11/SUM(K$7:K$18) -> 0.0071698156 | T11: =L11/SUM(L$7:L$18) -> 0.0028884144 | U11: =M11/SUM(M$7:M$18) -> 0.010916827 | V11: =N11/SUM(N$7:N$18) -> 0.0081949408 | W11: =O11/SUM(O$7:O$18) -> 0.0014499311 | Y11: 10_PETROLCOAL | Z11: =B$5*R11 -> 13.817026 | AA11: =$C$4*O45 -> 1079.2528 | AB11: =D$5*T11 -> 30.636528 | AC11: =E$5*U11 -> 108.46626 | AD11: =F$5*V11 -> 0.73963438 | AE11: =$G$4*K45 -> 1.4609493
A12: J. Information and communication | B12: 860.504 | D12: 3273.18 | E12: 1260.167 | F12: 12.954 | I12: 11_CHEMICAL | J12: 1.85435 | K12: 18.8812 | L12: 3.30516 | M12: 0.465715 | N12: 3.76093e-07 | O12: 0.00386203 | Q12: 11_CHEMICAL | R12: =J12/SUM(J$7:J$18) -> 0.12378893 | S12: =K12/SUM(K$7:K$18) -> 0.12308024 | T12: =L12/SUM(L$7:L$18) -> 0.11454815 | U12: =M12/SUM(M$7:M$18) -> 0.079812785 | V12: =N12/SUM(N$7:N$18) -> 2.4796131e-05 | W12: =O12/SUM(O$7:O$18) -> 0.068119367 | Y12: 11_CHEMICAL | Z12: =B$5*R12 -> 548.27616 | AA12: =$C$4*O46 -> 18526.933 | AB12: =D$5*T12 -> 1214.9772 | AC12: =E$5*U12 -> 792.99541 | AD12: =F$5*V12 -> 0.0022379748 | AE12: =$G$4*K46 -> 68.637011
A13: K. Financial and insurance activities | B13: 799.995 | D13: 1646.138 | E13: 1584.373 | F13: 24.257 | I13: 12_NONMET | J13: 0.463743 | K13: 12.8771 | L13: 0.99185 | M13: 0.300887 | N13: 0.00109854 | O13: 0.00148075 | Q13: 12_NONMET | R13: =J13/SUM(J$7:J$18) -> 0.030957614 | S13: =K13/SUM(K$7:K$18) -> 0.083941514 | T13: =L13/SUM(L$7:L$18) -> 0.034374911 | U13: =M13/SUM(M$7:M$18) -> 0.051565076 | V13: =N13/SUM(N$7:N$18) -> 0.072427675 | W13: =O13/SUM(O$7:O$18) -> 0.026117806 | Y13: 12_NONMET | Z13: =B$5*R13 -> 137.11502 | AA13: =$C$4*O47 -> 12635.488 | AB13: =D$5*T13 -> 364.60416 | AC13: =E$5*U13 -> 512.33482 | AD13: =F$5*V13 -> 6.5369598 | AE13: =$G$4*K47 -> 26.316278
A14: L. Real estate activities | B14: 555.727 | D14: 997.422 | E14: 1202.817 | F14: 1.154 | I14: 13_IRONSTL | J14: 0.563138 | K14: 6.63222 | L14: 1.17628 | M14: 0.20992 | N14: 1.58685e-05 | O14: 0.000546032 | Q14: 13_IRONSTL | R14: =J14/SUM(J$7:J$18) -> 0.037592824 | S14: =K14/SUM(K$7:K$18) -> 0.043233227 | T14: =L14/SUM(L$7:L$18) -> 0.040766769 | U14: =M14/SUM(M$7:M$18) -> 0.035975435 | V14: =N14/SUM(N$7:N$18) -> 0.0010462237 | W14: =O14/SUM(O$7:O$18) -> 0.009631037 | Y14: 13_IRONSTL | Z14: =B$5*R14 -> 166.50316 | AA14: =$C$4*O48 -> 6507.7802 | AB14: =D$5*T14 -> 432.40065 | AC14: =E$5*U14 -> 357.44092 | AD14: =F$5*V14 -> 0.094426918 | AE14: =$G$4*K48 -> 9.7042241
A15: M. Professional, scientific and technical activities | B15: 1156.684 | D15: 1697.019 | E15: 2296.913 | F15: 18.031 | I15: 14_NONFERR | J15: 0.202717 | K15: 4.56739 | L15: 0.80436 | M15: 0.294704 | N15: 0.00787533 | O15: 0.000118381 | Q15: 14_NONFERR | R15: =J15/SUM(J$7:J$18) -> 0.01353257 | S15: =K15/SUM(K$7:K$18) -> 0.02977329 | T15: =L15/SUM(L$7:L$18) -> 0.027877001 | U15: =M15/SUM(M$7:M$18) -> 0.050505453 | V15: =N15/SUM(N$7:N$18) -> 0.51922719 | W15: =O15/SUM(O$7:O$18) -> 0.0020880311 | Y15: 14_NONFERR | Z15: =B$5*R15 -> 59.93739 | AA15: =$C$4*O49 -> 4481.6924 | AB15: =D$5*T15 -> 295.68282 | AC15: =E$5*U15 -> 501.80673 | AD15: =F$5*V15 -> 46.86285 | AE15: =$G$4*K49 -> 2.1038982
A16: N. Administrative and support service activities | B16: 1311.593 | D16: 522.83 | E16: 1741.196 | F16: 20.163 | I16: 15_MACHINE | J16: 6.61521 | K16: 49.4583 | L16: 11.8583 | M16: 1.75171 | N16: 3.23894e-09 | O16: 0.00680916 | Q16: 15_MACHINE | R16: =J16/SUM(J$7:J$18) -> 0.44160476 | S16: =K16/SUM(K$7:K$18) -> 0.32240214 | T16: =L16/SUM(L$7:L$18) -> 0.41097747 | U16: =M16/SUM(M$7:M$18) -> 0.3002026 | V16: =N16/SUM(N$7:N$18) -> 2.1354606e-07 | W16: =O16/SUM(O$7:O$18) -> 0.12010152 | Y16: 15_MACHINE | Z16: =B$5*R16 -> 1955.9209 | AA16: =$C$4*O50 -> 48530.318 | AB16: =D$5*T16 -> 4359.1123 | AC16: =E$5*U16 -> 2982.7212 | AD16: =F$5*V16 -> 1.92736e-05 | AE16: =$G$4*K50 -> 121.01418
A17: O. Public administration and defence; compulsory social security | B17: 1076.364 | D17: 268.526 | E17: 4921.699 | F17: 85.953 | I17: 16_TRANSEQ | J17: 1.67099 | K17: 9.96614 | L17: 4.25361 | M17: 0.932989 | N17: 6.39991e-10 | O17: 0.00587562 | Q17: 16_TRANSEQ | R17: =J17/SUM(J$7:J$18) -> 0.11154856 | S17: =K17/SUM(K$7:K$18) -> 0.064965938 | T17: =L17/SUM(L$7:L$18) -> 0.14741893 | U17: =M17/SUM(M$7:M$18) -> 0.15989275 | V17: =N17/SUM(N$7:N$18) -> 4.219515e-08 | W17: =O17/SUM(O$7:O$18) -> 0.10363553 | Y17: 16_TRANSEQ | Z17: =B$5*R17 -> 494.06206 | AA17: =$C$4*O51 -> 9779.1461 | AB17: =D$5*T17 -> 1563.6275 | AC17: =E$5*U17 -> 1588.6454 | AD17: =F$5*V17 -> 3.8083233e-06 | AE17: =$G$4*K51 -> 104.42306
A18: P. Education | B18: 1883.333 | D18: 3327.575 | E18: 6684.415 | F18: 96.108 | I18: 17_OTHERIND | J18: 1.76074 | K18: 5.85391 | L18: 1.28122 | M18: 0.186667 | N18: 0.0004414 | O18: 0.00115896 | Q18: 17_OTHERIND | R18: =J18/SUM(J$7:J$18) -> 0.11753991 | S18: =K18/SUM(K$7:K$18) -> 0.038159684 | T18: =L18/SUM(L$7:L$18) -> 0.044403714 | U18: =M18/SUM(M$7:M$18) -> 0.031990409 | V18: =N18/SUM(N$7:N$18) -> 0.029101877 | W18: =O18/SUM(O$7:O$18) -> 0.020442001 | Y18: 17_OTHERIND | Z18: =B$5*R18 -> 520.59847 | AA18: =$C$4*O52 -> 5744.0735 | AB18: =D$5*T18 -> 470.9766 | AC18: =E$5*U18 -> 317.84691 | AD18: =F$5*V18 -> 2.6265899 | AE18: =$G$4*K52 -> 20.597341
A19: Q. Human health and social work activities | B19: 2205.97 | D19: 8364.065 | E19: 5555.554 | F19: 44.37 | I19: 18_TnD | J19: 0.238141 | K19: 5.01866 | L19: 0.553879 | M19: 1.26412 | N19: 0.0178633 | O19: 0.00185867 | Q19: 18_TnD | R19: =J19/SUM(J$19:J$27) -> 0.65998724 | S19: =K19/SUM(K$19:K$27) -> 0.53361655 | T19: =L19/SUM(L$19:L$27) -> 0.4155916 | U19: =M19/SUM(M$19:M$27) -> 0.34079807 | V19: =N19/SUM(N$19:N$27) -> 0.42259727 | W19: =O19/SUM(O$19:O$27) -> 0.61296492 | Y19: 18_TnD | Z19: =B$6*R19 -> 44.823693 | AA19: =$C$4*O53 -> 4924.4953 | AB19: =D$6*T19 -> 115.74559 | AC19: =E$6*U19 -> 621.00906 | AD19: =F$6*V19 -> 8.1764121 | AE19: =$G$4*K53 -> 33.032771
A20: R. Arts, entertainment and recreation | B20: 494.846 | D20: 3662.385 | E20: 1420.446 | F20: 17.999 | I20: 19_eNuclear | J20: 0.0548726 | K20: 0.414828 | L20: 0.0879619 | M20: 0.350481 | N20: 6.79231e-06 | O20: 5.63869e-07 | Q20: 19_eNuclear | R20: =J20/SUM(J$19:J$27) -> 0.15207468 | S20: =K20/SUM(K$19:K$27) -> 0.044107209 | T20: =L20/SUM(L$19:L$27) -> 0.066000384 | U20: =M20/SUM(M$19:M$27) -> 0.094487271 | V20: =N20/SUM(N$19:N$27) -> 0.00016068765 | W20: =O20/SUM(O$19:O$27) -> 0.00018595658 | Y20: 19_eNuclear | Z20: =B$6*R20 -> 10.328304 | AA20: =$C$4*O54 -> 407.04461 | AB20: =D$6*T20 -> 18.381635 | AC20: =E$6*U20 -> 172.17659 | AD20: =F$6*V20 -> 0.0031089846 | AE20: =$G$4*K54 -> 0.010021228
A21: S. Other service activities | B21: 1232.653 | D21: 1848.499 | E21: 1715.174 | F21: 24.547 | I21: 20_eCoal | J21: 0.0348225 | K21: 2.9844 | L21: 0.249273 | M21: 0.414602 | N21: 0.0234213 | O21: 0.00014146 | Q21: 20_eCoal | R21: =J21/SUM(J$19:J$27) -> 0.096507555 | S21: =K21/SUM(K$19:K$27) -> 0.31732081 | T21: =L21/SUM(L$19:L$27) -> 0.18703682 | U21: =M21/SUM(M$19:M$27) -> 0.11177385 | V21: =N21/SUM(N$19:N$27) -> 0.55408449 | W21: =O21/SUM(O$19:O$27) -> 0.046651648 | Y21: 20_eCoal | Z21: =B$6*R21 -> 6.5544071 | AA21: =$C$4*O55 -> 2928.4039 | AB21: =D$6*T21 -> 52.09125 | AC21: =E$6*U21 -> 203.67655 | AD21: =F$6*V21 -> 10.720427 | AE21: =$G$4*K55 -> 2.5140643
A22: T. Activities of households as employers; undifferentiated goods- and services-producing activities of households for own use | B22: 74.707 | D22: 2317.614 | E22: 12.276 | F22: 3.275 | I22: 21_eGas | J22: 0.0140013 | K22: 0.148069 | L22: 0.1106 | M22: 0.8989 | N22: 6.86508e-06 | O22: 7.89252e-06 | Q22: 21_eGas | R22: =J22/SUM(J$19:J$27) -> 0.038803395 | S22: =K22/SUM(K$19:K$27) -> 0.015743659 | T22: =L22/SUM(L$19:L$27) -> 0.082986412 | U22: =M22/SUM(M$19:M$27) -> 0.24233727 | V22: =N22/SUM(N$19:N$27) -> 0.00016240919 | W22: =O22/SUM(O$19:O$27) -> 0.0026028493 | Y22: 21_eGas | Z22: =B$6*R22 -> 2.6353714 | AA22: =$C$4*O56 -> 145.29079 | AB22: =D$6*T22 -> 23.11238 | AC22: =E$6*U22 -> 441.59181 | AD22: =F$6*V22 -> 0.003142293 | AE22: =$G$4*K56 -> 0.14026794
A23: U. Activities of extraterritorial organizations and bodies | B23: 11.797 | D23: 1484.646 | E23: 4.155 | F23: 2.014 | I23: 22_eOil | J23: 0.00612731 | K23: 0.0455161 | L23: 0.0481386 | M23: 0.0629385 | N23: 0.000422287 | O23: 0.000170717 | Q23: 22_eOil | R23: =J23/SUM(J$19:J$27) -> 0.016981311 | S23: =K23/SUM(K$19:K$27) -> 0.0048395676 | T23: =L23/SUM(L$19:L$27) -> 0.036119798 | U23: =M23/SUM(M$19:M$27) -> 0.016967787 | V23: =N23/SUM(N$19:N$27) -> 0.0099901661 | W23: =O23/SUM(O$19:O$27) -> 0.056300221 | Y23: 22_eOil | Z23: =B$6*R23 -> 1.1533027 | AA23: =$C$4*O57 -> 44.662085 | AB23: =D$6*T23 -> 10.059653 | AC23: =E$6*U23 -> 30.919042 | AD23: =F$6*V23 -> 0.19328973 | AE23: =$G$4*K57 -> 3.0340273
A24: X. Not elsewhere classified | B24: 108.663 | F24: 16.995 | I24: 23_eWind | J24: 0.00121878 | K24: 0.179211 | L24: 0.0144792 | M24: 0.000151315 | N24: 0.000456157 | O24: 5.62022e-07 | Q24: 23_eWind | R24: =J24/SUM(J$19:J$27) -> 0.0033777436 | S24: =K24/SUM(K$19:K$27) -> 0.019054878 | T24: =L24/SUM(L$19:L$27) -> 0.010864167 | U24: =M24/SUM(M$19:M$27) -> 4.0793485e-05 | V24: =N24/SUM(N$19:N$27) -> 0.010791439 | W24: =O24/SUM(O$19:O$27) -> 0.00018534746 | Y24: 23_eWind | Z24: =B$6*R24 -> 0.22940284 | AA24: =$C$4*O58 -> 175.84848 | AB24: =D$6*T24 -> 3.0257574 | AC24: =E$6*U24 -> 0.074334704 | AD24: =F$6*V24 -> 0.20879275 | AE24: =$G$4*K58 -> 0.0099884025
A25: Total | B25: 27231.369 | C25: =C9+C4+C3 -> 743849.65 | D25: 66769.405 | E25: 70102.263 | F25: 1202.84 | G25: =G9+G8+G4+G3 -> 15088.297 | I25: 24_eSolar | J25: 0.00126117 | K25: 0.037377 | L25: 0.0341066 | M25: 0.00092648 | N25: 2.81115e-05 | O25: 5.17796e-07 | Q25: 24_eSolar | R25: =J25/SUM(J$19:J$27) -> 0.0034952239 | S25: =K25/SUM(K$19:K$27) -> 0.0039741656 | T25: =L25/SUM(L$19:L$27) -> 0.025591179 | U25: =M25/SUM(M$19:M$27) -> 0.00024977265 | V25: =N25/SUM(N$19:N$27) -> 0.00066504192 | W25: =O25/SUM(O$19:O$27) -> 0.00017076231 | Y25: 24_eSolar | Z25: =B$6*R25 -> 0.23738162 | AA25: =$C$4*O59 -> 36.675698 | AB25: =D$6*T25 -> 7.127348 | AC25: =E$6*U25 -> 0.45514071 | AD25: =F$6*V25 -> 0.012867231 | AE25: =$G$4*K59 -> 0.0092024065
I26: 25_eHydro | J26: 0.000733773 | K26: 0.394848 | L26: 0.119544 | M26: 0.2546 | N26: 5.85401e-05 | O26: 0.000832039 | Q26: 25_eHydro | R26: =J26/SUM(J$19:J$27) -> 0.0020335886 | S26: =K26/SUM(K$19:K$27) -> 0.041982806 | T26: =L26/SUM(L$19:L$27) -> 0.089697357 | U26: =M26/SUM(M$19:M$27) -> 0.068638412 | V26: =N26/SUM(N$19:N$27) -> 0.0013849001 | W26: =O26/SUM(O$19:O$27) -> 0.27439552 | Y26: 25_eHydro | Z26: =B$6*R26 -> 0.1381132 | AA26: =$C$4*O60 -> 387.4395 | AB26: =D$6*T26 -> 24.981431 | AC26: =E$6*U26 -> 125.07429 | AD26: =F$6*V26 -> 0.026795048 | AE26: =$G$4*K60 -> 14.787216
I27: 26_eOther | J27: 0.00964824 | K27: 0.182084 | L27: 0.114766 | M27: 0.462574 | N27: 6.91497e-06 | O27: 1.98394e-05 | Q27: 26_eOther | R27: =J27/SUM(J$19:J$27) -> 0.026739265 | S27: =K27/SUM(K$19:K$27) -> 0.019360354 | T27: =L27/SUM(L$19:L$27) -> 0.086112284 | U27: =M27/SUM(M$19:M$27) -> 0.12470677 | V27: =N27/SUM(N$19:N$27) -> 0.00016358945 | W27: =O27/SUM(O$19:O$27) -> 0.0065427732 | Y27: 26_eOther | Z27: =B$6*R27 -> 1.8160239 | AA27: =$C$4*O61 -> 178.66757 | AB27: =D$6*T27 -> 23.98296 | AC27: =E$6*U27 -> 227.24318 | AD27: =F$6*V27 -> 0.0031651287 | AE27: =$G$4*K61 -> 0.35259103
I28: 27_CONSTRUC | J28: 5.71719 | K28: 62.1025 | L28: 13.2917 | M28: 3.14446 | N28: 0.0155464 | O28: 0.039782 | Q28: 27_CONSTRUC | Y28: 27_CONSTRUC | Z28: =B8 -> 2019.588 | AA28: =$C$4*O62 -> 60937.276 | AB28: =D8 -> 4960.678 | AC28: =E8 -> 4842.88 | AD28: =F8 -> 68.848 | AE28: =$G$4*K62 -> 707.01615
I29: 28_LTRP | J29: 1.35888 | K29: 25.1982 | L29: 6.3187 | M29: 1.4108 | N29: 0.0116496 | O29: 0.0299662 | Q29: 28_LTRP | R29: =J29/SUM(J$29:J$31) -> 0.80847168 | S29: =K29/SUM(K$29:K$31) -> 0.87999042 | T29: =L29/SUM(L$29:L$31) -> 0.90240728 | U29: =M29/SUM(M$29:M$31) -> 0.8157252 | V29: =N29/SUM(N$29:N$31) -> 0.82623931 | W29: =O29/SUM(O$29:O$31) -> 0.76539789 | Y29: 28_LTRP | Z29: =B$10*R29 -> 1157.214 | AA29: =$C$9*O63 -> 20755.462 | AB29: =D$10*T29 -> 3359.7805 | AC29: =E$10*U29 -> 5009.3815 | AD29: =F$10*V29 -> 50.502225 | AE29: =$G$9*K63 -> 305.73094
I30: 29_WTRP | J30: 0.14005 | K30: 1.5835 | L30: 0.48795 | M30: 0.118349 | N30: 0.000261577 | O30: 0.00405558 | Q30: 29_WTRP | R30: =J30/SUM(J$29:J$31) -> 0.083323368 | S30: =K30/SUM(K$29:K$31) -> 0.055300173 | T30: =L30/SUM(L$29:L$31) -> 0.069686745 | U30: =M30/SUM(M$29:M$31) -> 0.068429446 | V30: =N30/SUM(N$29:N$31) -> 0.018552156 | W30: =O30/SUM(O$29:O$31) -> 0.10358779 | Y30: 29_WTRP | Z30: =B$10*R30 -> 119.26574 | AA30: =$C$9*O64 -> 1304.3104 | AB30: =D$10*T30 -> 259.45288 | AC30: =E$10*U30 -> 420.22632 | AD30: =F$10*V30 -> 1.1339635 | AE30: =$G$9*K64 -> 41.377161
I31: 30_ATRP | J31: 0.181871 | K31: 1.85293 | L31: 0.195399 | M31: 0.200355 | N31: 0.00218837 | O31: 0.00512936 | Q31: 30_ATRP | R31: =J31/SUM(J$29:J$31) -> 0.10820496 | S31: =K31/SUM(K$29:K$31) -> 0.06470941 | T31: =L31/SUM(L$29:L$31) -> 0.027905974 | U31: =M31/SUM(M$29:M$31) -> 0.11584535 | V31: =N31/SUM(N$29:N$31) -> 0.15520853 | W31: =O31/SUM(O$29:O$31) -> 0.13101432 | Y31: 30_ATRP | Z31: =B$10*R31 -> 154.88025 | AA31: =$C$9*O65 -> 1526.2367 | AB31: =D$10*T31 -> 103.8976 | AC31: =E$10*U31 -> 711.40816 | AD31: =F$10*V31 -> 9.4868111 | AE31: =$G$9*K65 -> 52.33243
I32: 31_SER | J32: 39.0874 | K32: 372.968 | L32: 100.299 | M32: 32.864 | N32: 0.150226 | O32: 0.582145 | Q32: 31_SER | Y32: 31_SER | Z32: =SUM(B11:B24)+B9+B7 -> 17873.965 | AA32: =$C$9*O66 -> 307209.37 | AB32: =SUM(D11:D24)+D9+D7 -> 44997.081 | AC32: =SUM(E11:E24)+E9+E7 -> 41628.824 | AD32: =SUM(F11:F24)+F9+F7 -> 575.292 | AE32: =$G$9*K66 -> 5939.3496
Z33: =SUM(Z2:Z32) -> 27231.37 | AA33: =SUM(AA2:AA32) -> 743849.65 | AB33: =SUM(AB2:AB32) -> 66769.404 | AC33: =SUM(AC2:AC32) -> 70102.264 | AD33: =SUM(AD2:AD32) -> 1202.84 | AE33: =SUM(AE2:AE32) -> 15088.297
J35: 06_PRK | N35: 02_CHN
I36: 01_AGRICULT | J36: 0.00854196 | M36: 01_AGRICULT | N36: 43.5895
I37: 02_COAL | J37: 0.000753945 | K37: =J37/SUM(J$37:J$62) -> 0.0070526566 | M37: 02_COAL | N37: 3.91579 | O37: =N37/SUM($N$37:$N$62) -> 0.016697657
I38: 03_OIL | J38: 5.7828e-06 | K38: =J38/SUM(J$37:J$62) -> 5.4094267e-05 | M38: 03_OIL | N38: 0.643703 | O38: =N38/SUM($N$37:$N$62) -> 0.0027448693
I39: 04_GAS | J39: 9.81417e-06 | K39: =J39/SUM(J$37:J$62) -> 9.1805066e-05 | M39: 04_GAS | N39: 0.0253322 | O39: =N39/SUM($N$37:$N$62) -> 0.00010802121
I40: 05_MINING | J40: 0.00662343 | K40: =J40/SUM(J$37:J$62) -> 0.061957805 | M40: 05_MINING | N40: 5.01341 | O40: =N40/SUM($N$37:$N$62) -> 0.021378113
I41: 06_FOODPRO | J41: 0.0158267 | K41: =J41/SUM(J$37:J$62) -> 0.14804831 | M41: 06_FOODPRO | N41: 18.598 | O41: =N41/SUM($N$37:$N$62) -> 0.079305331
...

Sheet Employment_R11
B1: BAU | C1: BAU | D1: BAU | E1: BAU | F1: BAU | G1: BAU | H1: BAU | I1: BAU | J1: BAU | K1: BAU | L1: BAU | O1: BAU | P1: BAU | Q1: BAU | R1: BAU | S1: BAU | T1: BAU | U1: BAU | V1: BAU | W1: BAU | X1: BAU | Y1: BAU
B2: 07_NAM | C2: 08_LAM | D2: 09_WEU | E2: 10_EEU | F2: 11_FSU | G2: 12_MEA | H2: 13_AFR | I2: 14_CPA | J2: 15_SAS | K2: 16_PAS | L2: 17_PAO | O2: 07_NAM | P2: 08_LAM | Q2: 09_WEU | R2: 10_EEU | S2: 11_FSU | T2: 12_MEA | U2: 13_AFR | V2: 14_CPA | W2: 15_SAS | X2: 16_PAS | Y2: 17_PAO | AB2: 07_NAM | AC2: 08_LAM | AD2: 09_WEU | AE2: 10_EEU | AF2: 11_FSU | AG2: 12_MEA | AH2: 13_AFR | AI2: 14_CPA | AJ2: 15_SAS | AK2: 16_PAS | AL2: 17_PAO
A3: 01_AGRICULT | B3: 8.6774 | C3: 11.7065 | D3: 11.3611 | E3: 1.69085 | F3: 1.50016 | G3: 6.29866 | H3: 8.97314 | I3: 2.81987 | J3: 29.2409 | K3: 9.15073 | L3: 1.69772 | N3: 01_AGRICULT | AA3: 01_AGRICULT | AB3: ='R17'!N23 -> 3013.745 | AC3: ='R17'!O23 -> 40613.029 | AD3: ='R17'!P23 -> 10134.689 | AE3: ='R17'!Q23 -> 5659.7225 | AF3: ='R17'!R23 -> 14012.493 | AG3: ='R17'!S23 -> 26036.112 | AH3: ='R17'!T23 -> 203725.34 | AI3: ='R17'!U23 -> 24335.926 | ... AL3: ='R17'!X23 -> 487.99554
A4: 02_COAL | B4: 0.551015 | C4: 0.0478805 | D4: 0.154394 | E4: 0.189621 | F4: 0.207522 | G4: 0.00592343 | H4: 0.237505 | I4: 0.0801764 | J4: 0.554255 | K4: 0.247218 | L4: 0.340665 | N4: 02_COAL | O4: =B4/SUM(B$4:B$29) -> 0.0028886543 | P4: =C4/SUM(C$4:C$29) -> 0.0010174828 | Q4: =D4/SUM(D$4:D$29) -> 0.0010213874 | R4: =E4/SUM(E$4:E$29) -> 0.014609131 | S4: =F4/SUM(F$4:F$29) -> 0.026244087 | T4: =G4/SUM(G$4:G$29) -> 0.00014092156 | U4: =H4/SUM(H$4:H$29) -> 0.012874163 | V4: =I4/SUM(I$4:I$29) -> 0.0098983108 | ... Y4: =L4/SUM(L$4:L$29) -> 0.021851618 | AA4: 02_COAL | AB4: =O4*'R17'!N$24 -> 102.54092 | AC4: =P4*'R17'!O$24 -> 59.399809 | AD4: =Q4*'R17'!P$24 -> 51.574503 | AE4: =R4*'R17'!Q$24 -> 246.9179 | AF4: =S4*'R17'!R$24 -> 366.63989 | AG4: =T4*'R17'!S$24 -> 5.6035149 | AH4: =U4*'R17'!T$24 -> 556.36924 | AI4: =V4*'R17'!U$24 -> 180.66052 | ... AL4: =Y4*'R17'!X$24 -> 65.255094
A5: 03_OIL | B5: 1.43004 | C5: 0.800561 | D5: 0.225663 | E5: 0.0464969 | F5: 0.828935 | G5: 3.89586 | H5: 0.174868 | I5: 0.025074 | J5: 0.157942 | K5: 0.363669 | L5: 0.0282261 | N5: 03_OIL | O5: =B5/SUM(B$4:B$29) -> 0.007496876 | P5: =C5/SUM(C$4:C$29) -> 0.017012292 | Q5: =D5/SUM(D$4:D$29) -> 0.0014928647 | R5: =E5/SUM(E$4:E$29) -> 0.0035823001 | S5: =F5/SUM(F$4:F$29) -> 0.10483054 | T5: =G5/SUM(G$4:G$29) -> 0.092684587 | U5: =H5/SUM(H$4:H$29) -> 0.0094788702 | V5: =I5/SUM(I$4:I$29) -> 0.0030955524 | ... Y5: =L5/SUM(L$4:L$29) -> 0.0018105351 | AA5: 03_OIL | AB5: =O5*'R17'!N$24 -> 266.12274 | AC5: =P5*'R17'!O$24 -> 993.16361 | AD5: =Q5*'R17'!P$24 -> 75.381537 | AE5: =R5*'R17'!Q$24 -> 60.546653 | AF5: =S5*'R17'!R$24 -> 1464.5225 | AG5: =T5*'R17'!S$24 -> 3685.4508 | AH5: =U5*'R17'!T$24 -> 409.63843 | AI5: =V5*'R17'!U$24 -> 56.498942 | ... AL5: =Y5*'R17'!X$24 -> 5.4067685
A6: 04_GAS | B6: 1.15656 | C6: 0.263857 | D6: 0.25412 | E6: 0.0498759 | F6: 0.435706 | G6: 1.15267 | H6: 0.0569995 | I6: 0.141865 | J6: 0.189527 | K6: 0.391953 | L6: 0.230928 | N6: 04_GAS | O6: =B6/SUM(B$4:B$29) -> 0.0060631779 | P6: =C6/SUM(C$4:C$29) -> 0.0056070833 | Q6: =D6/SUM(D$4:D$29) -> 0.0016811208 | R6: =E6/SUM(E$4:E$29) -> 0.0038426313 | S6: =F6/SUM(F$4:F$29) -> 0.055101177 | T6: =G6/SUM(G$4:G$29) -> 0.027422634 | U6: =H6/SUM(H$4:H$29) -> 0.0030897069 | V6: =I6/SUM(I$4:I$29) -> 0.01751418 | ... Y6: =L6/SUM(L$4:L$29) -> 0.014812647 | AA6: 04_GAS | AB6: =O6*'R17'!N$24 -> 215.22959 | AC6: =P6*'R17'!O$24 -> 327.33692 | AD6: =Q6*'R17'!P$24 -> 84.887448 | AE6: =R6*'R17'!Q$24 -> 64.946669 | AF6: =S6*'R17'!R$24 -> 769.78441 | AG6: =T6*'R17'!S$24 -> 1090.4161 | AH6: =U6*'R17'!T$24 -> 133.52463 | AI6: =V6*'R17'!U$24 -> 319.6627 | ... AL6: =Y6*'R17'!X$24 -> 44.234742
A7: 05_MINING | B7: 4.74157 | C7: 1.55128 | D7: 1.24613 | E7: 0.210104 | F7: 0.418168 | G7: 0.939147 | H7: 1.28045 | I7: 0.12207 | J7: 0.713603 | K7: 0.971427 | L7: 1.31307 | N7: 05_MINING | O7: =B7/SUM(B$4:B$29) -> 0.02485732 | P7: =C7/SUM(C$4:C$29) -> 0.032965418 | Q7: =D7/SUM(D$4:D$29) -> 0.0082437237 | R7: =E7/SUM(E$4:E$29) -> 0.016187221 | S7: =F7/SUM(F$4:F$29) -> 0.052883249 | T7: =G7/SUM(G$4:G$29) -> 0.022342808 | U7: =H7/SUM(H$4:H$29) -> 0.069407893 | V7: =I7/SUM(I$4:I$29) -> 0.015070355 | ... Y7: =L7/SUM(L$4:L$29) -> 0.084225569 | AA7: 05_MINING | AB7: =O7*'R17'!N$24 -> 882.38064 | AC7: =P7*'R17'!O$24 -> 1924.494 | AD7: =Q7*'R17'!P$24 -> 416.26317 | AE7: =R7*'R17'!Q$24 -> 273.59015 | AF7: =S7*'R17'!R$24 -> 738.79912 | AG7: =T7*'R17'!S$24 -> 888.42516 | AH7: =U7*'R17'!T$24 -> 2999.5284 | AI7: =V7*'R17'!U$24 -> 275.05886 | ... AL7: =Y7*'R17'!X$24 -> 251.52131
A8: 06_FOODPRO | B8: 14.32 | C8: 7.61495 | D8: 13.3836 | E8: 1.33125 | F8: 0.620943 | G8: 4.63319 | H8: 7.11826 | I8: 0.30335 | J8: 4.31589 | K8: 3.88338 | L8: 2.01862 | N8: 06_FOODPRO | O8: =B8/SUM(B$4:B$29) -> 0.075071512 | P8: =C8/SUM(C$4:C$29) -> 0.16182121 | Q8: =D8/SUM(D$4:D$29) -> 0.088538677 | R8: =E8/SUM(E$4:E$29) -> 0.10256462 | S8: =F8/SUM(F$4:F$29) -> 0.078527011 | T8: =G8/SUM(G$4:G$29) -> 0.11022606 | U8: =H8/SUM(H$4:H$29) -> 0.3858514 | V8: =I8/SUM(I$4:I$29) -> 0.037450579 | ... Y8: =L8/SUM(L$4:L$29) -> 0.12948237 | AA8: 06_FOODPRO | AB8: =O8*'R17'!N$24 -> 2664.8749 | AC8: =P8*'R17'!O$24 -> 9446.9893 | AD8: =Q8*'R17'!P$24 -> 4470.7211 | AE8: =R8*'R17'!Q$24 -> 1733.5076 | AF8: =S8*'R17'!R$24 -> 1097.0522 | AG8: =T8*'R17'!S$24 -> 4382.9587 | AH8: =U8*'R17'!T$24 -> 16674.937 | AI8: =V8*'R17'!U$24 -> 683.5349 | ... AL8: =Y8*'R17'!X$24 -> 386.67089
A9: 07_TEXTILES | B9: 2.63783 | C9: 3.02333 | D9: 4.93716 | E9: 0.815476 | F9: 0.165806 | G9: 2.27336 | H9: 0.925128 | I9: 2.38194 | J9: 5.76461 | K9: 1.23344 | L9: 0.130337 | N9: 07_TEXTILES | O9: =B9/SUM(B$4:B$29) -> 0.013828623 | P9: =C9/SUM(C$4:C$29) -> 0.064247161 | Q9: =D9/SUM(D$4:D$29) -> 0.032661587 | R9: =E9/SUM(E$4:E$29) -> 0.062827409 | S9: =F9/SUM(F$4:F$29) -> 0.02096851 | T9: =G9/SUM(G$4:G$29) -> 0.054084447 | U9: =H9/SUM(H$4:H$29) -> 0.050147358 | V9: =I9/SUM(I$4:I$29) -> 0.29406637 | ... Y9: =L9/SUM(L$4:L$29) -> 0.0083603372 | AA9: 07_TEXTILES | AB9: =O9*'R17'!N$24 -> 490.88595 | AC9: =P9*'R17'!O$24 -> 3750.6965 | AD9: =Q9*'R17'!P$24 -> 1649.2323 | AE9: =R9*'R17'!Q$24 -> 1061.8846 | AF9: =S9*'R17'!R$24 -> 292.93807 | AG9: =T9*'R17'!S$24 -> 2150.5794 | AH9: =U9*'R17'!T$24 -> 2167.166 | AI9: =V9*'R17'!U$24 -> 5367.1967 | ... AL9: =Y9*'R17'!X$24 -> 24.966325
A10: 08_WOODPRO | B10: 2.11606 | C10: 0.809639 | D10: 1.90051 | E10: 0.247871 | F10: 0.0637124 | G10: 0.460689 | H10: 0.341023 | I10: 0.155088 | J10: 0.15845 | K10: 0.462443 | L10: 0.353197 | N10: 08_WOODPRO | O10: =B10/SUM(B$4:B$29) -> 0.011093284 | P10: =C10/SUM(C$4:C$29) -> 0.017205203 | Q10: =D10/SUM(D$4:D$29) -> 0.012572749 | R10: =E10/SUM(E$4:E$29) -> 0.019096936 | S10: =F10/SUM(F$4:F$29) -> 0.0080573327 | T10: =G10/SUM(G$4:G$29) -> 0.010960037 | U10: =H10/SUM(H$4:H$29) -> 0.018485445 | V10: =I10/SUM(I$4:I$29) -> 0.019146647 | ... Y10: =L10/SUM(L$4:L$29) -> 0.02265547 | AA10: 08_WOODPRO | AB10: =O10*'R17'!N$24 -> 393.78737 | AC10: =P10*'R17'!O$24 -> 1004.4256 | AD10: =Q10*'R17'!P$24 -> 634.85536 | AE10: =R10*'R17'!Q$24 -> 322.76903 | AF10: =S10*'R17'!R$24 -> 112.564 | AG10: =T10*'R17'!S$24 -> 435.80792 | AH10: =U10*'R17'!T$24 -> 798.86615 | AI10: =V10*'R17'!U$24 -> 349.45792 | ... AL10: =Y10*'R17'!X$24 -> 67.655625
A11: 09_PAPERPRO | B11: 6.30131 | C11: 1.57498 | D11: 5.7594 | E11: 0.42776 | F11: 0.0540814 | G11: 0.561953 | H11: 0.337438 | I11: 0.138173 | J11: 0.7938 | K11: 0.871888 | L11: 0.284235 | N11: 09_PAPERPRO | O11: =B11/SUM(B$4:B$29) -> 0.033034139 | P11: =C11/SUM(C$4:C$29) -> 0.033469054 | Q11: =D11/SUM(D$4:D$29) -> 0.038101083 | R11: =E11/SUM(E$4:E$29) -> 0.032956276 | S11: =F11/SUM(F$4:F$29) -> 0.0068393567 | T11: =G11/SUM(G$4:G$29) -> 0.013369162 | U11: =H11/SUM(H$4:H$29) -> 0.018291117 | V11: =I11/SUM(I$4:I$29) -> 0.017058378 | ... Y11: =L11/SUM(L$4:L$29) -> 0.018231971 | AA11: 09_PAPERPRO | AB11: =O11*'R17'!N$24 -> 1172.6398 | AC11: =P11*'R17'!O$24 -> 1953.8959 | AD11: =Q11*'R17'!P$24 -> 1923.8972 | AE11: =R11*'R17'!Q$24 -> 557.01425 | AF11: =S11*'R17'!R$24 -> 95.548417 | AG11: =T11*'R17'!S$24 -> 531.60281 | AH11: =U11*'R17'!T$24 -> 790.46808 | AI11: =V11*'R17'!U$24 -> 311.34356 | ... AL11: =Y11*'R17'!X$24 -> 54.445809
A12: 10_PETROLCOAL | B12: 0.489602 | C12: 0.245588 | D12: 0.262545 | E12: 0.0373025 | F12: 0.120082 | G12: 0.948088 | H12: 0.0592825 | I12: 0.0841938 | J12: 0.156593 | K12: 0.197508 | L12: 0.0304933 | N12: 10_PETROLCOAL | O12: =B12/SUM(B$4:B$29) -> 0.0025667013 | P12: =C12/SUM(C$4:C$29) -> 0.0052188586 | Q12: =D12/SUM(D$4:D$29) -> 0.0017368561 | R12: =E12/SUM(E$4:E$29) -> 0.0028739281 | S12: =F12/SUM(F$4:F$29) -> 0.015186065 | T12: =G12/SUM(G$4:G$29) -> 0.022555519 | U12: =H12/SUM(H$4:H$29) -> 0.0032134589 | V12: =I12/SUM(I$4:I$29) -> 0.010394286 | ... Y12: =L12/SUM(L$4:L$29) -> 0.0019559624 | AA12: 10_PETROLCOAL | AB12: =O12*'R17'!N$24 -> 91.112295 | AC12: =P12*'R17'!O$24 -> 304.67268 | AD12: =Q12*'R17'!P$24 -> 87.701775 | AE12: =R12*'R17'!Q$24 -> 48.574023 | AF12: =S12*'R17'!R$24 -> 212.1551 | AG12: =T12*'R17'!S$24 -> 896.88327 | AH12: =U12*'R17'!T$24 -> 138.87269 | AI12: =V12*'R17'!U$24 -> 189.71288 | ... AL12: =Y12*'R17'!X$24 -> 5.8410554
A13: 11_CHEMICAL | B13: 12.7283 | C13: 4.12578 | D13: 16.1462 | E13: 1.2255 | F13: 0.233895 | G13: 2.36489 | H13: 0.783305 | I13: 0.605672 | J13: 2.85924 | K13: 2.85847 | L13: 0.753781 | N13: 11_CHEMICAL | O13: =B13/SUM(B$4:B$29) -> 0.066727146 | P13: =C13/SUM(C$4:C$29) -> 0.087674734 | Q13: =D13/SUM(D$4:D$29) -> 0.10681455 | R13: =E13/SUM(E$4:E$29) -> 0.094417236 | S13: =F13/SUM(F$4:F$29) -> 0.029579326 | T13: =G13/SUM(G$4:G$29) -> 0.056261994 | U13: =H13/SUM(H$4:H$29) -> 0.042459721 | V13: =I13/SUM(I$4:I$29) -> 0.074774244 | ... Y13: =L13/SUM(L$4:L$29) -> 0.048350532 | AA13: 11_CHEMICAL | AB13: =O13*'R17'!N$24 -> 2368.6681 | AC13: =P13*'R17'!O$24 -> 5118.3789 | AD13: =Q13*'R17'!P$24 -> 5393.5531 | AE13: =R13*'R17'!Q$24 -> 1595.8036 | AF13: =S13*'R17'!R$24 -> 413.23444 | AG13: =T13*'R17'!S$24 -> 2237.166 | AH13: =U13*'R17'!T$24 -> 1834.9374 | AI13: =V13*'R17'!U$24 -> 1364.7534 | ... AL13: =Y13*'R17'!X$24 -> 144.38833
A14: 12_NONMET | B14: 2.72235 | C14: 1.1433 | D14: 3.88593 | E14: 0.387358 | F14: 0.131434 | G14: 1.58032 | H14: 0.258633 | I14: 0.276076 | J14: 0.754123 | K14: 0.70175 | L14: 0.304018 | N14: 12_NONMET | O14: =B14/SUM(B$4:B$29) -> 0.014271713 | P14: =C14/SUM(C$4:C$29) -> 0.024295654 | Q14: =D14/SUM(D$4:D$29) -> 0.025707216 | R14: =E14/SUM(E$4:E$29) -> 0.029843551 | S14: =F14/SUM(F$4:F$29) -> 0.016621685 | T14: =G14/SUM(G$4:G$29) -> 0.037596656 | U14: =H14/SUM(H$4:H$29) -> 0.014019424 | V14: =I14/SUM(I$4:I$29) -> 0.034083422 | ... Y14: =L14/SUM(L$4:L$29) -> 0.019500932 | AA14: 12_NONMET | AB14: =O14*'R17'!N$24 -> 506.61467 | AC14: =P14*'R17'!O$24 -> 1418.3603 | AD14: =Q14*'R17'!P$24 -> 1298.0745 | AE14: =R14*'R17'!Q$24 -> 504.40417 | AF14: =S14*'R17'!R$24 -> 232.21127 | AG14: =T14*'R17'!S$24 -> 1494.9694 | AH14: =U14*'R17'!T$24 -> 605.8628 | AI14: =V14*'R17'!U$24 -> 622.07872 | ... AL14: =Y14*'R17'!X$24 -> 58.235284
A15: 13_IRONSTL | B15: 1.75679 | C15: 0.524731 | D15: 2.94767 | E15: 0.297988 | F15: 0.218245 | G15: 0.481841 | H15: 0.122627 | I15: 0.204616 | J15: 0.282451 | K15: 0.521986 | L15: 0.254541 | N15: 13_IRONSTL | O15: =B15/SUM(B$4:B$29) -> 0.0092098381 | P15: =C15/SUM(C$4:C$29) -> 0.011150776 | Q15: =D15/SUM(D$4:D$29) -> 0.019500194 | R15: =E15/SUM(E$4:E$29) -> 0.022958142 | S15: =F15/SUM(F$4:F$29) -> 0.027600162 | T15: =G15/SUM(G$4:G$29) -> 0.011463254 | U15: =H15/SUM(H$4:H$29) -> 0.0066471019 | V15: =I15/SUM(I$4:I$29) -> 0.025261209 | ... Y15: =L15/SUM(L$4:L$29) -> 0.016327279 | AA15: 13_IRONSTL | AB15: =O15*'R17'!N$24 -> 326.92916 | AC15: =P15*'R17'!O$24 -> 650.97317 | AD15: =Q15*'R17'!P$24 -> 984.65364 | AE15: =R15*'R17'!Q$24 -> 388.02965 | AF15: =S15*'R17'!R$24 -> 385.58477 | AG15: =T15*'R17'!S$24 -> 455.81753 | AH15: =U15*'R17'!T$24 -> 287.26086 | AI15: =V15*'R17'!U$24 -> 461.05877 | ... AL15: =Y15*'R17'!X$24 -> 48.757861
... A29: 27_CONSTRUC | B29: 55.436 | C29: 12.1846 | D29: 36.2911 | E29: 2.10693 | F29: 1.51394 | G29: 12.4323 | H29: 3.10672 | I29: 0.874646 | J29: 19.3316 | K29: 8.71364 | L29: 6.79287 | N29: 27_CONSTRUC | O29: =B29/SUM(B$4:B$29) -> 0.29061902 | P29: =C29/SUM(C$4:C$29) -> 0.25892839 | Q29: =D29/SUM(D$4:D$29) -> 0.24008234 | R29: =E29/SUM(E$4:E$29) -> 0.16232599 | S29: =F29/SUM(F$4:F$29) -> 0.19145909 | T29: =G29/SUM(G$4:G$29) -> 0.29577105 | U29: =H29/SUM(H$4:H$29) -> 0.16840243 | V29: =I29/SUM(I$4:I$29) -> 0.10798088 | ... Y29: =L29/SUM(L$4:L$29) -> 0.43572189 | AA29: 27_CONSTRUC | AB29: =O29*'R17'!N$24 -> 10316.341 | AC29: =P29*'R17'!O$24 -> 15116.027 | AD29: =Q29*'R17'!P$24 -> 12122.851 | AE29: =R29*'R17'!Q$24 -> 2743.5713 | AF29: =S29*'R17'!R$24 -> 2674.7564 | AG29: =T29*'R17'!S$24 -> 11760.851 | AH29: =U29*'R17'!T$24 -> 7277.6718 | AI29: =V29*'R17'!U$24 -> 1970.8293 | ... AL29: =Y29*'R17'!X$24 -> 1301.1885
A30: 28_LTRP | B30: 19.3852 | C30: 7.35183 | D30: 16.0277 | E30: 1.56075 | F30: 0.591646 | G30: 2.98311 | H30: 2.39041 | I30: 0.252183 | J30: 9.58218 | K30: 2.91823 | L30: 2.15089 | N30: 28_LTRP | O30: =B30/SUM(B$30:B$33) -> 0.024470955 | P30: =C30/SUM(C$30:C$33) -> 0.052186247 | Q30: =D30/SUM(D$30:D$33) -> 0.036040543 | R30: =E30/SUM(E$30:E$33) -> 0.060239131 | S30: =F30/SUM(F$30:F$33) -> 0.047977459 | T30: =G30/SUM(G$30:G$33) -> 0.042488775 | U30: =H30/SUM(H$30:H$33) -> 0.048976315 | V30: =I30/SUM(I$30:I$33) -> 0.038039079 | ... Y30: =L30/SUM(L$30:L$33) -> 0.035603702 | AA30: 28_LTRP | AB30: =O30*'R17'!N$25 -> 3503.8434 | AC30: =P30*'R17'!O$25 -> 9722.3484 | AD30: =Q30*'R17'!P$25 -> 5945.5716 | AE30: =R30*'R17'!Q$25 -> 1893.9583 | AF30: =S30*'R17'!R$25 -> 1629.9756 | AG30: =T30*'R17'!S$25 -> 3610.33 | AH30: =U30*'R17'!T$25 -> 6960.6572 | AI30: =V30*'R17'!U$25 -> 906.6015 | ... AL30: =Y30*'R17'!X$25 -> 431.87129
A31: 29_WTRP | B31: 0.685396 | C31: 0.379388 | D31: 1.93127 | E31: 0.0676931 | F31: 0.0620108 | G31: 0.312399 | H31: 0.153243 | I31: 0.0808509 | J31: 0.35387 | K31: 1.04043 | L31: 0.151444 | N31: 29_WTRP | O31: =B31/SUM(B$30:B$33) -> 0.00086521131 | P31: =C31/SUM(C$30:C$33) -> 0.0026930487 | Q31: =D31/SUM(D$30:D$33) -> 0.0043427329 | R31: =E31/SUM(E$30:E$33) -> 0.0026127013 | S31: =F31/SUM(F$30:F$33) -> 0.0050285485 | T31: =G31/SUM(G$30:G$33) -> 0.0044495345 | U31: =H31/SUM(H$30:H$33) -> 0.0031397449 | V31: =I31/SUM(I$30:I$33) -> 0.012195484 | ... Y31: =L31/SUM(L$30:L$33) -> 0.0025068539 | AA31: 29_WTRP | AB31: =O31*'R17'!N$25 -> 123.88421 | AC31: =P31*'R17'!O$25 -> 501.71758 | AD31: =Q31*'R17'!P$25 -> 716.41621 | AE31: =R31*'R17'!Q$25 -> 82.145062 | AF31: =S31*'R17'!R$25 -> 170.83879 | AG31: =T31*'R17'!S$25 -> 378.0831 | AH31: =U31*'R17'!T$25 -> 446.22972 | AI31: =V31*'R17'!U$25 -> 290.66015 | ... AL31: =Y31*'R17'!X$25 -> 30.408024
A32: 30_ATRP | B32: 4.4792 | C32: 0.540553 | D32: 1.88708 | E32: 0.139695 | F32: 0.0724927 | G32: 0.460858 | H32: 0.316016 | I32: 0.130243 | J32: 0.331813 | K32: 0.871831 | L32: 0.479143 | N32: 30_ATRP | O32: =B32/SUM(B$30:B$33) -> 0.0056543291 | P32: =C32/SUM(C$30:C$33) -> 0.0038370627 | Q32: =D32/SUM(D$30:D$33) -> 0.0042433655 | R32: =E32/SUM(E$30:E$33) -> 0.0053917062 | S32: =F32/SUM(F$30:F$33) -> 0.0058785414 | T32: =G32/SUM(G$30:G$33) -> 0.0065640529 | U32: =H32/SUM(H$30:H$33) -> 0.0064747467 | V32: =I32/SUM(I$30:I$33) -> 0.019645748 | ... Y32: =L32/SUM(L$30:L$33) -> 0.0079312584 | AA32: 30_ATRP | AB32: =O32*'R17'!N$25 -> 809.60813 | AC32: =P32*'R17'!O$25 -> 714.8485 | AD32: =Q32*'R17'!P$25 -> 700.02366 | AE32: =R32*'R17'!Q$25 -> 169.51882 | AF32: =S32*'R17'!R$25 -> 199.71626 | AG32: =T32*'R17'!S$25 -> 557.75666 | AH32: =U32*'R17'!T$25 -> 920.20994 | AI32: =V32*'R17'!U$25 -> 468.22545 | ... AL32: =Y32*'R17'!X$25 -> 96.205806
A33: 31_SER | B33: 767.622 | C33: 132.605 | D33: 424.867 | E33: 24.1411 | F33: 11.6056 | G33: 66.453 | H33: 45.9478 | I33: 6.1663 | J33: 81.7552 | K33: 66.5476 | L33: 57.6305 | N33: 31_SER | O33: =B33/SUM(B$30:B$33) -> 0.96900951 | P33: =C33/SUM(C$30:C$33) -> 0.94128364 | Q33: =D33/SUM(D$30:D$33) -> 0.95537336 | R33: =E33/SUM(E$30:E$33) -> 0.93175646 | S33: =F33/SUM(F$30:F$33) -> 0.94111545 | T33: =G33/SUM(G$30:G$33) -> 0.94649764 | U33: =H33/SUM(H$30:H$33) -> 0.94140919 | V33: =I33/SUM(I$30:I$33) -> 0.93011969 | ... Y33: =L33/SUM(L$30:L$33) -> 0.95395819 | AA33: 31_SER | AB33: =O33*'R17'!N$25 -> 138746.43 | AC33: =P33*'R17'!O$25 -> 175362.05 | AD33: =Q33*'R17'!P$25 -> 157606.97 | AE33: =R33*'R17'!Q$25 -> 29295.041 | AF33: =S33*'R17'!R$25 -> 31973.248 | AG33: =T33*'R17'!S$25 -> 80425.214 | AH33: =U33*'R17'!T$25 -> 133795.83 | AI33: =V33*'R17'!U$25 -> 22167.937 | ... AL33: =Y33*'R17'!X$25 -> 11571.47
B34: =SUM(B3:B33) -> 991.60065 | C34: =SUM(C3:C33) -> 199.64107 | D34: =SUM(D3:D33) -> 607.23521 | E34: =SUM(E3:E33) -> 40.57971 | F34: =SUM(F3:F33) -> 21.739291 | G34: =SUM(G3:G33) -> 118.54155 | H34: =SUM(H3:H33) -> 76.228799 | I34: =SUM(I3:I33) -> 17.549455 | ... L34: =SUM(L3:L33) -> 77.699618 | AB34: =SUM(AB3:AB33) -> 181695.33 | AC34: =SUM(AC3:AC33) -> 285293.18 | AD34: =SUM(AD3:AD33) -> 225598.22 | AE34: =SUM(AE3:AE33) -> 54002 | AF34: =SUM(AF3:AF33) -> 61956.652 | AG34: =SUM(AG3:AG33) -> 150770.86 | AH34: =SUM(AH3:AH33) -> 389064.22 | AI34: =SUM(AI3:AI33) -> 66421.001 | ... AL34: =SUM(AL3:AL33) -> 15604.232

Sheet R17
A1: R17 | B1: Employment (persons) | C1: Agriculture (persons) | D1: Industry (persons) | E1: Services (persons) | G1: R17 | H1: Employment (1,000 persons) | I1: Agriculture (1,000 persons) | J1: Industry (1,000 persons) | K1: Services (1,000 persons)
A2: 01_KOR | B2: 27729654 | C2: 1426133.5 | D2: 6815421.1 | E2: 19488097 | G2: 01_KOR | H2: =B2/1000 -> 27729.654 | I2: =C2/1000 -> 1426.1335 | J2: =D2/1000 -> 6815.4211 | K2: =E2/1000 -> 19488.097
A3: 02_CHN | B3: 7.4384965e+08 | C3: 1.8294304e+08 | D3: 2.3011123e+08 | E3: 3.3079538e+08 | G3: 02_CHN | H3: =B3/1000 -> 743849.65 | I3: =C3/1000 -> 182943.04 | J3: =D3/1000 -> 230111.23 | K3: =E3/1000 -> 330795.38
A4: 03_JPN | B4: 67422271 | C4: 2201769.7 | D4: 16349852 | E4: 48870649 | G4: 03_JPN | H4: =B4/1000 -> 67422.271 | I4: =C4/1000 -> 2201.7697 | J4: =D4/1000 -> 16349.852 | K4: =E4/1000 -> 48870.649
A5: 04_RUS | B5: 70799173 | C5: 4129911.3 | D5: 18963269 | E5: 47705993 | G5: 04_RUS | H5: =B5/1000 -> 70799.173 | I5: =C5/1000 -> 4129.9113 | J5: =D5/1000 -> 18963.269 | K5: =E5/1000 -> 47705.993
A6: 05_MNG | B6: 1260073 | C6: 350490.53 | D6: 262762.5 | E6: 646820 | G6: 05_MNG | H6: =B6/1000 -> 1260.073 | I6: =C6/1000 -> 350.49053 | J6: =D6/1000 -> 262.7625 | K6: =E6/1000 -> 646.82
A7: 06_PRK | B7: 15088296 | C7: 6849611.3 | D7: 1899895.2 | E7: 6338790.2 | G7: 06_PRK | H7: =B7/1000 -> 15088.296 | I7: =C7/1000 -> 6849.6113 | J7: =D7/1000 -> 1899.8952 | K7: =E7/1000 -> 6338.7902
A8: 07_NAM | B8: 1.8169533e+08 | C8: 3013745 | D8: 35497818 | E8: 1.4318377e+08 | G8: 07_NAM | H8: =B8/1000 -> 181695.33 | I8: =C8/1000 -> 3013.745 | J8: =D8/1000 -> 35497.818 | K8: =E8/1000 -> 143183.77
A9: 08_LAM | B9: 2.8529318e+08 | C9: 40613029 | D9: 58379179 | E9: 1.8630097e+08 | G9: 08_LAM | H9: =B9/1000 -> 285293.18 | I9: =C9/1000 -> 40613.029 | J9: =D9/1000 -> 58379.179 | K9: =E9/1000 -> 186300.97
A10: 09_WEU | B10: 2.2559822e+08 | C10: 10134689 | D10: 50494556 | E10: 1.6496898e+08 | G10: 09_WEU | H10: =B10/1000 -> 225598.22 | I10: =C10/1000 -> 10134.689 | J10: =D10/1000 -> 50494.556 | K10: =E10/1000 -> 164968.98
A11: 10_EEU | B11: 54002001 | C11: 5659722.5 | D11: 16901614 | E11: 31440664 | G11: 10_EEU | H11: =B11/1000 -> 54002.001 | I11: =C11/1000 -> 5659.7225 | J11: =D11/1000 -> 16901.614 | K11: =E11/1000 -> 31440.664
A12: 11_RFSU | B12: 61956649 | C12: 14012493 | D12: 13970381 | E12: 33973779 | G12: 11_RFSU | H12: =B12/1000 -> 61956.649 | I12: =C12/1000 -> 14012.493 | J12: =D12/1000 -> 13970.381 | K12: =E12/1000 -> 33973.779
A13: 12_MEA | B13: 1.5077086e+08 | C13: 26036112 | D13: 39763362 | E13: 84971384 | G13: 12_MEA | H13: =B13/1000 -> 150770.86 | I13: =C13/1000 -> 26036.112 | J13: =D13/1000 -> 39763.362 | K13: =E13/1000 -> 84971.384
... A18: 17_RPAO | B18: 15604231 | C18: 487995.54 | D18: 2986282.1 | E18: 12129955 | G18: 17_RPAO | H18: =B18/1000 -> 15604.231 | I18: =C18/1000 -> 487.99554 | J18: =D18/1000 -> 2986.2821 | K18: =E18/1000 -> 12129.955
G21: R17 | H21: 01_KOR | I21: 02_CHN | J21: 03_JPN | K21: 04_RUS | L21: 05_MNG | M21: 06_PRK | N21: 07_NAM | O21: 08_LAM | P21: 09_WEU | Q21: 10_EEU | R21: 11_RFSU | S21: 12_MEA | T21: 13_AFR | U21: 14_RCPA | V21: 15_SAS | W21: 16_RPAS | X21: 17_RPAO
G22: Employment (1,000 persons) | H22: {=TRANSPOSE(H2:K18)} -> 27729.654 | I22: 743849.65 | J22: 67422.271 | K22: 70799.173 | L22: 1260.073 | M22: 15088.296 | N22: 181695.33 | O22: 285293.18 | P22: 225598.22 | Q22: 54002.001 | R22: 61956.649 | S22: 150770.86 | T22: 389064.22 | U22: 66421 | V22: 646037.66 | W22: 263333.55 | X22: 15604.231
G23: Agriculture (1,000 persons) | H23: 1426.1335 | I23: 182943.04 | J23: 2201.7697 | K23: 4129.9113 | L23: 350.49053 | M23: 6849.6113 | N23: 3013.745 | O23: 40613.029 | P23: 10134.689 | Q23: 5659.7225 | R23: 14012.493 | S23: 26036.112 | T23: 203725.34 | U23: 24335.926 | V23: 260012.24 | W23: 74893.657 | X23: 487.99554
G24: Industry (1,000 persons) | H24: 6815.4211 | I24: 230111.23 | J24: 16349.852 | K24: 18963.269 | L24: 262.7625 | M24: 1899.8952 | N24: 35497.818 | O24: 58379.179 | P24: 50494.556 | Q24: 16901.614 | R24: 13970.381 | S24: 39763.362 | T24: 43215.955 | U24: 18251.651 | V24: 158792.91 | W24: 56293.771 | X24: 2986.2821
G25: Services (1,000 persons) | H25: 19488.097 | I25: 330795.38 | J25: 48870.649 | K25: 47705.993 | L25: 646.82 | M25: 6338.7902 | N25: 143183.77 | O25: 186300.97 | P25: 164968.98 | Q25: 31440.664 | R25: 33973.779 | S25: 84971.384 | T25: 142122.93 | U25: 23833.424 | V25: 227232.56 | W25: 132146.13 | X25: 12129.955

Sheet Employment_2019
B1: 01_KOR | C1: 02_CHN | D1: 03_JPN | E1: 04_RUS | F1: 05_MNG | G1: 06_PRK | H1: 07_NAM | I1: 08_LAM | J1: 09_WEU | K1: 10_EEU | L1: 11_RFSU | M1: 12_MEA | N1: 13_AFR | O1: 14_RCPA | P1: 15_SAS | Q1: 16_RPAS | R1: 17_RPAO
A2: 01_AGRICULT | B2: =Employment_NEA!Z2 -> 1394.918 | C2: =Employment_NEA!AA2 -> 182943.04 | D2: =Employment_NEA!AB2 -> 2180.45 | E2: =Employment_NEA!AC2 -> 4131.296 | F2: =Employment_NEA!AD2 -> 330.051 | G2: =Employment_NEA!AE2 -> 6849.6113 | H2: =Employment_R11!AB3 -> 3013.745 | I2: =Employment_R11!AC3 -> 40613.029 | J2: =Employment_R11!AD3 -> 10134.689 | K2: =Employment_R11!AE3 -> 5659.7225 | L2: =Employment_R11!AF3 -> 14012.493 | M2: =Employment_R11!AG3 -> 26036.112 | N2: =Employment_R11!AH3 -> 203725.34 | O2: =Employment_R11!AI3 -> 24335.926 | ... R2: =Employment_R11!AL3 -> 487.99554
