Workbook

Sheet Baseyear
A1: GDPPPP
B2: 01_KOR | C2: 02_CHN | D2: 03_JPN | E2: 04_RUS | F2: 05_MNG | G2: 06_PRK | H2: 07_NAM | I2: 08_LAM | J2: 09_WEU | K2: 10_EEU | L2: 11_RFSU | M2: 12_MEA | N2: 13_AFR | O2: 14_RCPA | P2: 15_SAS | Q2: 16_RPAS | R2: 17_RPAO
A3: 2018 | B3: 2.1648129e+12 | C3: 2.1684385e+13 | D3: 5.2961118e+12 | E3: 3.9139759e+12 | F3: 3.8133349e+10 | G3: 0 | H3: 2.1975104e+13 | I3: 9.5856291e+12 | J3: 2.2625327e+13 | K3: 3.4729901e+12 | L3: 1.7847279e+12 | M3: 7.6935896e+12 | N3: 3.9738031e+12 | O3: 1.0358009e+12 | P3: 1.1196511e+13 | Q3: 7.0587981e+12 | R3: 1.4356632e+12
A4: 2019 | B4: 2.2133908e+12 | C4: 2.2940028e+13 | D4: 5.2748125e+12 | E4: 4.0000081e+12 | F4: 4.0269673e+10 | G4: 0 | H4: 2.247126e+13 | I4: 9.657573e+12 | J4: 2.2959584e+13 | K4: 3.6091441e+12 | L4: 1.8570133e+12 | M4: 7.7664346e+12 | N4: 4.0920868e+12 | O4: 1.1108024e+12 | P4: 1.1639449e+13 | Q4: 7.3579835e+12 | R4: 1.4675337e+12
A5: 2020 | B5: 2.1976887e+12 | C5: 2.3414274e+13 | D5: 5.0491242e+12 | E5: 3.8938617e+12 | F5: 3.8434281e+10 | G5: 0 | H5: 2.1805056e+13 | I5: 9.010867e+12 | J5: 2.1647745e+13 | K5: 3.4873467e+12 | L5: 1.8109689e+12 | M5: 7.5186202e+12 | N5: 4.0196625e+12 | O5: 1.1369823e+12 | P5: 1.1101407e+13 | Q5: 6.9801053e+12 | R5: 1.4619342e+12
A6: 2021 | B6: 2.2922934e+12 | C6: 2.5384031e+13 | D6: 5.157301e+12 | E6: 4.1124744e+12 | F6: 3.9063361e+10 | G6: 0 | H6: 2.3079216e+13 | I6: 9.6742145e+12 | J6: 2.3137908e+13 | K6: 3.7167234e+12 | L6: 1.8994803e+12 | M6: 7.839315e+12 | N6: 4.2025456e+12 | O6: 1.1664138e+12 | P6: 1.2038788e+13 | Q6: 7.217632e+12 | R6: 1.4993493e+12
A7: 2022 | B7: 2.3521835e+12 | C7: 2.6114006e+13 | D7: 5.2103503e+12 | E7: 4.027358e+12 | F7: 4.1029307e+10 | G7: 0 | H7: 2.355516e+13 | I7: 1.0060458e+13 | J7: 2.4011132e+13 | K7: 3.8710787e+12 | L7: 1.7867605e+12 | M7: 8.2152249e+12 | N7: 4.3645601e+12 | O7: 1.2548544e+12 | P7: 1.282315e+13 | Q7: 7.5899889e+12 | R7: 1.5601639e+12
B9: 01_KOR | C9: 02_CHN | D9: 03_JPN | E9: 04_RUS | F9: 05_MNG | G9: 06_PRK | H9: 07_NAM | I9: 08_LAM | J9: 09_WEU | K9: 10_EEU | L9: 11_RFSU | M9: 12_MEA | N9: 13_AFR | O9: 14_RCPA | P9: 15_SAS | Q9: 16_RPAS | R9: 17_RPAO
A10: 2018 | B10: =B3/10^9 -> 2164.8129 | C10: =C3/10^9 -> 21684.385 | D10: =D3/10^9 -> 5296.1118 | E10: =E3/10^9 -> 3913.9759 | F10: =F3/10^9 -> 38.133349 | G10: =G3/10^9 -> 0 | H10: =H3/10^9 -> 21975.104 | I10: =I3/10^9 -> 9585.6291 | ... R10: =R3/10^9 -> 1435.6632
A11: 2019 | B11: =B4/10^9 -> 2213.3908 | C11: =C4/10^9 -> 22940.028 | D11: =D4/10^9 -> 5274.8125 | E11: =E4/10^9 -> 4000.0081 | F11: =F4/10^9 -> 40.269673 | G11: =G4/10^9 -> 0 | H11: =H4/10^9 -> 22471.26 | I11: =I4/10^9 -> 9657.573 | ... R11: =R4/10^9 -> 1467.5337
A12: 2020 | B12: =B5/10^9 -> 2197.6887 | C12: =C5/10^9 -> 23414.274 | D12: =D5/10^9 -> 5049.1242 | E12: =E5/10^9 -> 3893.8617 | F12: =F5/10^9 -> 38.434281 | G12: =G5/10^9 -> 0 | H12: =H5/10^9 -> 21805.056 | I12: =I5/10^9 -> 9010.867 | ... R12: =R5/10^9 -> 1461.9342
A13: 2021 | B13: =B6/10^9 -> 2292.2934 | C13: =C6/10^9 -> 25384.031 | D13: =D6/10^9 -> 5157.301 | E13: =E6/10^9 -> 4112.4744 | F13: =F6/10^9 -> 39.063361 | G13: =G6/10^9 -> 0 | H13: =H6/10^9 -> 23079.216 | I13: =I6/10^9 -> 9674.2145 | ... R13: =R6/10^9 -> 1499.3493
A14: 2022 | B14: =B7/10^9 -> 2352.1835 | C14: =C7/10^9 -> 26114.006 | D14: =D7/10^9 -> 5210.3503 | E14: =E7/10^9 -> 4027.358 | F14: =F7/10^9 -> 41.029307 | G14: =G7/10^9 -> 0 | H14: =H7/10^9 -> 23555.16 | I14: =I7/10^9 -> 10060.458 | ... R14: =R7/10^9 -> 1560.1639
A16: 인구
B17: 01_KOR | C17: 02_CHN | D17: 03_JPN | E17: 04_RUS | F17: 05_MNG | G17: 06_PRK | H17: 07_NAM | I17: 08_LAM | J17: 09_WEU | K17: 10_EEU | L17: 11_RFSU | M17: 12_MEA | N17: 13_AFR | O17: 14_RCPA | P17: 15_SAS | Q17: 16_RPAS | R17: 17_RPAO
A18: 2018 | B18: 51585058 | C18: 1410212600 | D18: 126811000 | E18: 144477859 | F18: 3163991 | G18: 25638149 | H18: 367372316 | I18: 606012845 | J18: 506509163 | K18: 118486004 | L18: 139697133 | M18: 492023500 | N18: 1041066783 | O18: 118044574 | P18: 1803847309 | Q18: 552136139 | R18: 29863858
A19: 2019 | B19: 51764822 | C19: 1415252900 | D19: 126633000 | E19: 144406261 | F19: 3232430 | G19: 25755441 | H19: 369400170 | I19: 612532624 | J19: 508668160 | K19: 118257396 | L19: 140624677 | M19: 500519921 | N19: 1068943284 | O19: 119196515 | P19: 1823829015 | Q19: 557765166 | R19: 30314026
A20: 2020 | B20: 51836239 | C20: 1418581000 | D20: 126261000 | E20: 144073139 | F20: 3294335 | G20: 25867467 | H20: 373075756 | I20: 618164742 | J20: 510362210 | K20: 117929343 | L20: 141549937 | M20: 507832010 | N20: 1097345524 | O20: 120364944 | P20: 1843559390 | Q20: 563056302 | R20: 30739448
A21: 2021 | B21: 51744876 | C21: 1419773100 | D21: 125681593 | E21: 144130482 | F21: 3347782 | G21: 25971909 | H21: 373797149 | I21: 622920825 | J21: 511423932 | K21: 117014414 | L21: 142366636 | M21: 514709028 | N21: 1125863096 | O21: 121482109 | P21: 1861812142 | Q21: 567555311 | R21: 30796812
B23: 01_KOR | C23: 02_CHN | D23: 03_JPN | E23: 04_RUS | F23: 05_MNG | G23: 06_PRK | H23: 07_NAM | I23: 08_LAM | J23: 09_WEU | K23: 10_EEU | L23: 11_RFSU | M23: 12_MEA | N23: 13_AFR | O23: 14_RCPA | P23: 15_SAS | Q23: 16_RPAS | R23: 17_RPAO
A24: 2018 | B24: =B18/1000000 -> 51.585058 | C24: =C18/1000000 -> 1410.2126 | D24: =D18/1000000 -> 126.811 | E24: =E18/1000000 -> 144.47786 | F24: =F18/1000000 -> 3.163991 | G24: =G18/1000000 -> 25.638149 | H24: =H18/1000000 -> 367.37232 | I24: =I18/1000000 -> 606.01284 | ... R24: =R18/1000000 -> 29.863858
A25: 2019 | B25: =B19/1000000 -> 51.764822 | C25: =C19/1000000 -> 1415.2529 | D25: =D19/1000000 -> 126.633 | E25: =E19/1000000 -> 144.40626 | F25: =F19/1000000 -> 3.23243 | G25: =G19/1000000 -> 25.755441 | H25: =H19/1000000 -> 369.40017 | I25: =I19/1000000 -> 612.53262 | ... R25: =R19/1000000 -> 30.314026
A26: 2020 | B26: =B20/1000000 -> 51.836239 | C26: =C20/1000000 -> 1418.581 | D26: =D20/1000000 -> 126.261 | E26: =E20/1000000 -> 144.07314 | F26: =F20/1000000 -> 3.294335 | G26: =G20/1000000 -> 25.867467 | H26: =H20/1000000 -> 373.07576 | I26: =I20/1000000 -> 618.16474 | ... R26: =R20/1000000 -> 30.739448
A27: 2021 | B27: =B21/1000000 -> 51.744876 | C27: =C21/1000000 -> 1419.7731 | D27: =D21/1000000 -> 125.68159 | E27: =E21/1000000 -> 144.13048 | F27: =F21/1000000 -> 3.347782 | G27: =G21/1000000 -> 25.971909 | H27: =H21/1000000 -> 373.79715 | I27: =I21/1000000 -> 622.92083 | ... R27: =R21/1000000 -> 30.796812

Sheet GDP
B1: 01_KOR | C1: 02_CHN | D1: 03_JPN | E1: 04_RUS | F1: 05_MNG | G1: 06_PRK | H1: 07_NAM | I1: 08_LAM | J1: 09_WEU | K1: 10_EEU | L1: 11_FSU | M1: 12_MEA | N1: 13_AFR | O1: 14_CPA | P1: 15_SAS | Q1: 16_PAS | R1: 17_PAO
A2: 2018 | B2: =Baseyear!B10 -> 2164.8129 | C2: =Baseyear!C10 -> 21684.385 | D2: =Baseyear!D10 -> 5296.1118 | E2: =Baseyear!E10 -> 3913.9759 | F2: =Baseyear!F10 -> 38.133349 | G2: 47.318147 | H2: =Baseyear!H10 -> 21975.104 | I2: =Baseyear!I10 -> 9585.6291 | J2: =Baseyear!J10 -> 22625.327 | K2: =Baseyear!K10 -> 3472.9901 | L2: =Baseyear!L10 -> 1784.7279 | M2: =Baseyear!M10 -> 7693.5896 | N2: =Baseyear!N10 -> 3973.8031 | O2: =Baseyear!O10 -> 1035.8009 | ... R2: =Baseyear!R10 -> 1435.6632
A3: 2019 | B3: =Baseyear!B11 -> 2213.3908 | C3: =Baseyear!C11 -> 22940.028 | D3: =Baseyear!D11 -> 5274.8125 | E3: =Baseyear!E11 -> 4000.0081 | F3: =Baseyear!F11 -> 40.269673 | G3: =G2+G2*Sheet1!$E$52 -> 47.436589 | H3: =Baseyear!H11 -> 22471.26 | I3: =Baseyear!I11 -> 9657.573 | J3: =Baseyear!J11 -> 22959.584 | K3: =Baseyear!K11 -> 3609.1441 | L3: =Baseyear!L11 -> 1857.0133 | M3: =Baseyear!M11 -> 7766.4346 | N3: =Baseyear!N11 -> 4092.0868 | O3: =Baseyear!O11 -> 1110.8024 | ... R3: =Baseyear!R11 -> 1467.5337
A4: 2020 | B4: =Baseyear!B12 -> 2197.6887 | C4: =Baseyear!C12 -> 23414.274 | D4: =Baseyear!D12 -> 5049.1242 | E4: =Baseyear!E12 -> 3893.8617 | F4: =Baseyear!F12 -> 38.434281 | G4: =G3+G3*Sheet1!$E$52 -> 47.555328 | H4: =Baseyear!H12 -> 21805.056 | I4: =Baseyear!I12 -> 9010.867 | J4: =Baseyear!J12 -> 21647.745 | K4: =Baseyear!K12 -> 3487.3467 | L4: =Baseyear!L12 -> 1810.9689 | M4: =Baseyear!M12 -> 7518.6202 | N4: =Baseyear!N12 -> 4019.6625 | O4: =Baseyear!O12 -> 1136.9823 | ... R4: =Baseyear!R12 -> 1461.9342
A5: 2021 | B5: =Baseyear!B13 -> 2292.2934 | C5: =Baseyear!C13 -> 25384.031 | D5: =Baseyear!D13 -> 5157.301 | E5: =Baseyear!E13 -> 4112.4744 | F5: =Baseyear!F13 -> 39.063361 | G5: =G4+G4*Sheet1!$E$52 -> 47.674364 | H5: =Baseyear!H13 -> 23079.216 | I5: =Baseyear!I13 -> 9674.2145 | J5: =Baseyear!J13 -> 23137.908 | K5: =Baseyear!K13 -> 3716.7234 | L5: =Baseyear!L13 -> 1899.4803 | M5: =Baseyear!M13 -> 7839.315 | N5: =Baseyear!N13 -> 4202.5456 | O5: =Baseyear!O13 -> 1166.4138 | ... R5: =Baseyear!R13 -> 1499.3493
A6: 2022 | B6: =(B9-B5)/4+B5 -> 2326.875 | C6: =(C9-C5)/4+C5 -> 26693.29 | D6: =(D9-D5)/4+D5 -> 5239.3933 | E6: =(E9-E5)/4+E5 -> 4066.9158 | F6: =(F9-F5)/4+F5 -> 41.001671 | G6: =G5+G5*Sheet1!$E$52 -> 47.793698 | H6: =(H9-H5)/4+H5 -> 23418.653 | I6: =(I9-I5)/4+I5 -> 9849.2318 | J6: =(J9-J5)/4+J5 -> 23256.562 | K6: =(K9-K5)/4+K5 -> 3775.4882 | L6: =(L9-L5)/4+L5 -> 1938.2091 | M6: =(M9-M5)/4+M5 -> 8141.163 | N6: =(N9-N5)/4+N5 -> 4377.0315 | O6: =(O9-O5)/4+O5 -> 1245.2884 | ... R6: =(R9-R5)/4+R5 -> 1526.1775
A7: 2023 | B7: =(B9-B5)/4+B6 -> 2361.4567 | C7: =(C9-C5)/4+C6 -> 28002.548 | D7: =(D9-D5)/4+D6 -> 5321.4855 | E7: =(E9-E5)/4+E6 -> 4021.3572 | F7: =(F9-F5)/4+F6 -> 42.939981 | G7: =G6+G6*Sheet1!$E$52 -> 47.913331 | H7: =(H9-H5)/4+H6 -> 23758.09 | I7: =(I9-I5)/4+I6 -> 10024.249 | J7: =(J9-J5)/4+J6 -> 23375.216 | K7: =(K9-K5)/4+K6 -> 3834.253 | L7: =(L9-L5)/4+L6 -> 1976.9379 | M7: =(M9-M5)/4+M6 -> 8443.011 | N7: =(N9-N5)/4+N6 -> 4551.5173 | O7: =(O9-O5)/4+O6 -> 1324.1629 | ... R7: =(R9-R5)/4+R6 -> 1553.0057
A8: 2024 | B8: =(B9-B5)/4+B7 -> 2396.0383 | C8: =(C9-C5)/4+C7 -> 29311.806 | D8: =(D9-D5)/4+D7 -> 5403.5778 | E8: =(E9-E5)/4+E7 -> 3975.7986 | F8: =(F9-F5)/4+F7 -> 44.87829 | G8: =G7+G7*Sheet1!$E$52 -> 48.033263 | H8: =(H9-H5)/4+H7 -> 24097.528 | I8: =(I9-I5)/4+I7 -> 10199.266 | J8: =(J9-J5)/4+J7 -> 23493.869 | K8: =(K9-K5)/4+K7 -> 3893.0178 | L8: =(L9-L5)/4+L7 -> 2015.6667 | M8: =(M9-M5)/4+M7 -> 8744.859 | N8: =(N9-N5)/4+N7 -> 4726.0031 | O8: =(O9-O5)/4+O7 -> 1403.0375 | ... R8: =(R9-R5)/4+R7 -> 1579.8338
A9: 2025 | B9: 2430.62 | C9: 30621.064 | D9: 5485.67 | E9: 3930.24 | F9: 46.8166 | G9: =G8+G8*Sheet1!$E$52 -> 48.153496 | H9: 24436.965 | I9: 10374.284 | J9: 23612.523 | K9: 3951.7826 | L9: 2054.3955 | M9: 9046.707 | N9: 4900.489 | O9: 1481.912 | P9: 15017.581 | Q9: 10167.424 | R9: 1606.662
A10: 2026 | B10: =(B14-B9)/5+B9 -> 2478.518 | C10: =(C14-C9)/5+C9 -> 31849.824 | D10: =(D14-D9)/5+D9 -> 5529.576 | E10: =(E14-E9)/5+E9 -> 3989.154 | F10: =(F14-F9)/5+F9 -> 48.72012 | G10: =G9+G9*Sheet1!$E$52 -> 48.274029 | H10: =(H14-H9)/5+H9 -> 24914.997 | I10: =(I14-I9)/5+I9 -> 10651.893 | J10: =(J14-J9)/5+J9 -> 24056.213 | K10: =(K14-K9)/5+K9 -> 4068.4402 | L10: =(L14-L9)/5+L9 -> 2134.8368 | M10: =(M14-M9)/5+M9 -> 9421.6885 | N10: =(N14-N9)/5+N9 -> 5142.243 | O10: =(O14-O9)/5+O9 -> 1595.2163 | ... R10: =(R14-R9)/5+R9 -> 1650.987
A11: 2027 | B11: =(B14-B9)/5+B10 -> 2526.416 | C11: =(C14-C9)/5+C10 -> 33078.584 | D11: =(D14-D9)/5+D10 -> 5573.482 | E11: =(E14-E9)/5+E10 -> 4048.068 | F11: =(F14-F9)/5+F10 -> 50.62364 | G11: =G10+G10*Sheet1!$E$52 -> 48.394865 | H11: =(H14-H9)/5+H10 -> 25393.029 | I11: =(I14-I9)/5+I10 -> 10929.503 | J11: =(J14-J9)/5+J10 -> 24499.904 | K11: =(K14-K9)/5+K10 -> 4185.0978 | L11: =(L14-L9)/5+L10 -> 2215.2781 | M11: =(M14-M9)/5+M10 -> 9796.67 | N11: =(N14-N9)/5+N10 -> 5383.997 | O11: =(O14-O9)/5+O10 -> 1708.5205 | ... R11: =(R14-R9)/5+R10 -> 1695.312
A12: 2028 | B12: =(B14-B9)/5+B11 -> 2574.314 | C12: =(C14-C9)/5+C11 -> 34307.343 | D12: =(D14-D9)/5+D11 -> 5617.388 | E12: =(E14-E9)/5+E11 -> 4106.982 | F12: =(F14-F9)/5+F11 -> 52.52716 | G12: =G11+G11*Sheet1!$E$52 -> 48.516002 | H12: =(H14-H9)/5+H11 -> 25871.06 | I12: =(I14-I9)/5+I11 -> 11207.113 | J12: =(J14-J9)/5+J11 -> 24943.594 | K12: =(K14-K9)/5+K11 -> 4301.7555 | L12: =(L14-L9)/5+L11 -> 2295.7194 | M12: =(M14-M9)/5+M11 -> 10171.652 | N12: =(N14-N9)/5+N11 -> 5625.751 | O12: =(O14-O9)/5+O11 -> 1821.8248 | ... R12: =(R14-R9)/5+R11 -> 1739.637
A13: 2029 | B13: =(B14-B9)/5+B12 -> 2622.212 | C13: =(C14-C9)/5+C12 -> 35536.103 | D13: =(D14-D9)/5+D12 -> 5661.294 | E13: =(E14-E9)/5+E12 -> 4165.896 | F13: =(F14-F9)/5+F12 -> 54.43068 | G13: =G12+G12*Sheet1!$E$52 -> 48.637443 | H13: =(H14-H9)/5+H12 -> 26349.092 | I13: =(I14-I9)/5+I12 -> 11484.723 | J13: =(J14-J9)/5+J12 -> 25387.285 | K13: =(K14-K9)/5+K12 -> 4418.4131 | L13: =(L14-L9)/5+L12 -> 2376.1607 | M13: =(M14-M9)/5+M12 -> 10546.633 | N13: =(N14-N9)/5+N12 -> 5867.505 | O13: =(O14-O9)/5+O12 -> 1935.129 | ... R13: =(R14-R9)/5+R12 -> 1783.962
A14: 2030 | B14: 2670.11 | C14: 36764.863 | D14: 5705.2 | E14: 4224.81 | F14: 56.3342 | G14: =G13+G13*Sheet1!$E$52 -> 48.759188 | H14: 26827.124 | I14: 11762.332 | J14: 25830.975 | K14: 4535.0707 | L14: 2456.602 | M14: 10921.615 | N14: 6109.2591 | O14: 2048.4333 | P14: 19888.556 | Q14: 12365.375 | R14: 1828.287
A15: 2031 | B15: =(B19-B14)/5+B14 -> 2705.06 | C15: =(C19-C14)/5+C14 -> 37877.798 | D15: =(D19-D14)/5+D14 -> 5753.91 | E15: =(E19-E14)/5+E14 -> 4306.92 | F15: =(F19-F14)/5+F14 -> 58.66914 | G15: =G14+G14*Sheet1!$E$52 -> 48.881237 | H15: =(H19-H14)/5+H14 -> 27266.258 | I15: =(I19-I14)/5+I14 -> 12120.367 | J15: =(J19-J14)/5+J14 -> 26283.442 | K15: =(K19-K14)/5+K14 -> 4630.3487 | L15: =(L19-L14)/5+L14 -> 2546.2138 | M15: =(M19-M14)/5+M14 -> 11346.631 | N15: =(N19-N14)/5+N14 -> 6457.7655 | O15: =(O19-O14)/5+O14 -> 2175.7444 | ... R15: =(R19-R14)/5+R14 -> 1875.4674
A16: 2032 | B16: =(B19-B14)/5+B15 -> 2740.01 | C16: =(C19-C14)/5+C15 -> 38990.734 | D16: =(D19-D14)/5+D15 -> 5802.62 | E16: =(E19-E14)/5+E15 -> 4389.03 | F16: =(F19-F14)/5+F15 -> 61.00408 | G16: =G15+G15*Sheet1!$E$52 -> 49.003592 | H16: =(H19-H14)/5+H15 -> 27705.391 | I16: =(I19-I14)/5+I15 -> 12478.401 | J16: =(J19-J14)/5+J15 -> 26735.909 | K16: =(K19-K14)/5+K15 -> 4725.6266 | L16: =(L19-L14)/5+L15 -> 2635.8256 | M16: =(M19-M14)/5+M15 -> 11771.648 | N16: =(N19-N14)/5+N15 -> 6806.2719 | O16: =(O19-O14)/5+O15 -> 2303.0556 | ... R16: =(R19-R14)/5+R15 -> 1922.6478
A17: 2033 | B17: =(B19-B14)/5+B16 -> 2774.96 | C17: =(C19-C14)/5+C16 -> 40103.669 | D17: =(D19-D14)/5+D16 -> 5851.33 | E17: =(E19-E14)/5+E16 -> 4471.14 | F17: =(F19-F14)/5+F16 -> 63.33902 | G17: =G16+G16*Sheet1!$E$52 -> 49.126254 | H17: =(H19-H14)/5+H16 -> 28144.525 | I17: =(I19-I14)/5+I16 -> 12836.435 | J17: =(J19-J14)/5+J16 -> 27188.376 | K17: =(K19-K14)/5+K16 -> 4820.9046 | L17: =(L19-L14)/5+L16 -> 2725.4374 | M17: =(M19-M14)/5+M16 -> 12196.665 | N17: =(N19-N14)/5+N16 -> 7154.7783 | O17: =(O19-O14)/5+O16 -> 2430.3667 | ... R17: =(R19-R14)/5+R16 -> 1969.8282
A18: 2034 | B18: =(B19-B14)/5+B17 -> 2809.91 | C18: =(C19-C14)/5+C17 -> 41216.605 | D18: =(D19-D14)/5+D17 -> 5900.04 | E18: =(E19-E14)/5+E17 -> 4553.25 | F18: =(F19-F14)/5+F17 -> 65.67396 | G18: =G17+G17*Sheet1!$E$52 -> 49.249222 | H18: =(H19-H14)/5+H17 -> 28583.659 | I18: =(I19-I14)/5+I17 -> 13194.469 | J18: =(J19-J14)/5+J17 -> 27640.843 | K18: =(K19-K14)/5+K17 -> 4916.1825 | L18: =(L19-L14)/5+L17 -> 2815.0492 | M18: =(M19-M14)/5+M17 -> 12621.682 | N18: =(N19-N14)/5+N17 -> 7503.2847 | O18: =(O19-O14)/5+O17 -> 2557.6779 | ... R18: =(R19-R14)/5+R17 -> 2017.0086
A19: 2035 | B19: 2844.86 | C19: 42329.54 | D19: 5948.75 | E19: 4635.36 | F19: 68.0089 | G19: =G18+G18*Sheet1!$E$52 -> 49.372498 | H19: 29022.792 | I19: 13552.503 | J19: 28093.31 | K19: 5011.4605 | L19: 2904.661 | M19: 13046.699 | N19: 7851.7912 | O19: 2684.989 | P19: 25206.623 | Q19: 14557.709 | R19: 2064.189
A20: 2036 | B20: =(B24-B19)/5+B19 -> 2869.73 | C20: =(C24-C19)/5+C19 -> 43218.37 | D20: =(D24-D19)/5+D19 -> 5990.412 | E20: =(E24-E19)/5+E19 -> 4720.446 | F20: =(F24-F19)/5+F19 -> 70.5476 | G20: =G19+G19*Sheet1!$E$52 -> 49.496083 | H20: =(H24-H19)/5+H19 -> 29443.005 | I20: =(I24-I19)/5+I19 -> 13976.933 | J20: =(J24-J19)/5+J19 -> 28563.244 | K20: =(K24-K19)/5+K19 -> 5090.027 | L20: =(L24-L19)/5+L19 -> 2993.979 | M20: =(M24-M19)/5+M19 -> 13522.139 | N20: =(N24-N19)/5+N19 -> 8283.5034 | O20: =(O24-O19)/5+O19 -> 2806.9882 | ... R20: =(R24-R19)/5+R19 -> 2114.3576
A21: 2037 | B21: =(B24-B19)/5+B20 -> 2894.6 | C21: =(C24-C19)/5+C20 -> 44107.2 | D21: =(D24-D19)/5+D20 -> 6032.074 | E21: =(E24-E19)/5+E20 -> 4805.532 | F21: =(F24-F19)/5+F20 -> 73.0863 | G21: =G20+G20*Sheet1!$E$52 -> 49.619977 | H21: =(H24-H19)/5+H20 -> 29863.218 | I21: =(I24-I19)/5+I20 -> 14401.363 | J21: =(J24-J19)/5+J20 -> 29033.178 | K21: =(K24-K19)/5+K20 -> 5168.5935 | L21: =(L24-L19)/5+L20 -> 3083.297 | M21: =(M24-M19)/5+M20 -> 13997.579 | N21: =(N24-N19)/5+N20 -> 8715.2157 | O21: =(O24-O19)/5+O20 -> 2928.9874 | ... R21: =(R24-R19)/5+R20 -> 2164.5262
A22: 2038 | B22: =(B24-B19)/5+B21 -> 2919.47 | C22: =(C24-C19)/5+C21 -> 44996.031 | D22: =(D24-D19)/5+D21 -> 6073.736 | E22: =(E24-E19)/5+E21 -> 4890.618 | F22: =(F24-F19)/5+F21 -> 75.625 | G22: =G21+G21*Sheet1!$E$52 -> 49.744181 | H22: =(H24-H19)/5+H21 -> 30283.431 | I22: =(I24-I19)/5+I21 -> 14825.793 | J22: =(J24-J19)/5+J21 -> 29503.112 | K22: =(K24-K19)/5+K21 -> 5247.1601 | L22: =(L24-L19)/5+L21 -> 3172.615 | M22: =(M24-M19)/5+M21 -> 14473.02 | N22: =(N24-N19)/5+N21 -> 9146.928 | O22: =(O24-O19)/5+O21 -> 3050.9866 | ... R22: =(R24-R19)/5+R21 -> 2214.6948
A23: 2039 | B23: =(B24-B19)/5+B22 -> 2944.34 | C23: =(C24-C19)/5+C22 -> 45884.861 | D23: =(D24-D19)/5+D22 -> 6115.398 | E23: =(E24-E19)/5+E22 -> 4975.704 | F23: =(F24-F19)/5+F22 -> 78.1637 | G23: =G22+G22*Sheet1!$E$52 -> 49.868696 | H23: =(H24-H19)/5+H22 -> 30703.644 | I23: =(I24-I19)/5+I22 -> 15250.223 | J23: =(J24-J19)/5+J22 -> 29973.046 | K23: =(K24-K19)/5+K22 -> 5325.7266 | L23: =(L24-L19)/5+L22 -> 3261.933 | M23: =(M24-M19)/5+M22 -> 14948.46 | N23: =(N24-N19)/5+N22 -> 9578.6402 | O23: =(O24-O19)/5+O22 -> 3172.9858 | ... R23: =(R24-R19)/5+R22 -> 2264.8634
A24: 2040 | B24: 2969.21 | C24: 46773.691 | D24: 6157.06 | E24: 5060.79 | F24: 80.7024 | G24: =G23+G23*Sheet1!$E$52 -> 49.993523 | H24: 31123.857 | I24: 15674.653 | J24: 30442.98 | K24: 5404.2931 | L24: 3351.251 | M24: 15423.9 | N24: 10010.353 | O24: 3294.985 | P24: 31038.545 | Q24: 16648.234 | R24: 2315.032
A25: 2041 | B25: =(B29-B24)/5+B24 -> 2987.112 | C25: =(C29-C24)/5+C24 -> 47622.001 | D25: =(D29-D24)/5+D24 -> 6199.932 | E25: =(E29-E24)/5+E24 -> 5147.096 | F25: =(F29-F24)/5+F24 -> 83.49678 | G25: =G24+G24*Sheet1!$E$52 -> 50.118662 | H25: =(H29-H24)/5+H24 -> 31536.282 | I25: =(I29-I24)/5+I24 -> 16158.705 | J25: =(J29-J24)/5+J24 -> 30926.463 | K25: =(K29-K24)/5+K24 -> 5463.7973 | L25: =(L29-L24)/5+L24 -> 3438.4935 | M25: =(M29-M24)/5+M24 -> 15943.352 | N25: =(N29-N24)/5+N24 -> 10549.574 | O25: =(O29-O24)/5+O24 -> 3412.5282 | ... R25: =(R29-R24)/5+R24 -> 2369.0262
A26: 2042 | B26: =(B29-B24)/5+B25 -> 3005.014 | C26: =(C29-C24)/5+C25 -> 48470.311 | D26: =(D29-D24)/5+D25 -> 6242.804 | E26: =(E29-E24)/5+E25 -> 5233.402 | F26: =(F29-F24)/5+F25 -> 86.29116 | G26: =G25+G25*Sheet1!$E$52 -> 50.244115 | H26: =(H29-H24)/5+H25 -> 31948.706 | I26: =(I29-I24)/5+I25 -> 16642.757 | J26: =(J29-J24)/5+J25 -> 31409.946 | K26: =(K29-K24)/5+K25 -> 5523.3015 | L26: =(L29-L24)/5+L25 -> 3525.736 | M26: =(M29-M24)/5+M25 -> 16462.804 | N26: =(N29-N24)/5+N25 -> 11088.796 | O26: =(O29-O24)/5+O25 -> 3530.0714 | ... R26: =(R29-R24)/5+R25 -> 2423.0204
A27: 2043 | B27: =(B29-B24)/5+B26 -> 3022.916 | C27: =(C29-C24)/5+C26 -> 49318.622 | D27: =(D29-D24)/5+D26 -> 6285.676 | E27: =(E29-E24)/5+E26 -> 5319.708 | F27: =(F29-F24)/5+F26 -> 89.08554 | G27: =G26+G26*Sheet1!$E$52 -> 50.369881 | H27: =(H29-H24)/5+H26 -> 32361.131 | I27: =(I29-I24)/5+I26 -> 17126.808 | J27: =(J29-J24)/5+J26 -> 31893.429 | K27: =(K29-K24)/5+K26 -> 5582.8058 | L27: =(L29-L24)/5+L26 -> 3612.9784 | M27: =(M29-M24)/5+M26 -> 16982.256 | N27: =(N29-N24)/5+N26 -> 11628.018 | O27: =(O29-O24)/5+O26 -> 3647.6146 | ... R27: =(R29-R24)/5+R26 -> 2477.0146
A28: 2044 | B28: =(B29-B24)/5+B27 -> 3040.818 | C28: =(C29-C24)/5+C27 -> 50166.932 | D28: =(D29-D24)/5+D27 -> 6328.548 | E28: =(E29-E24)/5+E27 -> 5406.014 | F28: =(F29-F24)/5+F27 -> 91.87992 | G28: =G27+G27*Sheet1!$E$52 -> 50.495962 | H28: =(H29-H24)/5+H27 -> 32773.556 | I28: =(I29-I24)/5+I27 -> 17610.86 | J28: =(J29-J24)/5+J27 -> 32376.912 | K28: =(K29-K24)/5+K27 -> 5642.31 | L28: =(L29-L24)/5+L27 -> 3700.2209 | M28: =(M29-M24)/5+M27 -> 17501.708 | N28: =(N29-N24)/5+N27 -> 12167.24 | O28: =(O29-O24)/5+O27 -> 3765.1578 | ... R28: =(R29-R24)/5+R27 -> 2531.0088
A29: 2045 | B29: 3058.72 | C29: 51015.242 | D29: 6371.42 | E29: 5492.32 | F29: 94.6743 | G29: =G28+G28*Sheet1!$E$52 -> 50.622359 | H29: 33185.981 | I29: 18094.912 | J29: 32860.395 | K29: 5701.8142 | L29: 3787.4634 | M29: 18021.16 | N29: 12706.461 | O29: 3882.701 | P29: 37446.154 | Q29: 18663.736 | R29: 2585.003
A30: 2046 | B30: =(B34-B29)/5+B29 -> 3071.018 | C30: =(C34-C29)/5+C29 -> 51805.812 | D30: =(D34-D29)/5+D29 -> 6416.856 | E30: =(E34-E29)/5+E29 -> 5579.152 | F30: =(F34-F29)/5+F29 -> 97.85204 | G30: =G29+G29*Sheet1!$E$52 -> 50.749073 | H30: =(H34-H29)/5+H29 -> 33594.991 | I30: =(I34-I29)/5+I29 -> 18627.56 | J30: =(J34-J29)/5+J29 -> 33342.219 | K30: =(K34-K29)/5+K29 -> 5751.5447 | L30: =(L34-L29)/5+L29 -> 3875.7253 | M30: =(M34-M29)/5+M29 -> 18588.185 | N30: =(N34-N29)/5+N29 -> 13375.645 | O30: =(O34-O29)/5+O29 -> 3997.011 | ... R30: =(R34-R29)/5+R29 -> 2641.005
A31: 2047 | B31: =(B34-B29)/5+B30 -> 3083.316 | C31: =(C34-C29)/5+C30 -> 52596.382 | D31: =(D34-D29)/5+D30 -> 6462.292 | E31: =(E34-E29)/5+E30 -> 5665.984 | F31: =(F34-F29)/5+F30 -> 101.02978 | G31: =G30+G30*Sheet1!$E$52 -> 50.876103 | H31: =(H34-H29)/5+H30 -> 34004.001 | I31: =(I34-I29)/5+I30 -> 19160.209 | J31: =(J34-J29)/5+J30 -> 33824.042 | K31: =(K34-K29)/5+K30 -> 5801.2751 | L31: =(L34-L29)/5+L30 -> 3963.9872 | M31: =(M34-M29)/5+M30 -> 19155.21 | N31: =(N34-N29)/5+N30 -> 14044.829 | O31: =(O34-O29)/5+O30 -> 4111.321 | ... R31: =(R34-R29)/5+R30 -> 2697.007
A32: 2048 | B32: =(B34-B29)/5+B31 -> 3095.614 | C32: =(C34-C29)/5+C31 -> 53386.953 | D32: =(D34-D29)/5+D31 -> 6507.728 | E32: =(E34-E29)/5+E31 -> 5752.816 | F32: =(F34-F29)/5+F31 -> 104.20752 | G32: =G31+G31*Sheet1!$E$52 -> 51.003451 | H32: =(H34-H29)/5+H31 -> 34413.011 | I32: =(I34-I29)/5+I31 -> 19692.857 | J32: =(J34-J29)/5+J31 -> 34305.865 | K32: =(K34-K29)/5+K31 -> 5851.0056 | L32: =(L34-L29)/5+L31 -> 4052.2492 | M32: =(M34-M29)/5+M31 -> 19722.235 | N32: =(N34-N29)/5+N31 -> 14714.013 | O32: =(O34-O29)/5+O31 -> 4225.631 | ... R32: =(R34-R29)/5+R31 -> 2753.009
A33: 2049 | B33: =(B34-B29)/5+B32 -> 3107.912 | C33: =(C34-C29)/5+C32 -> 54177.523 | D33: =(D34-D29)/5+D32 -> 6553.164 | E33: =(E34-E29)/5+E32 -> 5839.648 | F33: =(F34-F29)/5+F32 -> 107.38526 | G33: =G32+G32*Sheet1!$E$52 -> 51.131119 | H33: =(H34-H29)/5+H32 -> 34822.021 | I33: =(I34-I29)/5+I32 -> 20225.506 | J33: =(J34-J29)/5+J32 -> 34787.689 | K33: =(K34-K29)/5+K32 -> 5900.736 | L33: =(L34-L29)/5+L32 -> 4140.5111 | M33: =(M34-M29)/5+M32 -> 20289.261 | N33: =(N34-N29)/5+N32 -> 15383.197 | O33: =(O34-O29)/5+O32 -> 4339.941 | ... R33: =(R34-R29)/5+R32 -> 2809.011
A34: 2050 | B34: 3120.21 | C34: 54968.093 | D34: 6598.6 | E34: 5926.48 | F34: 110.563 | G34: =G33+G33*Sheet1!$E$52 -> 51.259105 | H34: 35231.031 | I34: 20758.154 | J34: 35269.512 | K34: 5950.4665 | L34: 4228.773 | M34: 20856.286 | N34: 16052.381 | O34: 4454.251 | P34: 44472.414 | Q34: 20623.289 | R34: 2865.013
A35: 2051 | B35: =(B39-B34)/5+B34 -> 3125.836 | C35: =(C39-C34)/5+C34 -> 55653.318 | D35: =(D39-D34)/5+D34 -> 6642.002 | E35: =(E39-E34)/5+E34 -> 6021.756 | F35: =(F39-F34)/5+F34 -> 114.2586 | G35: =G34+G34*Sheet1!$E$52 -> 51.387412 | H35: =(H39-H34)/5+H34 -> 35646.204 | I35: =(I39-I34)/5+I34 -> 21332.94 | J35: =(J39-J34)/5+J34 -> 35747.529 | K35: =(K39-K34)/5+K34 -> 5994.5824 | L35: =(L39-L34)/5+L34 -> 4322.4437 | M35: =(M39-M34)/5+M34 -> 21483.536 | N35: =(N39-N34)/5+N34 -> 16877.119 | O35: =(O39-O34)/5+O34 -> 4568.3928 | ... R35: =(R39-R34)/5+R34 -> 2921.867
A36: 2052 | B36: =(B39-B34)/5+B35 -> 3131.462 | C36: =(C39-C34)/5+C35 -> 56338.544 | D36: =(D39-D34)/5+D35 -> 6685.404 | E36: =(E39-E34)/5+E35 -> 6117.032 | F36: =(F39-F34)/5+F35 -> 117.9542 | G36: =G35+G35*Sheet1!$E$52 -> 51.516041 | H36: =(H39-H34)/5+H35 -> 36061.376 | I36: =(I39-I34)/5+I35 -> 21907.726 | J36: =(J39-J34)/5+J35 -> 36225.546 | K36: =(K39-K34)/5+K35 -> 6038.6982 | L36: =(L39-L34)/5+L35 -> 4416.1144 | M36: =(M39-M34)/5+M35 -> 22110.786 | N36: =(N39-N34)/5+N35 -> 17701.858 | O36: =(O39-O34)/5+O35 -> 4682.5346 | ... R36: =(R39-R34)/5+R35 -> 2978.721
A37: 2053 | B37: =(B39-B34)/5+B36 -> 3137.088 | C37: =(C39-C34)/5+C36 -> 57023.769 | D37: =(D39-D34)/5+D36 -> 6728.806 | E37: =(E39-E34)/5+E36 -> 6212.308 | F37: =(F39-F34)/5+F36 -> 121.6498 | G37: =G36+G36*Sheet1!$E$52 -> 51.644991 | H37: =(H39-H34)/5+H36 -> 36476.549 | I37: =(I39-I34)/5+I36 -> 22482.512 | J37: =(J39-J34)/5+J36 -> 36703.563 | K37: =(K39-K34)/5+K36 -> 6082.8141 | L37: =(L39-L34)/5+L36 -> 4509.785 | M37: =(M39-M34)/5+M36 -> 22738.036 | N37: =(N39-N34)/5+N36 -> 18526.596 | O37: =(O39-O34)/5+O36 -> 4796.6764 | ... R37: =(R39-R34)/5+R36 -> 3035.575
A38: 2054 | B38: =(B39-B34)/5+B37 -> 3142.714 | C38: =(C39-C34)/5+C37 -> 57708.995 | D38: =(D39-D34)/5+D37 -> 6772.208 | E38: =(E39-E34)/5+E37 -> 6307.584 | F38: =(F39-F34)/5+F37 -> 125.3454 | G38: =G37+G37*Sheet1!$E$52 -> 51.774264 | H38: =(H39-H34)/5+H37 -> 36891.721 | I38: =(I39-I34)/5+I37 -> 23057.299 | J38: =(J39-J34)/5+J37 -> 37181.58 | K38: =(K39-K34)/5+K37 -> 6126.9299 | L38: =(L39-L34)/5+L37 -> 4603.4557 | M38: =(M39-M34)/5+M37 -> 23365.286 | N38: =(N39-N34)/5+N37 -> 19351.335 | O38: =(O39-O34)/5+O37 -> 4910.8182 | ... R38: =(R39-R34)/5+R37 -> 3092.429
A39: 2055 | B39: 3148.34 | C39: 58394.22 | D39: 6815.61 | E39: 6402.86 | F39: 129.041 | G39: =G38+G38*Sheet1!$E$52 -> 51.903861 | H39: 37306.894 | I39: 23632.085 | J39: 37659.597 | K39: 6171.0458 | L39: 4697.1264 | M39: 23992.536 | N39: 20176.073 | O39: 5024.96 | P39: 52180.754 | Q39: 22604.325 | R39: 3149.283
A40: 2056 | B40: =(B44-B39)/5+B39 -> 3148.094 | C40: =(C44-C39)/5+C39 -> 59054.777 | D40: =(D44-D39)/5+D39 -> 6854.064 | E40: =(E44-E39)/5+E39 -> 6512.924 | F40: =(F44-F39)/5+F39 -> 133.334 | G40: =G39+G39*Sheet1!$E$52 -> 52.033782 | H40: =(H44-H39)/5+H39 -> 37733.159 | I40: =(I44-I39)/5+I39 -> 24240.385 | J40: =(J44-J39)/5+J39 -> 38136.562 | K40: =(K44-K39)/5+K39 -> 6212.4034 | L40: =(L44-L39)/5+L39 -> 4799.752 | M40: =(M44-M39)/5+M39 -> 24685.544 | N40: =(N44-N39)/5+N39 -> 21181.827 | O40: =(O44-O39)/5+O39 -> 5139.3432 | ... R40: =(R44-R39)/5+R39 -> 3208.3142
...

Sheet Sheet1
A1: Country or Area | B1: Year | C1: Item | D1: Value
A2: Democratic People's Republic of Korea | B2: 1970 | C2: Gross Domestic Product (GDP) | D2: 4.9273326e+09
A3: Democratic People's Republic of Korea | B3: 1971 | C3: Gross Domestic Product (GDP) | D3: 5.4397752e+09
A4: Democratic People's Republic of Korea | B4: 1972 | C4: Gross Domestic Product (GDP) | D4: 6.0055118e+09
A5: Democratic People's Republic of Korea | B5: 1973 | C5: Gross Domestic Product (GDP) | D5: 6.630085e+09
A6: Democratic People's Republic of Korea | B6: 1974 | C6: Gross Domestic Product (GDP) | D6: 7.3196139e+09
A7: Democratic People's Republic of Korea | B7: 1975 | C7: Gross Domestic Product (GDP) | D7: 8.0808537e+09
A8: Democratic People's Republic of Korea | B8: 1976 | C8: Gross Domestic Product (GDP) | D8: 8.4121687e+09
A9: Democratic People's Republic of Korea | B9: 1977 | C9: Gross Domestic Product (GDP) | D9: 8.7570676e+09
A10: Democratic People's Republic of Korea | B10: 1978 | C10: Gross Domestic Product (GDP) | D10: 9.1161074e+09
A11: Democratic People's Republic of Korea | B11: 1979 | C11: Gross Domestic Product (GDP) | D11: 9.4898678e+09
A12: Democratic People's Republic of Korea | B12: 1980 | C12: Gross Domestic Product (GDP) | D12: 9.8789524e+09
A13: Democratic People's Republic of Korea | B13: 1981 | C13: Gross Domestic Product (GDP) | D13: 1.0244474e+10
... A51: Democratic People's Republic of Korea | B51: 2019 | C51: Gross Domestic Product (GDP) | D51: 1.6331452e+10
A52: Democratic People's Republic of Korea | B52: 2020 | C52: Gross Domestic Product (GDP) | D52: 1.5847372e+10 | E52: =(D52/D22)^(1/30)-1 -> 0.0025031086
A53: Democratic People's Republic of Korea | B53: 2021 | C53: Gross Domestic Product (GDP) | D53: 1.6750453e+10
A54: Democratic People's Republic of Korea | B54: 2022 | C54: Gross Domestic Product (GDP) | D54: 1.5176135e+10
A55: Democratic People's Republic of Korea | B55: 2023 | C55: Gross Domestic Product (GDP) | D55: 1.6446632e+10
A56: Democratic People's Republic of Korea | B56: 2024 | C56: Gross Domestic Product (GDP) | D56: 1.7199288e+10

Sheet TOT_POP
B1: 01_KOR | C1: 02_CHN | D1: 03_JPN | E1: 04_RUS | F1: 05_MNG | G1: 06_PRK | H1: 07_NAM | I1: 08_LAM | J1: 09_WEU | K1: 10_EEU | L1: 11_FSU | M1: 12_MEA | N1: 13_AFR | O1: 14_CPA | P1: 15_SAS | Q1: 16_PAS | R1: 17_PAO
A2: 2018 | B2: =Baseyear!B24 -> 51.585058 | C2: =Baseyear!C24 -> 1410.2126 | D2: =Baseyear!D24 -> 126.811 | E2: =Baseyear!E24 -> 144.47786 | F2: =Baseyear!F24 -> 3.163991 | G2: =Baseyear!G24 -> 25.638149 | H2: =Baseyear!H24 -> 367.37232 | I2: =Baseyear!I24 -> 606.01284 | ... R2: =Baseyear!R24 -> 29.863858
A3: 2019 | B3: =Baseyear!B25 -> 51.764822 | C3: =Baseyear!C25 -> 1415.2529 | D3: =Baseyear!D25 -> 126.633 | E3: =Baseyear!E25 -> 144.40626 | F3: =Baseyear!F25 -> 3.23243 | G3: =Baseyear!G25 -> 25.755441 | H3: =Baseyear!H25 -> 369.40017 | I3: =Baseyear!I25 -> 612.53262 | ... R3: =Baseyear!R25 -> 30.314026
A4: 2020 | B4: 51.858125 | C4: 1431.4999 | D4: 125.54277 | E4: 145.76166 | F4: 3.26646 | G4: 25.813238 | H4: 376.69581 | I4: 616.16249 | J4: 507.43512 | K4: 119.39772 | L4: 147.826 | M4: 504.77669 | N4: 1056.8717 | O4: 119.76551 | P4: 1833.4695 | Q4: 585.76563 | R4: 30.570668
A5: 2021 | B5: =(B9-B4)/5+B4 -> 51.786592 | C5: =(C9-C4)/5+C4 -> 1431.9813 | D5: =(D9-D4)/5+D4 -> 124.92877 | E5: =(E9-E4)/5+E4 -> 145.68343 | F5: =(F9-F4)/5+F4 -> 3.3146956 | G5: =(G9-G4)/5+G4 -> 25.930335 | H5: =(H9-H4)/5+H4 -> 378.16362 | I5: =(I9-I4)/5+I4 -> 620.40692 | ... R5: =(R9-R4)/5+R4 -> 30.805844
A6: 2022 | B6: =(B9-B4)/5+B5 -> 51.715059 | C6: =(C9-C4)/5+C5 -> 1432.4626 | D6: =(D9-D4)/5+D5 -> 124.31477 | E6: =(E9-E4)/5+E5 -> 145.60519 | F6: =(F9-F4)/5+F5 -> 3.3629312 | G6: =(G9-G4)/5+G5 -> 26.047432 | H6: =(H9-H4)/5+H5 -> 379.63143 | I6: =(I9-I4)/5+I5 -> 624.65136 | ... R6: =(R9-R4)/5+R5 -> 31.04102
A7: 2023 | B7: =(B9-B4)/5+B6 -> 51.643525 | C7: =(C9-C4)/5+C6 -> 1432.9439 | D7: =(D9-D4)/5+D6 -> 123.70077 | E7: =(E9-E4)/5+E6 -> 145.52696 | F7: =(F9-F4)/5+F6 -> 3.4111668 | G7: =(G9-G4)/5+G6 -> 26.164528 | H7: =(H9-H4)/5+H6 -> 381.09923 | I7: =(I9-I4)/5+I6 -> 628.89579 | ... R7: =(R9-R4)/5+R6 -> 31.276195
A8: 2024 | B8: =(B9-B4)/5+B7 -> 51.571992 | C8: =(C9-C4)/5+C7 -> 1433.4252 | D8: =(D9-D4)/5+D7 -> 123.08677 | E8: =(E9-E4)/5+E7 -> 145.44873 | F8: =(F9-F4)/5+F7 -> 3.4594024 | G8: =(G9-G4)/5+G7 -> 26.281625 | H8: =(H9-H4)/5+H7 -> 382.56704 | I8: =(I9-I4)/5+I7 -> 633.14023 | ... R8: =(R9-R4)/5+R7 -> 31.511371
A9: 2025 | B9: 51.500459 | C9: 1433.9066 | D9: 122.47277 | E9: 145.3705 | F9: 3.507638 | G9: 26.398722 | H9: 384.03485 | I9: 637.38466 | J9: 513.37254 | K9: 118.39289 | L9: 145.58631 | M9: 546.38378 | N9: 1198.3107 | O9: 124.87487 | P9: 1923.8986 | Q9: 609.50494 | R9: 31.746547
A10: 2026 | B10: =(B14-B9)/5+B9 -> 51.396674 | C10: =(C14-C9)/5+C9 -> 1431.8895 | D10: =(D14-D9)/5+D9 -> 121.84778 | E10: =(E14-E9)/5+E9 -> 144.97634 | F10: =(F14-F9)/5+F9 -> 3.5508772 | G10: =(G14-G9)/5+G9 -> 26.425373 | H10: =(H14-H9)/5+H9 -> 385.70267 | I10: =(I14-I9)/5+I9 -> 641.62507 | ... R10: =(R14-R9)/5+R9 -> 31.972087
A11: 2027 | B11: =(B14-B9)/5+B10 -> 51.292888 | C11: =(C14-C9)/5+C10 -> 1429.8724 | D11: =(D14-D9)/5+D10 -> 121.22278 | E11: =(E14-E9)/5+E10 -> 144.58219 | F11: =(F14-F9)/5+F10 -> 3.5941164 | G11: =(G14-G9)/5+G10 -> 26.452023 | H11: =(H14-H9)/5+H10 -> 387.3705 | I11: =(I14-I9)/5+I10 -> 645.86548 | ... R11: =(R14-R9)/5+R10 -> 32.197627
A12: 2028 | B12: =(B14-B9)/5+B11 -> 51.189103 | C12: =(C14-C9)/5+C11 -> 1427.8553 | D12: =(D14-D9)/5+D11 -> 120.59779 | E12: =(E14-E9)/5+E11 -> 144.18804 | F12: =(F14-F9)/5+F11 -> 3.6373556 | G12: =(G14-G9)/5+G11 -> 26.478674 | H12: =(H14-H9)/5+H11 -> 389.03832 | I12: =(I14-I9)/5+I11 -> 650.10589 | ... R12: =(R14-R9)/5+R11 -> 32.423167
A13: 2029 | B13: =(B14-B9)/5+B12 -> 51.085317 | C13: =(C14-C9)/5+C12 -> 1425.8382 | D13: =(D14-D9)/5+D12 -> 119.9728 | E13: =(E14-E9)/5+E12 -> 143.79388 | F13: =(F14-F9)/5+F12 -> 3.6805948 | G13: =(G14-G9)/5+G12 -> 26.505324 | H13: =(H14-H9)/5+H12 -> 390.70614 | I13: =(I14-I9)/5+I12 -> 654.3463 | ... R13: =(R14-R9)/5+R12 -> 32.648707
A14: 2030 | B14: 50.981532 | C14: 1423.8211 | D14: 119.3478 | E14: 143.39973 | F14: 3.723834 | G14: 26.531975 | H14: 392.37396 | I14: 658.58671 | J14: 517.43296 | K14: 115.68046 | L14: 150.99513 | M14: 586.7984 | N14: 1349.9982 | O14: 129.11908 | P14: 2014.7081 | Q14: 631.96893 | R14: 32.874247
A15: 2031 | B15: =(B19-B14)/5+B14 -> 50.836034 | C15: =(C19-C14)/5+C14 -> 1420.3344 | D15: =(D19-D14)/5+D14 -> 118.68838 | E15: =(E19-E14)/5+E14 -> 143.03333 | F15: =(F19-F14)/5+F14 -> 3.7658628 | G15: =(G19-G14)/5+G14 -> 26.500876 | H15: =(H19-H14)/5+H14 -> 394.00155 | I15: =(I19-I14)/5+I14 -> 662.13351 | ... R15: =(R19-R14)/5+R14 -> 33.083355
A16: 2032 | B16: =(B19-B14)/5+B15 -> 50.690536 | C16: =(C19-C14)/5+C15 -> 1416.8477 | D16: =(D19-D14)/5+D15 -> 118.02895 | E16: =(E19-E14)/5+E15 -> 142.66693 | F16: =(F19-F14)/5+F15 -> 3.8078916 | G16: =(G19-G14)/5+G15 -> 26.469777 | H16: =(H19-H14)/5+H15 -> 395.62915 | I16: =(I19-I14)/5+I15 -> 665.6803 | ... R16: =(R19-R14)/5+R15 -> 33.292463
A17: 2033 | B17: =(B19-B14)/5+B16 -> 50.545039 | C17: =(C19-C14)/5+C16 -> 1413.361 | D17: =(D19-D14)/5+D16 -> 117.36953 | E17: =(E19-E14)/5+E16 -> 142.30052 | F17: =(F19-F14)/5+F16 -> 3.8499204 | G17: =(G19-G14)/5+G16 -> 26.438679 | H17: =(H19-H14)/5+H16 -> 397.25675 | I17: =(I19-I14)/5+I16 -> 669.2271 | ... R17: =(R19-R14)/5+R16 -> 33.501572
A18: 2034 | B18: =(B19-B14)/5+B17 -> 50.399541 | C18: =(C19-C14)/5+C17 -> 1409.8743 | D18: =(D19-D14)/5+D17 -> 116.7101 | E18: =(E19-E14)/5+E17 -> 141.93412 | F18: =(F19-F14)/5+F17 -> 3.8919492 | G18: =(G19-G14)/5+G17 -> 26.40758 | H18: =(H19-H14)/5+H17 -> 398.88435 | I18: =(I19-I14)/5+I17 -> 672.7739 | ... R18: =(R19-R14)/5+R17 -> 33.71068
A19: 2035 | B19: 50.254043 | C19: 1406.3876 | D19: 116.05068 | E19: 141.56772 | F19: 3.933978 | G19: 26.376481 | H19: 400.51195 | I19: 676.32069 | J19: 521.14012 | K19: 112.84864 | L19: 155.38455 | M19: 625.26124 | N19: 1508.5646 | O19: 132.35367 | P19: 2093.8538 | Q19: 650.60012 | R19: 33.919788
A20: 2036 | B20: =(B24-B19)/5+B19 -> 50.048539 | C20: =(C24-C19)/5+C19 -> 1401.7501 | D20: =(D24-D19)/5+D19 -> 115.37368 | E20: =(E24-E19)/5+E19 -> 141.2922 | F20: =(F24-F19)/5+F19 -> 3.9761666 | G20: =(G24-G19)/5+G19 -> 26.316701 | H20: =(H24-H19)/5+H19 -> 402.03983 | I20: =(I24-I19)/5+I19 -> 679.09036 | ... R20: =(R24-R19)/5+R19 -> 34.116764
A21: 2037 | B21: =(B24-B19)/5+B20 -> 49.843035 | C21: =(C24-C19)/5+C20 -> 1397.1126 | D21: =(D24-D19)/5+D20 -> 114.69669 | E21: =(E24-E19)/5+E20 -> 141.01669 | F21: =(F24-F19)/5+F20 -> 4.0183552 | G21: =(G24-G19)/5+G20 -> 26.256921 | H21: =(H24-H19)/5+H20 -> 403.56771 | I21: =(I24-I19)/5+I20 -> 681.86003 | ... R21: =(R24-R19)/5+R20 -> 34.313741
A22: 2038 | B22: =(B24-B19)/5+B21 -> 49.637532 | C22: =(C24-C19)/5+C21 -> 1392.4751 | D22: =(D24-D19)/5+D21 -> 114.01969 | E22: =(E24-E19)/5+E21 -> 140.74117 | F22: =(F24-F19)/5+F21 -> 4.0605438 | G22: =(G24-G19)/5+G21 -> 26.197142 | H22: =(H24-H19)/5+H21 -> 405.09559 | I22: =(I24-I19)/5+I21 -> 684.62969 | ... R22: =(R24-R19)/5+R21 -> 34.510717
A23: 2039 | B23: =(B24-B19)/5+B22 -> 49.432028 | C23: =(C24-C19)/5+C22 -> 1387.8376 | D23: =(D24-D19)/5+D22 -> 113.3427 | E23: =(E24-E19)/5+E22 -> 140.46566 | F23: =(F24-F19)/5+F22 -> 4.1027324 | G23: =(G24-G19)/5+G22 -> 26.137362 | H23: =(H24-H19)/5+H22 -> 406.62348 | I23: =(I24-I19)/5+I22 -> 687.39936 | ... R23: =(R24-R19)/5+R22 -> 34.707694
A24: 2040 | B24: 49.226524 | C24: 1383.2001 | D24: 112.66571 | E24: 140.19014 | F24: 4.144921 | G24: 26.077582 | H24: 408.15136 | I24: 690.16902 | J24: 524.74761 | K24: 110.07122 | L24: 159.16709 | M24: 661.96793 | N24: 1671.6665 | O24: 134.75628 | P24: 2159.9012 | Q24: 664.89658 | R24: 34.90467
A25: 2041 | B25: =(B29-B24)/5+B24 -> 48.96557 | C25: =(C29-C24)/5+C24 -> 1377.1165 | D25: =(D29-D24)/5+D24 -> 111.98516 | E25: =(E29-E24)/5+E24 -> 140.01852 | F25: =(F29-F24)/5+F24 -> 4.1871994 | G25: =(G29-G24)/5+G24 -> 25.996516 | H25: =(H29-H24)/5+H24 -> 409.55809 | I25: =(I29-I24)/5+I24 -> 692.1472 | ... R25: =(R29-R24)/5+R24 -> 35.097881
A26: 2042 | B26: =(B29-B24)/5+B25 -> 48.704617 | C26: =(C29-C24)/5+C25 -> 1371.0329 | D26: =(D29-D24)/5+D25 -> 111.30461 | E26: =(E29-E24)/5+E25 -> 139.8469 | F26: =(F29-F24)/5+F25 -> 4.2294778 | G26: =(G29-G24)/5+G25 -> 25.91545 | H26: =(H29-H24)/5+H25 -> 410.96481 | I26: =(I29-I24)/5+I25 -> 694.12538 | ... R26: =(R29-R24)/5+R25 -> 35.291091
A27: 2043 | B27: =(B29-B24)/5+B26 -> 48.443663 | C27: =(C29-C24)/5+C26 -> 1364.9493 | D27: =(D29-D24)/5+D26 -> 110.62407 | E27: =(E29-E24)/5+E26 -> 139.67528 | F27: =(F29-F24)/5+F26 -> 4.2717562 | G27: =(G29-G24)/5+G26 -> 25.834384 | H27: =(H29-H24)/5+H26 -> 412.37154 | I27: =(I29-I24)/5+I26 -> 696.10356 | ... R27: =(R29-R24)/5+R26 -> 35.484302
A28: 2044 | B28: =(B29-B24)/5+B27 -> 48.18271 | C28: =(C29-C24)/5+C27 -> 1358.8658 | D28: =(D29-D24)/5+D27 -> 109.94352 | E28: =(E29-E24)/5+E27 -> 139.50366 | F28: =(F29-F24)/5+F27 -> 4.3140346 | G28: =(G29-G24)/5+G27 -> 25.753318 | H28: =(H29-H24)/5+H27 -> 413.77827 | I28: =(I29-I24)/5+I27 -> 698.08174 | ... R28: =(R29-R24)/5+R27 -> 35.677512
A29: 2045 | B29: 47.921756 | C29: 1352.7822 | D29: 109.26298 | E29: 139.33204 | F29: 4.356313 | G29: 25.672252 | H29: 415.185 | I29: 700.05993 | J29: 528.14209 | K29: 107.42978 | L29: 162.41989 | M29: 696.25875 | N29: 1836.4752 | O29: 136.36771 | P29: 2211.6873 | Q29: 675.10224 | R29: 35.870723
A30: 2046 | B30: =(B34-B29)/5+B29 -> 47.630087 | C30: =(C34-C29)/5+C29 -> 1344.917 | D30: =(D34-D29)/5+D29 -> 108.60672 | E30: =(E34-E29)/5+E29 -> 139.21691 | F30: =(F34-F29)/5+F29 -> 4.3974436 | G30: =(G34-G29)/5+G29 -> 25.58005 | H30: =(H34-H29)/5+H29 -> 416.51918 | I30: =(I34-I29)/5+I29 -> 701.26522 | ... R30: =(R34-R29)/5+R29 -> 36.065335
A31: 2047 | B31: =(B34-B29)/5+B30 -> 47.338418 | C31: =(C34-C29)/5+C30 -> 1337.0518 | D31: =(D34-D29)/5+D30 -> 107.95046 | E31: =(E34-E29)/5+E30 -> 139.10179 | F31: =(F34-F29)/5+F30 -> 4.4385742 | G31: =(G34-G29)/5+G30 -> 25.487849 | H31: =(H34-H29)/5+H30 -> 417.85336 | I31: =(I34-I29)/5+I30 -> 702.47052 | ... R31: =(R34-R29)/5+R30 -> 36.259947
A32: 2048 | B32: =(B34-B29)/5+B31 -> 47.046749 | C32: =(C34-C29)/5+C31 -> 1329.1866 | D32: =(D34-D29)/5+D31 -> 107.29421 | E32: =(E34-E29)/5+E31 -> 138.98667 | F32: =(F34-F29)/5+F31 -> 4.4797048 | G32: =(G34-G29)/5+G31 -> 25.395647 | H32: =(H34-H29)/5+H31 -> 419.18754 | I32: =(I34-I29)/5+I31 -> 703.67581 | ... R32: =(R34-R29)/5+R31 -> 36.45456
A33: 2049 | B33: =(B34-B29)/5+B32 -> 46.75508 | C33: =(C34-C29)/5+C32 -> 1321.3215 | D33: =(D34-D29)/5+D32 -> 106.63795 | E33: =(E34-E29)/5+E32 -> 138.87154 | F33: =(F34-F29)/5+F32 -> 4.5208354 | G33: =(G34-G29)/5+G32 -> 25.303446 | H33: =(H34-H29)/5+H32 -> 420.52173 | I33: =(I34-I29)/5+I32 -> 704.88111 | ... R33: =(R34-R29)/5+R32 -> 36.649172
A34: 2050 | B34: 46.463411 | C34: 1313.4563 | D34: 105.9817 | E34: 138.75642 | F34: 4.561966 | G34: 25.211244 | H34: 421.85591 | I34: 706.0864 | J34: 531.08102 | K34: 104.9802 | L34: 165.04495 | M34: 726.99012 | N34: 2000.0515 | O34: 137.28632 | P34: 2249.7629 | Q34: 681.38847 | R34: 36.843784
A35: 2051 | B35: =(B39-B34)/5+B34 -> 46.094153 | C35: =(C39-C34)/5+C34 -> 1303.7605 | D35: =(D39-D34)/5+D34 -> 105.35577 | E35: =(E39-E34)/5+E34 -> 138.59887 | F35: =(F39-F34)/5+F34 -> 4.5982444 | G35: =(G39-G34)/5+G34 -> 25.105476 | H35: =(H39-H34)/5+H34 -> 422.99722 | I35: =(I39-I34)/5+I34 -> 706.61199 | ... R35: =(R39-R34)/5+R34 -> 37.023302
A36: 2052 | B36: =(B39-B34)/5+B35 -> 45.724894 | C36: =(C39-C34)/5+C35 -> 1294.0648 | D36: =(D39-D34)/5+D35 -> 104.72984 | E36: =(E39-E34)/5+E35 -> 138.44131 | F36: =(F39-F34)/5+F35 -> 4.6345228 | G36: =(G39-G34)/5+G35 -> 24.999709 | H36: =(H39-H34)/5+H35 -> 424.13853 | I36: =(I39-I34)/5+I35 -> 707.13758 | ... R36: =(R39-R34)/5+R35 -> 37.20282
A37: 2053 | B37: =(B39-B34)/5+B36 -> 45.355636 | C37: =(C39-C34)/5+C36 -> 1284.3691 | D37: =(D39-D34)/5+D36 -> 104.10391 | E37: =(E39-E34)/5+E36 -> 138.28376 | F37: =(F39-F34)/5+F36 -> 4.6708012 | G37: =(G39-G34)/5+G36 -> 24.893941 | H37: =(H39-H34)/5+H36 -> 425.27983 | I37: =(I39-I34)/5+I36 -> 707.66317 | ... R37: =(R39-R34)/5+R36 -> 37.382339
A38: 2054 | B38: =(B39-B34)/5+B37 -> 44.986377 | C38: =(C39-C34)/5+C37 -> 1274.6733 | D38: =(D39-D34)/5+D37 -> 103.47798 | E38: =(E39-E34)/5+E37 -> 138.12621 | F38: =(F39-F34)/5+F37 -> 4.7070796 | G38: =(G39-G34)/5+G37 -> 24.788174 | H38: =(H39-H34)/5+H37 -> 426.42114 | I38: =(I39-I34)/5+I37 -> 708.18876 | ... R38: =(R39-R34)/5+R37 -> 37.561857
A39: 2055 | B39: 44.617119 | C39: 1264.9776 | D39: 102.85205 | E39: 137.96866 | F39: 4.743358 | G39: 24.682406 | H39: 427.56245 | I39: 708.71435 | J39: 532.38073 | K39: 102.57122 | L39: 166.81242 | M39: 753.38509 | N39: 2158.1484 | O39: 137.57931 | P39: 2277.057 | Q39: 684.24752 | R39: 37.741375
A40: 2056 | B40: =(B44-B39)/5+B39 -> 44.188614 | C40: =(C44-C39)/5+C39 -> 1254.0888 | D40: =(D44-D39)/5+D39 -> 102.22836 | E40: =(E44-E39)/5+E39 -> 137.76339 | F40: =(F44-F39)/5+F39 -> 4.7721718 | G40: =(G44-G39)/5+G39 -> 24.549861 | H40: =(H44-H39)/5+H39 -> 428.66315 | I40: =(I44-I39)/5+I39 -> 708.60744 | ... R40: =(R44-R39)/5+R39 -> 37.906807
...

Sheet GDP_Projection
B1: 2018 | C1: 2019 | D1: 2020 | E1: 2021 | F1: 2022 | G1: 2023 | H1: 2024 | I1: 2025 | J1: 2026 | K1: 2027 | L1: 2028 | M1: 2029 | N1: 2030 | O1: 2031 | P1: 2032 | Q1: 2033 | R1: 2034 | S1: 2035 | T1: 2036 | U1: 2037 | V1: 2038 | W1: 2039 | X1: 2040 | Y1: 2041 | Z1: 2042 | AA1: 2043 | AB1: 2044 | AC1: 2045 | AD1: 2046 | AE1: 2047 | AF1: 2048 | AG1: 2049 | AH1: 2050 | AI1: 2051 | AJ1: 2052 | AK1: 2053 | AL1: 2054 | AM1: 2055 | AN1: 2056 | AO1: 2057 | AP1: 2058 | AQ1: 2059 | AR1: 2060 | AS1: 2061 | AT1: 2062 | AU1: 2063 | AV1: 2064 | AW1: 2065 | AX1: 2066 | AY1: 2067 | AZ1: 2068 | BA1: 2069 | BB1: 2070 | BC1: 2071 | BD1: 2072 | BE1: 2073 | BF1: 2074 | BG1: 2075 | BH1: 2076 | BI1: 2077 | BJ1: 2078 | BK1: 2079 | BL1: 2080 | BM1: 2081 | BN1: 2082 | BO1: 2083 | BP1: 2084 | BQ1: 2085 | BR1: 2086 | BS1: 2087 | BT1: 2088 | BU1: 2089 | BV1: 2090 | BW1: 2091 | BX1: 2092 | BY1: 2093 | BZ1: 2094 | CA1: 2095 | CB1: 2096 | CC1: 2097 | CD1: 2098 | CE1: 2099 | CF1: 2100
A2: 01_KOR | B2: {=TRANSPOSE(GDP!B2:B84)} -> 2164.8129 | C2: 2213.3908 | D2: 2197.6887 | E2: 2292.2934 | F2: 2326.875 | G2: 2361.4567 | H2: 2396.0383 | I2: 2430.62 | J2: 2478.518 | K2: 2526.416 | L2: 2574.314 | M2: 2622.212 | N2: 2670.11 | O2: 2705.06 | P2: 2740.01 | Q2: 2774.96 | R2: 2809.91 | S2: 2844.86 | T2: 2869.73 | U2: 2894.6 | V2: 2919.47 | W2: 2944.34 | X2: 2969.21 | Y2: 2987.112 | Z2: 3005.014 | AA2: 3022.916 | AB2: 3040.818 | AC2: 3058.72 | AD2: 3071.018 | AE2: 3083.316 | AF2: 3095.614 | AG2: 3107.912 | AH2: 3120.21 | AI2: 3125.836 | AJ2: 3131.462 | AK2: 3137.088 | AL2: 3142.714 | AM2: 3148.34 | AN2: 3148.094 | AO2: 3147.848 | AP2: 3147.602 | AQ2: 3147.356 | AR2: 3147.11 | AS2: 3144.368 | AT2: 3141.626 | AU2: 3138.884 | AV2: 3136.142 | AW2: 3133.4 | AX2: 3127.558 | AY2: 3121.716 | AZ2: 3115.874 | BA2: 3110.032 | BB2: 3104.19 | BC2: 3095.18 | BD2: 3086.17 | BE2: 3077.16 | BF2: 3068.15 | BG2: 3059.14 | BH2: 3047.166 | BI2: 3035.192 | BJ2: 3023.218 | BK2: 3011.244 | BL2: 2999.27 | BM2: 2985.19 | BN2: 2971.11 | BO2: 2957.03 | BP2: 2942.95 | BQ2: 2928.87 | BR2: 2913.096 | BS2: 2897.322 | BT2: 2881.548 | BU2: 2865.774 | BV2: 2850 | BW2: 2832.902 | BX2: 2815.804 | BY2: 2798.706 | BZ2: 2781.608 | CA2: 2764.51 | CB2: 2746.806 | CC2: 2729.102 | CD2: 2711.398 | CE2: 2693.694 | CF2: 2675.99
A3: 02_CHN | B3: {=TRANSPOSE(GDP!C2:C84)} -> 21684.385 | C3: 22940.028 | D3: 23414.274 | E3: 25384.031 | F3: 26693.29 | G3: 28002.548 | H3: 29311.806 | I3: 30621.064 | J3: 31849.824 | K3: 33078.584 | L3: 34307.343 | M3: 35536.103 | N3: 36764.863 | O3: 37877.798 | P3: 38990.734 | Q3: 40103.669 | R3: 41216.605 | S3: 42329.54 | T3: 43218.37 | U3: 44107.2 | V3: 44996.031 | W3: 45884.861 | X3: 46773.691 | Y3: 47622.001 | Z3: 48470.311 | AA3: 49318.622 | AB3: 50166.932 | AC3: 51015.242 | AD3: 51805.812 | AE3: 52596.382 | AF3: 53386.953 | AG3: 54177.523 | AH3: 54968.093 | AI3: 55653.318 | AJ3: 56338.544 | AK3: 57023.769 | AL3: 57708.995 | AM3: 58394.22 | AN3: 59054.777 | AO3: 59715.333 | AP3: 60375.89 | AQ3: 61036.446 | AR3: 61697.003 | AS3: 62322.84 | AT3: 62948.677 | AU3: 63574.514 | AV3: 64200.351 | AW3: 64826.188 | AX3: 65329.606 | AY3: 65833.024 | AZ3: 66336.442 | BA3: 66839.86 | BB3: 67343.278 | BC3: 67717.769 | BD3: 68092.26 | BE3: 68466.751 | BF3: 68841.242 | BG3: 69215.733 | BH3: 69490.551 | BI3: 69765.369 | BJ3: 70040.188 | BK3: 70315.006 | BL3: 70589.824 | BM3: 70791.723 | BN3: 70993.622 | BO3: 71195.52 | BP3: 71397.419 | BQ3: 71599.318 | BR3: 71762.502 | BS3: 71925.687 | BT3: 72088.871 | BU3: 72252.056 | BV3: 72415.24 | BW3: 72547.917 | BX3: 72680.594 | BY3: 72813.271 | BZ3: 72945.948 | CA3: 73078.625 | CB3: 73153.642 | CC3: 73228.659 | CD3: 73303.677 | CE3: 73378.694 | CF3: 73453.711
A4: 03_JPN | B4: {=TRANSPOSE(GDP!D2:R2)} -> 5296.1118 | C4: {=TRANSPOSE(GDP!D3:G84)} -> 5274.8125 | D4: 5049.1242 | E4: 5157.301 | F4: 5239.3933 | G4: 5321.4855 | H4: 5403.5778 | I4: 5485.67 | J4: 5529.576 | K4: 5573.482 | L4: 5617.388 | M4: 5661.294 | N4: 5705.2 | O4: 5753.91 | P4: 5802.62 | Q4: 5851.33 | R4: 5900.04 | S4: 5948.75 | T4: 5990.412 | U4: 6032.074 | V4: 6073.736 | W4: 6115.398 | X4: 6157.06 | Y4: 6199.932 | Z4: 6242.804 | AA4: 6285.676 | AB4: 6328.548 | AC4: 6371.42 | AD4: 6416.856 | AE4: 6462.292 | AF4: 6507.728 | AG4: 6553.164 | AH4: 6598.6 | AI4: 6642.002 | AJ4: 6685.404 | AK4: 6728.806 | AL4: 6772.208 | AM4: 6815.61 | AN4: 6854.064 | AO4: 6892.518 | AP4: 6930.972 | AQ4: 6969.426 | AR4: 7007.88 | AS4: 7041.024 | AT4: 7074.168 | AU4: 7107.312 | AV4: 7140.456 | AW4: 7173.6 | AX4: 7200.24 | AY4: 7226.88 | AZ4: 7253.52 | BA4: 7280.16 | BB4: 7306.8 | BC4: 7328.06 | BD4: 7349.32 | BE4: 7370.58 | BF4: 7391.84 | BG4: 7413.1 | BH4: 7432.194 | BI4: 7451.288 | BJ4: 7470.382 | BK4: 7489.476 | BL4: 7508.57 | BM4: 7527.222 | BN4: 7545.874 | BO4: 7564.526 | BP4: 7583.178 | BQ4: 7601.83 | BR4: 7618.882 | BS4: 7635.934 | BT4: 7652.986 | BU4: 7670.038 | BV4: 7687.09 | BW4: 7700.066 | BX4: 7713.042 | BY4: 7726.018 | BZ4: 7738.994 | CA4: 7751.97 | CB4: 7758.134 | CC4: 7764.298 | CD4: 7770.462 | CE4: 7776.626 | CF4: 7782.79
A5: 04_RUS | B5: 3913.9759 | C5: 4000.0081 | D5: 3893.8617 | E5: 4112.4744 | F5: 4066.9158 | G5: 4021.3572 | H5: 3975.7986 | I5: 3930.24 | J5: 3989.154 | K5: 4048.068 | L5: 4106.982 | M5: 4165.896 | N5: 4224.81 | O5: 4306.92 | P5: 4389.03 | Q5: 4471.14 | R5: 4553.25 | S5: 4635.36 | T5: 4720.446 | U5: 4805.532 | V5: 4890.618 | W5: 4975.704 | X5: 5060.79 | Y5: 5147.096 | Z5: 5233.402 | AA5: 5319.708 | AB5: 5406.014 | AC5: 5492.32 | AD5: 5579.152 | AE5: 5665.984 | AF5: 5752.816 | AG5: 5839.648 | AH5: 5926.48 | AI5: 6021.756 | AJ5: 6117.032 | AK5: 6212.308 | AL5: 6307.584 | AM5: 6402.86 | AN5: 6512.924 | AO5: 6622.988 | AP5: 6733.052 | AQ5: 6843.116 | AR5: 6953.18 | AS5: 7069.914 | AT5: 7186.648 | AU5: 7303.382 | AV5: 7420.116 | AW5: 7536.85 | AX5: 7658.53 | AY5: 7780.21 | AZ5: 7901.89 | BA5: 8023.57 | BB5: 8145.25 | BC5: 8268.47 | BD5: 8391.69 | BE5: 8514.91 | BF5: 8638.13 | BG5: 8761.35 | BH5: 8886.588 | BI5: 9011.826 | BJ5: 9137.064 | BK5: 9262.302 | BL5: 9387.54 | BM5: 9518.752 | BN5: 9649.964 | BO5: 9781.176 | BP5: 9912.388 | BQ5: 10043.6 | BR5: 10184.32 | BS5: 10325.04 | BT5: 10465.76 | BU5: 10606.48 | BV5: 10747.2 | BW5: 10896.44 | BX5: 11045.68 | BY5: 11194.92 | BZ5: 11344.16 | CA5: 11493.4 | CB5: 11645.2 | CC5: 11797 | CD5: 11948.8 | CE5: 12100.6 | CF5: 12252.4
A6: 05_MNG | B6: 38.133349 | C6: 40.269673 | D6: 38.434281 | E6: 39.063361 | F6: 41.001671 | G6: 42.939981 | H6: 44.87829 | I6: 46.8166 | J6: 48.72012 | K6: 50.62364 | L6: 52.52716 | M6: 54.43068 | N6: 56.3342 | O6: 58.66914 | P6: 61.00408 | Q6: 63.33902 | R6: 65.67396 | S6: 68.0089 | T6: 70.5476 | U6: 73.0863 | V6: 75.625 | W6: 78.1637 | X6: 80.7024 | Y6: 83.49678 | Z6: 86.29116 | AA6: 89.08554 | AB6: 91.87992 | AC6: 94.6743 | AD6: 97.85204 | AE6: 101.02978 | AF6: 104.20752 | AG6: 107.38526 | AH6: 110.563 | AI6: 114.2586 | AJ6: 117.9542 | AK6: 121.6498 | AL6: 125.3454 | AM6: 129.041 | AN6: 133.334 | AO6: 137.627 | AP6: 141.92 | AQ6: 146.213 | AR6: 150.506 | AS6: 155.4462 | AT6: 160.3864 | AU6: 165.3266 | AV6: 170.2668 | AW6: 175.207 | AX6: 180.6334 | AY6: 186.0598 | AZ6: 191.4862 | BA6: 196.9126 | BB6: 202.339 | BC6: 208.176 | BD6: 214.013 | BE6: 219.85 | BF6: 225.687 | BG6: 231.524 | BH6: 237.7938 | BI6: 244.0636 | BJ6: 250.3334 | BK6: 256.6032 | BL6: 262.873 | BM6: 269.609 | BN6: 276.345 | BO6: 283.081 | BP6: 289.817 | BQ6: 296.553 | BR6: 303.7968 | BS6: 311.0406 | BT6: 318.2844 | BU6: 325.5282 | BV6: 332.772 | BW6: 340.5136 | BX6: 348.2552 | BY6: 355.9968 | BZ6: 363.7384 | CA6: 371.48 | CB6: 379.6734 | CC6: 387.8668 | CD6: 396.0602 | CE6: 404.2536 | CF6: 412.447
A7: 06_PRK | B7: 47.318147 | C7: 47.436589 | D7: 47.555328 | E7: 47.674364 | F7: 47.793698 | G7: 47.913331 | H7: 48.033263 | I7: 48.153496 | J7: 48.274029 | K7: 48.394865 | L7: 48.516002 | M7: 48.637443 | N7: 48.759188 | O7: 48.881237 | P7: 49.003592 | Q7: 49.126254 | R7: 49.249222 | S7: 49.372498 | T7: 49.496083 | U7: 49.619977 | V7: 49.744181 | W7: 49.868696 | X7: 49.993523 | Y7: 50.118662 | Z7: 50.244115 | AA7: 50.369881 | AB7: 50.495962 | AC7: 50.622359 | AD7: 50.749073 | AE7: 50.876103 | AF7: 51.003451 | AG7: 51.131119 | AH7: 51.259105 | AI7: 51.387412 | AJ7: 51.516041 | AK7: 51.644991 | AL7: 51.774264 | AM7: 51.903861 | AN7: 52.033782 | AO7: 52.164028 | AP7: 52.2946 | AQ7: 52.425499 | AR7: 52.556726 | AS7: 52.688281 | AT7: 52.820166 | AU7: 52.95238 | AV7: 53.084926 | AW7: 53.217803 | AX7: 53.351013 | AY7: 53.484556 | AZ7: 53.618434 | BA7: 53.752647 | BB7: 53.887195 | BC7: 54.022081 | BD7: 54.157304 | BE7: 54.292866 | BF7: 54.428767 | BG7: 54.565008 | BH7: 54.70159 | BI7: 54.838514 | BJ7: 54.975781 | BK7: 55.113391 | BL7: 55.251346 | BM7: 55.389646 | BN7: 55.528292 | BO7: 55.667286 | BP7: 55.806627 | BQ7: 55.946317 | BR7: 56.086357 | BS7: 56.226747 | BT7: 56.367489 | BU7: 56.508582 | BV7: 56.65003 | BW7: 56.791831 | BX7: 56.933987 | BY7: 57.076499 | BZ7: 57.219368 | CA7: 57.362594 | CB7: 57.506179 | CC7: 57.650123 | CD7: 57.794427 | CE7: 57.939093 | CF7: 58.084121
A8: 07_NAM | B8: 21975.104 | C8: {=TRANSPOSE(GDP!H3:R84)} -> 22471.26 | D8: 21805.056 | E8: 23079.216 | F8: 23418.653 | G8: 23758.09 | H8: 24097.528 | I8: 24436.965 | J8: 24914.997 | K8: 25393.029 | L8: 25871.06 | M8: 26349.092 | N8: 26827.124 | O8: 27266.258 | P8: 27705.391 | Q8: 28144.525 | R8: 28583.659 | S8: 29022.792 | T8: 29443.005 | U8: 29863.218 | V8: 30283.431 | W8: 30703.644 | X8: 31123.857 | Y8: 31536.282 | Z8: 31948.706 | AA8: 32361.131 | AB8: 32773.556 | AC8: 33185.981 | AD8: 33594.991 | AE8: 34004.001 | AF8: 34413.011 | AG8: 34822.021 | AH8: 35231.031 | AI8: 35646.204 | AJ8: 36061.376 | AK8: 36476.549 | AL8: 36891.721 | AM8: 37306.894 | AN8: 37733.159 | AO8: 38159.425 | AP8: 38585.691 | AQ8: 39011.957 | AR8: 39438.223 | AS8: 39876.916 | AT8: 40315.608 | AU8: 40754.301 | AV8: 41192.993 | AW8: 41631.686 | AX8: 42066.691 | AY8: 42501.696 | AZ8: 42936.701 | BA8: 43371.706 | BB8: 43806.71 | BC8: 44232.837 | BD8: 44658.963 | BE8: 45085.089 | BF8: 45511.215 | BG8: 45937.341 | BH8: 46351.63 | BI8: 46765.919 | BJ8: 47180.207 | BK8: 47594.496 | BL8: 48008.785 | BM8: 48411.81 | BN8: 48814.835 | BO8: 49217.86 | BP8: 49620.886 | BQ8: 50023.911 | BR8: 50417.186 | BS8: 50810.462 | BT8: 51203.737 | BU8: 51597.013 | BV8: 51990.288 | BW8: 52374.408 | BX8: 52758.528 | BY8: 53142.648 | BZ8: 53526.768 | CA8: 53910.887 | CB8: 54281.258 | CC8: 54651.629 | CD8: 55022.001 | CE8: 55392.372 | CF8: 55762.743
A9: 08_LAM | B9: 9585.6291 | C9: 9657.573 | D9: 9010.867 | E9: 9674.2145 | F9: 9849.2318 | G9: 10024.249 | H9: 10199.266 | I9: 10374.284 | J9: 10651.893 | K9: 10929.503 | L9: 11207.113 | M9: 11484.723 | N9: 11762.332 | O9: 12120.367 | P9: 12478.401 | Q9: 12836.435 | R9: 13194.469 | S9: 13552.503 | T9: 13976.933 | U9: 14401.363 | V9: 14825.793 | W9: 15250.223 | X9: 15674.653 | Y9: 16158.705 | Z9: 16642.757 | AA9: 17126.808 | AB9: 17610.86 | AC9: 18094.912 | AD9: 18627.56 | AE9: 19160.209 | AF9: 19692.857 | AG9: 20225.506 | AH9: 20758.154 | AI9: 21332.94 | AJ9: 21907.726 | AK9: 22482.512 | AL9: 23057.299 | AM9: 23632.085 | AN9: 24240.385 | AO9: 24848.684 | AP9: 25456.984 | AQ9: 26065.284 | AR9: 26673.584 | AS9: 27318.846 | AT9: 27964.107 | AU9: 28609.369 | AV9: 29254.631 | AW9: 29899.893 | AX9: 30567.527 | AY9: 31235.162 | AZ9: 31902.797 | BA9: 32570.431 | BB9: 33238.066 | BC9: 33919.444 | BD9: 34600.822 | BE9: 35282.2 | BF9: 35963.578 | BG9: 36644.957 | BH9: 37324.181 | BI9: 38003.406 | BJ9: 38682.631 | BK9: 39361.855 | BL9: 40041.08 | BM9: 40715.444 | BN9: 41389.809 | BO9: 42064.173 | BP9: 42738.537 | BQ9: 43412.901 | BR9: 44081.031 | BS9: 44749.161 | BT9: 45417.291 | BU9: 46085.421 | BV9: 46753.551 | BW9: 47414.347 | BX9: 48075.142 | BY9: 48735.938 | BZ9: 49396.734 | CA9: 50057.53 | CB9: 50710.368 | CC9: 51363.207 | CD9: 52016.045 | CE9: 52668.883 | CF9: 53321.721
A10: 09_WEU | B10: 22625.327 | C10: 22959.584 | D10: 21647.745 | E10: 23137.908 | F10: 23256.562 | G10: 23375.216 | H10: 23493.869 | I10: 23612.523 | J10: 24056.213 | K10: 24499.904 | L10: 24943.594 | M10: 25387.285 | N10: 25830.975 | O10: 26283.442 | P10: 26735.909 | Q10: 27188.376 | R10: 27640.843 | S10: 28093.31 | T10: 28563.244 | U10: 29033.178 | V10: 29503.112 | W10: 29973.046 | X10: 30442.98 | Y10: 30926.463 | Z10: 31409.946 | AA10: 31893.429 | AB10: 32376.912 | AC10: 32860.395 | AD10: 33342.219 | AE10: 33824.042 | AF10: 34305.865 | AG10: 34787.689 | AH10: 35269.512 | AI10: 35747.529 | AJ10: 36225.546 | AK10: 36703.563 | AL10: 37181.58 | AM10: 37659.597 | AN10: 38136.562 | AO10: 38613.526 | AP10: 39090.491 | AQ10: 39567.456 | AR10: 40044.421 | AS10: 40512.959 | AT10: 40981.496 | AU10: 41450.034 | AV10: 41918.572 | AW10: 42387.11 | AX10: 42826.903 | AY10: 43266.697 | AZ10: 43706.491 | BA10: 44146.285 | BB10: 44586.078 | BC10: 44994.813 | BD10: 45403.549 | BE10: 45812.284 | BF10: 46221.019 | BG10: 46629.755 | BH10: 47005.413 | BI10: 47381.072 | BJ10: 47756.73 | BK10: 48132.389 | BL10: 48508.047 | BM10: 48852.362 | BN10: 49196.676 | BO10: 49540.991 | BP10: 49885.306 | BQ10: 50229.62 | BR10: 50545.098 | BS10: 50860.577 | BT10: 51176.055 | BU10: 51491.533 | BV10: 51807.011 | BW10: 52092.876 | BX10: 52378.74 | BY10: 52664.604 | BZ10: 52950.469 | CA10: 53236.333 | CB10: 53485.152 | CC10: 53733.971 | CD10: 53982.789 | CE10: 54231.608 | CF10: 54480.427
A11: 10_EEU | B11: 3472.9901 | C11: 3609.1441 | D11: 3487.3467 | E11: 3716.7234 | F11: 3775.4882 | G11: 3834.253 | H11: 3893.0178 | I11: 3951.7826 | J11: 4068.4402 | K11: 4185.0978 | L11: 4301.7555 | M11: 4418.4131 | N11: 4535.0707 | O11: 4630.3487 | P11: 4725.6266 | Q11: 4820.9046 | R11: 4916.1825 | S11: 5011.4605 | T11: 5090.027 | U11: 5168.5935 | V11: 5247.1601 | W11: 5325.7266 | X11: 5404.2931 | Y11: 5463.7973 | Z11: 5523.3015 | AA11: 5582.8058 | AB11: 5642.31 | AC11: 5701.8142 | AD11: 5751.5447 | AE11: 5801.2751 | AF11: 5851.0056 | AG11: 5900.736 | AH11: 5950.4665 | AI11: 5994.5824 | AJ11: 6038.6982 | AK11: 6082.8141 | AL11: 6126.9299 | AM11: 6171.0458 | AN11: 6212.4034 | AO11: 6253.761 | AP11: 6295.1186 | AQ11: 6336.4762 | AR11: 6377.8338 | AS11: 6417.2675 | AT11: 6456.7011 | AU11: 6496.1348 | AV11: 6535.5684 | AW11: 6575.0021 | AX11: 6609.6416 | AY11: 6644.2811 | AZ11: 6678.9207 | BA11: 6713.5602 | BB11: 6748.1997 | BC11: 6777.3133 | BD11: 6806.427 | BE11: 6835.5406 | BF11: 6864.6543 | BG11: 6893.7679 | BH11: 6918.4347 | BI11: 6943.1014 | BJ11: 6967.7682 | BK11: 6992.4349 | BL11: 7017.1017 | BM11: 7039.7509 | BN11: 7062.4001 | BO11: 7085.0493 | BP11: 7107.6985 | BQ11: 7130.3477 | BR11: 7153.2663 | BS11: 7176.1848 | BT11: 7199.1034 | BU11: 7222.0219 | BV11: 7244.9405 | BW11: 7268.9374 | BX11: 7292.9343 | BY11: 7316.9313 | BZ11: 7340.9282 | CA11: 7364.9251 | CB11: 7388.4468 | CC11: 7411.9685 | CD11: 7435.4901 | CE11: 7459.0118 | CF11: 7482.5335
A12: 11_FSU | B12: 1784.7279 | C12: 1857.0133 | D12: 1810.9689 | E12: 1899.4803 | F12: 1938.2091 | G12: 1976.9379 | H12: 2015.6667 | I12: 2054.3955 | J12: 2134.8368 | K12: 2215.2781 | L12: 2295.7194 | M12: 2376.1607 | N12: 2456.602 | O12: 2546.2138 | P12: 2635.8256 | Q12: 2725.4374 | R12: 2815.0492 | S12: 2904.661 | T12: 2993.979 | U12: 3083.297 | V12: 3172.615 | W12: 3261.933 | X12: 3351.251 | Y12: 3438.4935 | Z12: 3525.736 | AA12: 3612.9784 | AB12: 3700.2209 | AC12: 3787.4634 | AD12: 3875.7253 | AE12: 3963.9872 | AF12: 4052.2492 | AG12: 4140.5111 | AH12: 4228.773 | AI12: 4322.4437 | AJ12: 4416.1144 | AK12: 4509.785 | AL12: 4603.4557 | AM12: 4697.1264 | AN12: 4799.752 | AO12: 4902.3776 | AP12: 5005.0031 | AQ12: 5107.6287 | AR12: 5210.2543 | AS12: 5322.1087 | AT12: 5433.9631 | AU12: 5545.8175 | AV12: 5657.6719 | AW12: 5769.5263 | AX12: 5887.5141 | AY12: 6005.502 | AZ12: 6123.4898 | BA12: 6241.4777 | BB12: 6359.4655 | BC12: 6481.207 | BD12: 6602.9485 | BE12: 6724.69 | BF12: 6846.4315 | BG12: 6968.173 | BH12: 7094.5456 | BI12: 7220.9182 | BJ12: 7347.2908 | BK12: 7473.6634 | BL12: 7600.036 | BM12: 7733.9542 | BN12: 7867.8724 | BO12: 8001.7906 | BP12: 8135.7088 | BQ12: 8269.627 | BR12: 8413.2242 | BS12: 8556.8214 | BT12: 8700.4186 | BU12: 8844.0158 | BV12: 8987.613 | BW12: 9140.4244 | BX12: 9293.2358 | BY12: 9446.0472 | BZ12: 9598.8586 | CA12: 9751.67 | CB12: 9911.3956 | CC12: 10071.121 | CD12: 10230.847 | CE12: 10390.572 | CF12: 10550.298
A13: 12_MEA | B13: 7693.5896 | C13: 7766.4346 | D13: 7518.6202 | E13: 7839.315 | F13: 8141.163 | G13: 8443.011 | H13: 8744.859 | I13: 9046.707 | J13: 9421.6885 | K13: 9796.67 | L13: 10171.652 | M13: 10546.633 | N13: 10921.615 | O13: 11346.631 | P13: 11771.648 | Q13: 12196.665 | R13: 12621.682 | S13: 13046.699 | T13: 13522.139 | U13: 13997.579 | V13: 14473.02 | W13: 14948.46 | X13: 15423.9 | Y13: 15943.352 | Z13: 16462.804 | AA13: 16982.256 | AB13: 17501.708 | AC13: 18021.16 | AD13: 18588.185 | AE13: 19155.21 | AF13: 19722.235 | AG13: 20289.261 | AH13: 20856.286 | AI13: 21483.536 | AJ13: 22110.786 | AK13: 22738.036 | AL13: 23365.286 | AM13: 23992.536 | AN13: 24685.544 | AO13: 25378.553 | AP13: 26071.562 | AQ13: 26764.57 | AR13: 27457.579 | AS13: 28211.438 | AT13: 28965.298 | AU13: 29719.157 | AV13: 30473.017 | AW13: 31226.876 | AX13: 32014.024 | AY13: 32801.172 | AZ13: 33588.319 | BA13: 34375.467 | BB13: 35162.614 | BC13: 35982.546 | BD13: 36802.478 | BE13: 37622.409 | BF13: 38442.341 | BG13: 39262.272 | BH13: 40114.779 | BI13: 40967.285 | BJ13: 41819.792 | BK13: 42672.298 | BL13: 43524.805 | BM13: 44412.802 | BN13: 45300.8 | BO13: 46188.797 | BP13: 47076.795 | BQ13: 47964.792 | BR13: 48895.883 | BS13: 49826.974 | BT13: 50758.065 | BU13: 51689.155 | BV13: 52620.246 | BW13: 53596.033 | BX13: 54571.82 | BY13: 55547.607 | BZ13: 56523.394 | CA13: 57499.181 | CB13: 58511.337 | CC13: 59523.493 | CD13: 60535.649 | CE13: 61547.805 | CF13: 62559.961
