Workbook

Sheet Sheet4
A1: VMGP | B1: 1 r_01KOR | C1: 2 r_02CHN | D1: 3 r_03JPN | E1: 4 r_04RUS | F1: 5 r_05MNG | G1: 6 r_06PRK | H1: 7 r_07NAM | I1: 8 r_08LAM | J1: 9 r_09WEU | K1: 10 r_10EEU | L1: 11 r_11FSU | M1: 12 r_12MEA | N1: 13 r_13AFR | O1: 14 r_14CPA | P1: 15 r_15SAS | Q1: 16 r_16PAS | R1: 17 r_17PAO | S1: Total | U1: VMIP | V1: 1 r_01KOR | W1: 2 r_02CHN | X1: 3 r_03JPN | Y1: 4 r_04RUS | Z1: 5 r_05MNG | AA1: 6 r_06PRK | AB1: 7 r_07NAM | AC1: 8 r_08LAM | AD1: 9 r_09WEU | AE1: 10 r_10EEU | AF1: 11 r_11FSU | AG1: 12 r_12MEA | AH1: 13 r_13AFR | AI1: 14 r_14CPA | AJ1: 15 r_15SAS | AK1: 16 r_16PAS | AL1: 17 r_17PAO | AM1: Total
A2: 1 pdr | B2: 9.3121071e-07 | C2: 0.0002139911 | D2: 2.8266996e-07 | E2: 2.2386444e-06 | F2: 2.2996129e-07 | G2: 8.9701389e-06 | H2: 9.3885692e-06 | I2: 0.0005639544 | J2: 0.00346568 | K2: 0.003301004 | L2: 0.01505449 | M2: 0.005768673 | N2: 0.0001905997 | O2: 1.2455692e-07 | P2: 8.3041123e-06 | Q2: 2.9981395e-05 | R2: 6.3865887e-06 | S2: 0.02862523 | U2: 1 pdr | V2: 1.0074772e-05 | W2: 0.0004589131 | X2: 1.5498358e-06 | Y2: 1.6278009e-05 | Z2: 1.9106722e-06 | AA2: 2.2785121e-05 | AB2: 6.9296613e-05 | AC2: 0.006951504 | AD2: 0.4341764 | AE2: 0.005917739 | AF2: 0.1534355 | AG2: 0.003023792 | AH2: 0.0002132227 | AI2: 1.8970635e-06 | AJ2: 0.0002853246 | AK2: 0.002389939 | AL2: 4.2173622e-05 | AM2: 0.6070183
A3: 2 wht | B3: 0.02811587 | C3: 0.1866295 | D3: 0.6071023 | E3: 0.001204543 | F3: 5.5638779e-05 | G3: 2.8926352e-05 | H3: 0.125556 | I3: 0.2339336 | J3: 2.613409 | K3: 0.1544637 | L3: 9.43884 | M3: 35.24386 | N3: 0.821752 | O3: 0.004305799 | P3: 0.1875052 | Q3: 0.218363 | R3: 0.005893066 | S3: 49.87102 | U3: 2 wht | V3: 0.1678985 | W3: 1.346002 | X3: 2.070199 | Y3: 0.004523437 | Z3: 0.0002487362 | AA3: 0.0001882663 | AB3: 0.5684947 | AC3: 9.063951 | AD3: 129.9139 | AE3: 3.023015 | AF3: 11.78537 | AG3: 143.461 | AH3: 2.723857 | AI3: 0.03809304 | AJ3: 1.554871 | AK3: 3.716911 | AL3: 0.0222531 | AM3: 309.4608
A4: 3 gro | B4: 0.03547825 | C4: 0.2149161 | D4: 0.4703493 | E4: 0.01422193 | F4: 0.002041676 | G4: 0.02538221 | H4: 0.3238413 | I4: 1.433539 | J4: 1.313668 | K4: 0.5003994 | L4: 0.4341094 | M4: 43.37849 | N4: 0.04140093 | O4: 0.02176552 | P4: 0.1322285 | Q4: 0.04536747 | R4: 0.0522377 | S4: 48.43944 | U4: 3 gro | V4: 0.121403 | W4: 0.8453037 | X4: 2.99664 | Y4: 3.412317 | Z4: 0.005259659 | AA4: 0.05443107 | AB4: 0.7774743 | AC4: 2.173058 | AD4: 168.7945 | AE4: 12.37858 | AF4: 17.62543 | AG4: 173.3977 | AH4: 0.2511308 | AI4: 0.1086856 | AJ4: 0.9542945 | AK4: 3.389633 | AL4: 0.1092605 | AM4: 387.3951
A5: 4 v_f | B5: 0.05894043 | C5: 0.3752084 | D5: 0.3864366 | E5: 0.09092227 | F5: 0.0003850489 | G5: 0.005409294 | H5: 0.6913538 | I5: 1.404369 | J5: 15.55063 | K5: 0.2795158 | L5: 6.521482 | M5: 172.9286 | N5: 0.1112077 | O5: 0.02115145 | P5: 0.4783205 | Q5: 0.1945831 | R5: 0.07654036 | S5: 199.175 | U5: 4 v_f | V5: 0.3534218 | W5: 2.375625 | X5: 53.01391 | Y5: 40.6519 | Z5: 0.001742998 | AA5: 0.02457441 | AB5: 3.549701 | AC5: 62.83224 | AD5: 1113.8 | AE5: 84.05601 | AF5: 19.20967 | AG5: 519.3646 | AH5: 1.694023 | AI5: 126.8136 | AJ5: 3.944724 | AK5: 147.1551 | AL5: 0.2715409 | AM5: 2179.112
A6: 5 osd | B6: 0.006228198 | C6: 0.01539414 | D6: 0.001974776 | E6: 0.006210703 | F6: 0.01193367 | G6: 4.3800137e-05 | H6: 0.008880231 | I6: 0.009705248 | J6: 3.741579 | K6: 0.00556298 | L6: 0.09139532 | M6: 0.7995356 | N6: 0.003352767 | O6: 0.001495401 | P6: 0.003757809 | Q6: 0.00883344 | R6: 0.001302938 | S6: 4.717186 | U6: 5 osd | V6: 0.1148041 | W6: 0.3435503 | X6: 0.0262656 | Y6: 0.07253382 | Z6: 0.1678721 | AA6: 0.0007496801 | AB6: 0.115239 | AC6: 1.239749 | AD6: 186.3417 | AE6: 12.38258 | AF6: 1.535624 | AG6: 39.35078 | AH6: 1.245239 | AI6: 0.03992759 | AJ6: 0.260117 | AK6: 139.1286 | AL6: 0.01409723 | AM6: 382.3794
A7: 6 c_b | B7: 9.7440825e-06 | C7: 5.7649846e-05 | D7: 0.000471083 | E7: 0.001931211 | F7: 5.3336301e-08 | G7: 2.2340008e-07 | H7: 0.0002006176 | I7: 1.8605886e-05 | J7: 0.002366462 | K7: 0.002337408 | L7: 0.001192461 | M7: 0.3707814 | N7: 6.7101901e-06 | O7: 1.364734e-07 | P7: 1.3552829e-05 | Q7: 4.5114e-05 | R7: 7.7901141e-06 | S7: 0.3794402 | U7: 6 c_b | V7: 0.01500953 | W7: 0.1053564 | X7: 0.2375578 | Y7: 0.8639719 | Z7: 6.1492479e-05 | AA7: 0.0003914388 | AB7: 0.1772076 | AC7: 0.05096002 | AD7: 6.260554 | AE7: 1.847636 | AF7: 0.1684881 | AG7: 0.4512727 | AH7: 0.004040361 | AI7: 0.0003013127 | AJ7: 0.01101982 | AK7: 0.07911783 | AL7: 0.007658334 | AM7: 10.28061
A8: 7 pfb | B8: 0.0005432542 | C8: 0.00326391 | D8: 0.004401328 | E8: 0.0001892081 | F8: 9.0555432e-07 | G8: 0.0001893656 | H8: 0.01030417 | I8: 0.02002153 | J8: 0.03175401 | K8: 0.02231937 | L8: 0.0507303 | M8: 0.4003652 | N8: 0.005757369 | O8: 0.0001303737 | P8: 0.01555058 | Q8: 0.03138673 | R8: 0.003212654 | S8: 0.6001203 | U8: 7 pfb | V8: 0.01287722 | W8: 0.06827416 | X8: 4.868451 | Y8: 0.8637066 | Z8: 1.5771933e-05 | AA8: 0.0003043747 | AB8: 0.1588358 | AC8: 19.03274 | AD8: 150.9914 | AE8: 1.011095 | AF8: 0.8037975 | AG8: 1.326747 | AH8: 0.6437827 | AI8: 0.003564083 | AJ8: 9.069837 | AK8: 0.5105597 | AL8: 0.02576143 | AM8: 189.3918
A9: 8 ocr | B9: 0.007822909 | C9: 0.05109521 | D9: 0.0429289 | E9: 0.007585668 | F9: 2.4113811e-05 | G9: 0.001779269 | H9: 0.2432593 | I9: 0.404486 | J9: 5.503874 | K9: 0.2213634 | L9: 2.379117 | M9: 23.46189 | N9: 0.02582556 | O9: 0.00158701 | P9: 0.01876972 | Q9: 0.06753934 | R9: 0.03393248 | S9: 32.47289 | U9: 8 ocr | V9: 0.5691648 | W9: 4.177137 | X9: 37.12442 | Y9: 15.88425 | Z9: 0.001314082 | AA9: 0.1003515 | AB9: 12.60119 | AC9: 88.63203 | AD9: 320.3502 | AE9: 26.338 | AF9: 22.70869 | AG9: 108.7675 | AH9: 2.841137 | AI9: 0.1660126 | AJ9: 24.63696 | AK9: 227.8458 | AL9: 0.9061418 | AM9: 893.6503
A10: 9 ctl | B10: 0.0009116659 | C10: 0.03164996 | D10: 0.09330142 | E10: 0.002535297 | F10: 4.9412833e-05 | G10: 0.0003608256 | H10: 0.02926713 | I10: 0.03643373 | J10: 0.4903373 | K10: 0.1457732 | L10: 0.1893076 | M10: 8.767535 | N10: 0.02261001 | O10: 0.007683645 | P10: 0.006046559 | Q10: 0.04881052 | R10: 0.2738878 | S10: 10.1465 | U10: 9 ctl | V10: 2.906852 | W10: 38.62785 | X10: 26.17495 | Y10: 2.797666 | Z10: 1.248459 | AA10: 0.2907027 | AB10: 0.3816952 | AC10: 109.5084 | AD10: 148.4174 | AE10: 11.00939 | AF10: 3.426104 | AG10: 85.6479 | AH10: 63.70251 | AI10: 120.7992 | AJ10: 1.411164 | AK10: 371.4256 | AL10: 3.524794 | AM10: 991.3007
A11: 10 oap | B11: 0.01317452 | C11: 0.05689165 | D11: 0.06038523 | E11: 0.003852748 | F11: 5.1016039e-05 | G11: 0.0008810936 | H11: 0.04679165 | I11: 0.08425903 | J11: 0.5907842 | K11: 0.4796225 | L11: 0.7614325 | M11: 8.30207 | N11: 0.002925873 | O11: 0.007295006 | P11: 0.006153835 | Q11: 0.0344122 | R11: 0.002124669 | S11: 10.45311 | U11: 10 oap | V11: 49.80087 | W11: 354.427 | X11: 14.30355 | Y11: 5.696978 | Z11: 0.004140167 | AA11: 0.1074385 | AB11: 3.12414 | AC11: 252.6581 | AD11: 241.2037 | AE11: 27.96474 | AF11: 14.27164 | AG11: 44.21563 | AH11: 15.37114 | AI11: 18.44176 | AJ11: 9.447433 | AK11: 142.7086 | AL11: 22.77903 | AM11: 1216.526
A12: 11 rmk | B12: 1.7207183e-08 | C12: 5.4017949e-07 | D12: 0.0001064501 | E12: 6.5621333e-07 | F12: 8.6451424e-09 | G12: 2.4464461e-08 | H12: 9.2128321e-06 | I12: 1.6765405e-05 | J12: 0.007956961 | K12: 0.0001102236 | L12: 9.4543997e-05 | M12: 0.0004003178 | N12: 7.4349232e-06 | O12: 4.2640345e-09 | P12: 5.1782291e-07 | Q12: 1.3164055e-06 | R12: 1.8695323e-08 | S12: 0.008705014 | U12: 11 rmk | V12: 6.738236e-05 | W12: 0.002622409 | X12: 0.00480639 | Y12: 0.001426295 | Z12: 2.608433e-05 | AA12: 0.0001121423 | AB12: 0.02671891 | AC12: 0.003619365 | AD12: 0.1770044 | AE12: 0.002794414 | AF12: 0.002308605 | AG12: 0.009811684 | AH12: 0.04734405 | AI12: 2.8099239e-05 | AJ12: 0.002761106 | AK12: 0.2158242 | AL12: 4.9267572e-05 | AM12: 0.4973247
A13: 12 wol | B13: 3.6683022e-07 | C13: 0.00117785 | D13: 0.0001050471 | E13: 1.1736823e-06 | F13: 5.8224249e-08 | G13: 9.4234001e-06 | H13: 4.6864657e-06 | I13: 8.5565816e-06 | J13: 0.006624188 | K13: 0.0001728021 | L13: 0.001202217 | M13: 0.003845774 | N13: 3.8116168e-06 | O13: 1.0951383e-07 | P13: 5.2446198e-06 | Q13: 4.2823835e-06 | R13: 4.2581942e-06 | S13: 0.01316985 | U13: 12 wol | V13: 0.2577834 | W13: 61.18645 | X13: 6.278538 | Y13: 0.002028905 | Z13: 0.0001298034 | AA13: 5.0870975e-05 | AB13: 0.009786288 | AC13: 0.3859652 | AD13: 4.554415 | AE13: 5.20226 | AF13: 0.03188853 | AG13: 0.1206821 | AH13: 0.6749924 | AI13: 0.0004355735 | AJ13: 5.258537 | AK13: 19.06471 | AL13: 0.008765653 | AM13: 103.0374
... A74: Total | B74: 94.84372 | C74: 43414 | D74: 4045.98 | E74: 1807.651 | F74: 169.9129 | G74: 661.8225 | H74: 19918.01 | I74: 8922.611 | J74: 84289.97 | K74: 10289.94 | L74: 3669.426 | M74: 89231.73 | N74: 5671.186 | O74: 693.188 | P74: 6071.453 | Q74: 5421.744 | R74: 4844.922 | S74: 289218.4 | U74: Total | V74: 49532.8 | W74: 333414.5 | X74: 125576.1 | Y74: 53165.23 | Z74: 542.9525 | AA74: 1885.499 | AB74: 635683.1 | AC74: 157473.6 | AD74: 756124.7 | AE74: 103349.6 | AF74: 34929.9 | AG74: 133014 | AH74: 70057.2 | AI74: 20345.78 | AJ74: 110154.8 | AK74: 195482.7 | AL74: 58743.68 | AM74: 2839476
A76: VMGP | B76: 1 r_01KOR | C76: 2 r_02CHN | D76: 3 r_03JPN | E76: 4 r_04RUS | F76: 5 r_05MNG | G76: 6 r_06PRK | H76: 7 r_07NAM | I76: 8 r_08LAM | J76: 9 r_09WEU | K76: 10 r_10EEU | L76: 11 r_11FSU | M76: 12 r_12MEA | N76: 13 r_13AFR | O76: 14 r_14CPA | P76: 15 r_15SAS | Q76: 16 r_16PAS | R76: 17 r_17PAO | S76: Total
A77: 1 pdr | B77: 9.3121071e-07 | C77: 0.0002139911 | D77: 2.8266996e-07 | E77: 2.2386444e-06 | F77: 2.2996129e-07 | G77: 8.9701389e-06 | H77: 9.3885692e-06 | I77: 0.0005639544 | J77: 0.00346568 | K77: 0.003301004 | L77: 0.01505449 | M77: 0.005768673 | N77: 0.0001905997 | O77: 1.2455692e-07 | P77: 8.3041123e-06 | Q77: 2.9981395e-05 | R77: 6.3865887e-06 | S77: 0.02862523
A78: 2 wht | B78: 0.02811587 | C78: 0.1866295 | D78: 0.6071023 | E78: 0.001204543 | F78: 5.5638779e-05 | G78: 2.8926352e-05 | H78: 0.125556 | I78: 0.2339336 | J78: 2.613409 | K78: 0.1544637 | L78: 9.43884 | M78: 35.24386 | N78: 0.821752 | O78: 0.004305799 | P78: 0.1875052 | Q78: 0.218363 | R78: 0.005893066 | S78: 49.87102
A79: 3 gro | B79: 0.03547825 | C79: 0.2149161 | D79: 0.4703493 | E79: 0.01422193 | F79: 0.002041676 | G79: 0.02538221 | H79: 0.3238413 | I79: 1.433539 | J79: 1.313668 | K79: 0.5003994 | L79: 0.4341094 | M79: 43.37849 | N79: 0.04140093 | O79: 0.02176552 | P79: 0.1322285 | Q79: 0.04536747 | R79: 0.0522377 | S79: 48.43944
A80: 4 v_f | B80: 0.05894043 | C80: 0.3752084 | D80: 0.3864366 | E80: 0.09092227 | F80: 0.0003850489 | G80: 0.005409294 | H80: 0.6913538 | I80: 1.404369 | J80: 15.55063 | K80: 0.2795158 | L80: 6.521482 | M80: 172.9286 | N80: 0.1112077 | O80: 0.02115145 | P80: 0.4783205 | Q80: 0.1945831 | R80: 0.07654036 | S80: 199.175
A81: 5 osd | B81: 0.006228198 | C81: 0.01539414 | D81: 0.001974776 | E81: 0.006210703 | F81: 0.01193367 | G81: 4.3800137e-05 | H81: 0.008880231 | I81: 0.009705248 | J81: 3.741579 | K81: 0.00556298 | L81: 0.09139532 | M81: 0.7995356 | N81: 0.003352767 | O81: 0.001495401 | P81: 0.003757809 | Q81: 0.00883344 | R81: 0.001302938 | S81: 4.717186
A82: 6 c_b | B82: 9.7440825e-06 | C82: 5.7649846e-05 | D82: 0.000471083 | E82: 0.001931211 | F82: 5.3336301e-08 | G82: 2.2340008e-07 | H82: 0.0002006176 | I82: 1.8605886e-05 | J82: 0.002366462 | K82: 0.002337408 | L82: 0.001192461 | M82: 0.3707814 | N82: 6.7101901e-06 | O82: 1.364734e-07 | P82: 1.3552829e-05 | Q82: 4.5114e-05 | R82: 7.7901141e-06 | S82: 0.3794402
A83: 7 pfb | B83: 0.0005432542 | C83: 0.00326391 | D83: 0.004401328 | E83: 0.0001892081 | F83: 9.0555432e-07 | G83: 0.0001893656 | H83: 0.01030417 | I83: 0.02002153 | J83: 0.03175401 | K83: 0.02231937 | L83: 0.0507303 | M83: 0.4003652 | N83: 0.005757369 | O83: 0.0001303737 | P83: 0.01555058 | Q83: 0.03138673 | R83: 0.003212654 | S83: 0.6001203
A84: 8 ocr | B84: 0.007822909 | C84: 0.05109521 | D84: 0.0429289 | E84: 0.007585668 | F84: 2.4113811e-05 | G84: 0.001779269 | H84: 0.2432593 | I84: 0.404486 | J84: 5.503874 | K84: 0.2213634 | L84: 2.379117 | M84: 23.46189 | N84: 0.02582556 | O84: 0.00158701 | P84: 0.01876972 | Q84: 0.06753934 | R84: 0.03393248 | S84: 32.47289
A85: 9 ctl | B85: 0.0009116659 | C85: 0.03164996 | D85: 0.09330142 | E85: 0.002535297 | F85: 4.9412833e-05 | G85: 0.0003608256 | H85: 0.02926713 | I85: 0.03643373 | J85: 0.4903373 | K85: 0.1457732 | L85: 0.1893076 | M85: 8.767535 | N85: 0.02261001 | O85: 0.007683645 | P85: 0.006046559 | Q85: 0.04881052 | R85: 0.2738878 | S85: 10.1465
A86: 10 oap | B86: 0.01317452 | C86: 0.05689165 | D86: 0.06038523 | E86: 0.003852748 | F86: 5.1016039e-05 | G86: 0.0008810936 | H86: 0.04679165 | I86: 0.08425903 | J86: 0.5907842 | K86: 0.4796225 | L86: 0.7614325 | M86: 8.30207 | N86: 0.002925873 | O86: 0.007295006 | P86: 0.006153835 | Q86: 0.0344122 | R86: 0.002124669 | S86: 10.45311
A87: 11 rmk | B87: 1.7207183e-08 | C87: 5.4017949e-07 | D87: 0.0001064501 | E87: 6.5621333e-07 | F87: 8.6451424e-09 | G87: 2.4464461e-08 | H87: 9.2128321e-06 | I87: 1.6765405e-05 | J87: 0.007956961 | K87: 0.0001102236 | L87: 9.4543997e-05 | M87: 0.0004003178 | N87: 7.4349232e-06 | O87: 4.2640345e-09 | P87: 5.1782291e-07 | Q87: 1.3164055e-06 | R87: 1.8695323e-08 | S87: 0.008705014
A88: 12 wol | B88: 3.6683022e-07 | C88: 0.00117785 | D88: 0.0001050471 | E88: 1.1736823e-06 | F88: 5.8224249e-08 | G88: 9.4234001e-06 | H88: 4.6864657e-06 | I88: 8.5565816e-06 | J88: 0.006624188 | K88: 0.0001728021 | L88: 0.001202217 | M88: 0.003845774 | N88: 3.8116168e-06 | O88: 1.0951383e-07 | P88: 5.2446198e-06 | Q88: 4.2823835e-06 | R88: 4.2581942e-06 | S88: 0.01316985
... A149: Total | B149: 94.84372 | C149: 43414 | D149: 4045.98 | E149: 1807.651 | F149: 169.9129 | G149: 661.8225 | H149: 19918.01 | I149: 8922.611 | J149: 84289.97 | K149: 10289.94 | L149: 3669.426 | M149: 89231.73 | N149: 5671.186 | O149: 693.188 | P149: 6071.453 | Q149: 5421.744 | R149: 4844.922 | S149: 289218.4

Sheet ISSUE1
A1: VDFB
B2: TND | C2: 원자력 | D2: 석탄 | E2: 가스 | F2: 풍력 | G2: 수력 | H2: 석유 | I2: 기타 | J2: 태양광
A3: 1 r_01KOR | B3: 4782.8422 | C3: 2100.9022 | D3: 2106.9748 | E3: 1522.279 | F3: 47.922283 | G3: 39.335682 | H3: 2722.2424 | I3: 1110.9407 | J3: 76.106659 | L3: =MIN(B3:J19) -> 0.089986
A4: 2 r_02CHN | B4: 91247.07 | C4: 7182.3222 | D4: 169488.63 | E4: 8402.604 | F4: 3942.8578 | G4: 9975.5826 | H4: 6829.2311 | I4: 7071.7466 | J4: 1080.4408
A5: 3 r_03JPN | B5: 32209.338 | C5: 2972.9106 | D5: 13347.859 | E5: 8186.9809 | F5: 528.81501 | G5: 5845.9623 | H5: 7785.9374 | I5: 8560.7687 | J5: 1898.0068
A6: 4 r_04RUS | B6: 14966.201 | C6: 4225.6017 | D6: 12535.096 | E6: 47395.857 | F6: 2.334783 | G6: 3934.3852 | H6: 3875.9993 | I6: 10024.66 | J6: 15.051793
A7: 5 r_05MNG | B7: 255.81603 | D7: 735.57337 | F7: 8.255378 | G7: 1.182436 | H7: 9.555556 | J7: 0.602846
A8: 6 r_06PRK | B8: 118.04802 | D8: 79.717208 | E8: 12.58004 | G8: 71.24374 | H8: 58.386208 | I8: 2.525715 | J8: 0.090916
A9: 7 r_07NAM | B9: 31512.336 | C9: 24453.473 | D9: 75531.316 | E9: 36718.28 | F9: 5548.6375 | G9: 8499.4379 | H9: 1868.6645 | I9: 4482.6981 | J9: 878.05812
A10: 8 r_08LAM | B10: 24394.123 | C10: 1691.0308 | D10: 2176.6413 | E10: 17025.996 | F10: 1164.0804 | G10: 7060.2712 | H10: 12419.707 | I10: 5525.9983 | J10: 168.70944
A11: 9 r_09WEU | B11: 56334.101 | C11: 13921.992 | D11: 16783.521 | E11: 9424.3216 | F11: 9214.7315 | G11: 4972.5557 | H11: 5205.434 | I11: 14448.827 | J11: 3717.7044
A12: 10 r_10EEU | B12: 11616.351 | C12: 1558.6775 | D12: 13322.479 | E12: 2212.6693 | F12: 418.18003 | G12: 793.85718 | H12: 1534.1797 | I12: 1507.9657 | J12: 123.62493
A13: 11 r_11FSU | B13: 5795.7922 | C13: 3649.4352 | D13: 11817.26 | E13: 10746.43 | F13: 51.868143 | G13: 1027.2067 | H13: 865.20665 | I13: 1862.1755 | J13: 32.009635
A14: 12 r_12MEA | B14: 12513.865 | C14: 1144.8673 | D14: 350.02558 | E14: 58274.321 | F14: 109.20218 | G14: 1642.8781 | H14: 35928.709 | I14: 30.099555 | J14: 64.403722
A15: 13 r_13AFR | B15: 2341.3516 | C15: 1980.0339 | D15: 15177.289 | E15: 2419.3429 | F15: 329.59051 | G15: 1507.1816 | H15: 1510.5353 | I15: 488.98324 | J15: 447.25464
A16: 14 r_14CPA | B16: 3156.1701 | D16: 2665.9496 | E16: 1716.7448 | F16: 5.166828 | G16: 1305.8019 | H16: 41.596205 | I16: 6.812481 | J16: 0.089986
A17: 15 r_15SAS | B17: 28965.358 | C17: 1697.5693 | D17: 77654.936 | E17: 14832.246 | F17: 550.61736 | G17: 4667.7684 | H17: 4840.2521 | I17: 3670.4307 | J17: 263.11619
A18: 16 r_16PAS | B18: 9819.5922 | C18: 161.11725 | D18: 9018.1003 | E18: 11076.938 | F18: 41.747692 | G18: 799.384 | H18: 3520.3774 | I18: 2244.8142 | J18: 89.575312
A19: 17 r_17PAO | B19: 9203.9951 | D19: 8002.7955 | E19: 3726.2117 | F19: 118.65637 | G19: 308.15863 | H19: 435.50543 | I19: 245.36708 | J19: 63.194071

Sheet VDFB_ref(한국)
A1: VDFB | B1: 1 a_pdr | C1: 2 a_wht | D1: 3 a_gro | E1: 4 a_v_f | F1: 5 a_osd | G1: 6 a_c_b | H1: 7 a_pfb | I1: 8 a_ocr | J1: 9 a_ctl | K1: 10 a_oap | L1: 11 a_rmk | M1: 12 a_wol | N1: 13 a_frs | O1: 14 a_fsh | P1: 15 a_coa | Q1: 16 a_oil | R1: 17 a_gas | S1: 18 a_oxt | T1: 19 a_cmt | U1: 20 a_omt | V1: 21 a_vol | W1: 22 a_mil | X1: 23 a_pcr | Y1: 24 a_sgr | Z1: 25 a_ofd | AA1: 26 a_b_t | AB1: 27 a_tex | AC1: 28 a_wap | AD1: 29 a_lea | AE1: 30 a_lum | AF1: 31 a_ppp | AG1: 32 a_p_c | AH1: 33 a_chm | AI1: 34 a_bph | AJ1: 35 a_rpp | AK1: 36 a_nmm | AL1: 37 a_i_s | AM1: 38 a_nfm | AN1: 39 a_fmp | AO1: 40 a_ele | AP1: 41 a_eeq | AQ1: 42 a_ome | AR1: 43 a_mvh | AS1: 44 a_otn | AT1: 45 a_omf | AU1: 46 a_TnD | AV1: 47 a_eNuclear | AW1: 48 a_eCoal | AX1: 49 a_eGas | AY1: 50 a_eWind | AZ1: 51 a_eHydro | BA1: 52 a_eOil | BB1: 53 a_eOther | BC1: 54 a_eSolar | BD1: 55 a_wtr | BE1: 56 a_cns | BF1: 57 a_trd | BG1: 58 a_afs | BH1: 59 a_otp | BI1: 60 a_wtp | BJ1: 61 a_atp | BK1: 62 a_whs | BL1: 63 a_cmn | BM1: 64 a_ofi | BN1: 65 a_ins | BO1: 66 a_rsa | BP1: 67 a_obs | BQ1: 68 a_ros | BR1: 69 a_osg | BS1: 70 a_edu | BT1: 71 a_hht | BU1: 72 a_dwe | BV1: Total | BX1: 47 a_eNuclear | BY1: 49 a_eGas | BZ1: 50 a_eWind | CA1: 53 a_eOther
A2: 1 pdr | B2: 235.44057 | C2: 0.868489 | D2: 0.781739 | E2: 73.638039 | F2: 2.892915 | G2: 0.011711 | H2: 0.208568 | I2: 14.255424 | J2: 131.65016 | K2: 104.85478 | L2: 63.238949 | M2: 0.962164 | N2: 31.834063 | O2: 13.461308 | P2: 0 | Q2: 5e-06 | R2: 3.6e-05 | S2: 5.1e-05 | T2: 0.155493 | U2: 1.927837 | V2: 0.411119 | W2: 0.63775 | X2: 5226.9941 | Y2: 0.00382 | Z2: 645.41455 | AA2: 0.683967 | AB2: 0.079924 | AC2: 0.287427 | AD2: 0.153057 | AE2: 0.007176 | AF2: 0.032847 | AG2: 0.000386 | AH2: 1.107512 | AI2: 0.110788 | AJ2: 0.134182 | AK2: 0.024969 | AL2: 0.000548 | AM2: 7.1e-05 | AN2: 0.024902 | AO2: 0.414393 | AP2: 0.566034 | AQ2: 0.696861 | AR2: 0.002354 | AS2: 0.00035 | AT2: 3.697609 | AU2: 0.016818 | AV2: 0.008877 | AW2: 0.007371 | AX2: 0.002748 | AY2: 0.000212 | AZ2: 0.000155 | BA2: 0.001055 | BB2: 0.002043 | BC2: 0.000272 | BD2: 0.01285 | BE2: 0.099394 | BF2: 1.962025 | BG2: 34.49905 | BH2: 0.033746 | BI2: 0.035975 | BJ2: 0.000348 | BK2: 1.474426 | BL2: 0.014931 | BM2: 0.001409 | BN2: 0.000626 | BO2: 0.536904 | BP2: 1.671824 | BQ2: 2.830645 | BR2: 49.857239 | BS2: 5.816187 | BT2: 0.329124 | BU2: 0.057275 | BV2: 6656.9426 | BX2: =AV2/$AV$74 -> 4.2253277e-06 | BY2: =AX2/$AX$74 -> 1.8051881e-06 | BZ2: =AY2/$AY$74 -> 4.4238293e-06 | CA2: =BB2/$BB$74 -> 1.838982e-06
A3: 2 wht | B3: 0.142582 | C3: 0.159666 | D3: 0.040317 | E3: 0.108266 | F3: 4.4e-05 | G3: 2.7e-05 | H3: 0.000498 | I3: 0.017613 | J3: 0.046907 | K3: 0.252344 | L3: 0.124276 | M3: 0.001779 | N3: 0.039717 | O3: 0.026473 | P3: 0 | Q3: 0 | R3: 0 | S3: 3e-06 | T3: 0.001656 | U3: 0.038771 | V3: 0.422944 | W3: 0.000518 | X3: 0.125336 | Y3: 0.001703 | Z3: 21.836815 | AA3: 4.331537 | AB3: 0.002157 | AC3: 0.003066 | AD3: 0.001207 | AE3: 0.000393 | AF3: 0.001655 | AG3: 3.8e-05 | AH3: 0.141492 | AI3: 0.002232 | AJ3: 0.001655 | AK3: 0.000328 | AL3: 4.1e-05 | AM3: 1.4e-05 | AN3: 0.001046 | AO3: 0.001584 | AP3: 0.002087 | AQ3: 0.003326 | AR3: 0.000442 | AS3: 7.2e-05 | AT3: 4.637761 | AU3: 0.001244 | AV3: 0.000657 | AW3: 0.000545 | AX3: 0.000203 | AY3: 1.6e-05 | AZ3: 1.1e-05 | BA3: 7.8e-05 | BB3: 0.000151 | BC3: 2e-05 | BD3: 0.000171 | BE3: 0.013583 | BF3: 0.025489 | BG3: 1.613559 | BH3: 0.000666 | BI3: 0.000658 | BJ3: 0.0001 | BK3: 0.016996 | BL3: 0.000832 | BM3: 0.000566 | BN3: 0.00036 | BO3: 0.005658 | BP3: 0.064631 | BQ3: 0.042636 | BR3: 1.567062 | BS3: 0.013567 | BT3: 0.149878 | BU3: 0.001095 | BV3: 36.040827 | BX3: =AV3/$AV$74 -> 3.127228e-07 | BY3: =AX3/$AX$74 -> 1.3335269e-07 | BZ3: =AY3/$AY$74 -> 3.3387391e-07 | CA3: =BB3/$BB$74 -> 1.3592084e-07
A4: 3 gro | B4: 0.305475 | C4: 0.125064 | D4: 0.125417 | E4: 0.267453 | F4: 0.000393 | G4: 7.5e-05 | H4: 0.001244 | I4: 0.007169 | J4: 0.294068 | K4: 1.115281 | L4: 0.365435 | M4: 0.004088 | N4: 0.173153 | O4: 0.10114 | P4: 0 | Q4: 0 | R4: 1e-06 | S4: 5e-06 | T4: 0.005926 | U4: 0.145719 | V4: 1.092175 | W4: 0.003899 | X4: 0.619689 | Y4: 0.001945 | Z4: 24.707844 | AA4: 11.284249 | AB4: 0.003065 | AC4: 0.00449 | AD4: 0.003278 | AE4: 0.002582 | AF4: 0.004444 | AG4: 3.6e-05 | AH4: 0.141205 | AI4: 0.004983 | AJ4: 0.003858 | AK4: 0.000267 | AL4: 5.1e-05 | AM4: 1.2e-05 | AN4: 0.000937 | AO4: 0.005231 | AP4: 0.006753 | AQ4: 0.008701 | AR4: 0.000254 | AS4: 0.000187 | AT4: 12.324741 | AU4: 0.000503 | AV4: 0.000265 | AW4: 0.00022 | AX4: 8.2e-05 | AY4: 6e-06 | AZ4: 5e-06 | BA4: 3.2e-05 | BB4: 6.1e-05 | BC4: 8e-06 | BD4: 0.001538 | BE4: 0.008329 | BF4: 0.022688 | BG4: 3.109436 | BH4: 0.000676 | BI4: 0.001109 | BJ4: 0.000412 | BK4: 0.006891 | BL4: 0.003966 | BM4: 0.00071 | BN4: 0.000487 | BO4: 0.003048 | BP4: 0.143204 | BQ4: 0.059911 | BR4: 0.492846 | BS4: 0.043372 | BT4: 0.418745 | BU4: 0.000437 | BV4: 57.580973 | BX4: =AV4/$AV$74 -> 1.2613629e-07 | BY4: =AX4/$AX$74 -> 5.3866604e-08 | BZ4: =AY4/$AY$74 -> 1.2520272e-07 | CA4: =BB4/$BB$74 -> 5.4908419e-08
A5: 4 v_f | B5: 51.95723 | C5: 0.833316 | D5: 0.720939 | E5: 61.92585 | F5: 0.012878 | G5: 0.014992 | H5: 0.216589 | I5: 0.945156 | J5: 11.33894 | K5: 35.375847 | L5: 5.700005 | M5: 0.278457 | N5: 32.826168 | O5: 16.160227 | P5: 0.009083 | Q5: 0.024684 | R5: 0.000441 | S5: 0.872711 | T5: 0.195181 | U5: 9.377981 | V5: 2.440901 | W5: 19.266869 | X5: 0.142149 | Y5: 0.069482 | Z5: 1869.7476 | AA5: 112.09949 | AB5: 1.96016 | AC5: 0.754505 | AD5: 0.294793 | AE5: 0.414109 | AF5: 1.407896 | AG5: 0.32057 | AH5: 16.693657 | AI5: 16.797001 | AJ5: 1.991289 | AK5: 1.793231 | AL5: 2.579478 | AM5: 1.033528 | AN5: 4.953287 | AO5: 4.270399 | AP5: 1.776151 | AQ5: 4.478749 | AR5: 1.545892 | AS5: 0.591062 | AT5: 189.26808 | AU5: 0.349841 | AV5: 0.184659 | AW5: 0.153339 | AX5: 0.057168 | AY5: 0.00441 | AZ5: 0.003228 | BA5: 0.021954 | BB5: 0.042499 | BC5: 0.005648 | BD5: 2.285331 | BE5: 7.483033 | BF5: 21.335407 | BG5: 3397.0005 | BH5: 2.299411 | BI5: 0.478476 | BJ5: 0.367359 | BK5: 2.172335 | BL5: 9.790193 | BM5: 3.728606 | BN5: 2.536878 | BO5: 1.71866 | BP5: 22.463152 | BQ5: 84.250641 | BR5: 101.6351 | BS5: 40.118088 | BT5: 98.289658 | BU5: 0.062637 | BV5: 6284.3152 | BX5: =AV5/$AV$74 -> 8.7895098e-05 | BY5: =AX5/$AX$74 -> 3.755422e-05 | BZ5: =AY5/$AY$74 -> 9.2023996e-05 | CA5: =BB5/$BB$74 -> 3.8254966e-05
A6: 5 osd | B6: 0.340968 | C6: 0.005304 | D6: 0.005957 | E6: 303.23346 | F6: 19.861965 | G6: 0.000909 | H6: 1.322587 | I6: 21.061819 | J6: 0.085841 | K6: 0.268669 | L6: 0.043457 | M6: 0.000927 | N6: 0.852224 | O6: 0.092846 | P6: 1e-06 | Q6: 1e-06 | R6: 0.000109 | S6: 1.4e-05 | T6: 0.00212 | U6: 0.027495 | V6: 37.799709 | W6: 0.022023 | X6: 0.01547 | Y6: 0.06744 | Z6: 25.173075 | AA6: 0.207009 | AB6: 0.409223 | AC6: 0.068396 | AD6: 0.027072 | AE6: 0.006072 | AF6: 0.004859 | AG6: 0.000269 | AH6: 1.89531 | AI6: 0.044099 | AJ6: 0.065126 | AK6: 0.005719 | AL6: 0.000372 | AM6: 7e-05 | AN6: 0.007888 | AO6: 0.015741 | AP6: 0.015058 | AQ6: 0.536268 | AR6: 0.021993 | AS6: 0.008238 | AT6: 0.036453 | AU6: 0.1811 | AV6: 0.095592 | AW6: 0.079378 | AX6: 0.029594 | AY6: 0.002283 | AZ6: 0.001671 | BA6: 0.011365 | BB6: 0.022 | BC6: 0.002924 | BD6: 0.004158 | BE6: 3.573989 | BF6: 1.203352 | BG6: 3.027756 | BH6: 0.002617 | BI6: 0.003633 | BJ6: 0.000163 | BK6: 0.104791 | BL6: 0.00508 | BM6: 0.000207 | BN6: 0.000179 | BO6: 0.03234 | BP6: 0.198971 | BQ6: 3.876603 | BR6: 45.812973 | BS6: 7.815326 | BT6: 1.847653 | BU6: 0.00625 | BV6: 481.60157 | BX6: =AV6/$AV$74 -> 4.5500453e-05 | BY6: =AX6/$AX$74 -> 1.9440589e-05 | BZ6: =AY6/$AY$74 -> 4.7639634e-05 | CA6: =BB6/$BB$74 -> 1.9803036e-05
A7: 6 c_b | B7: 0.000484 | C7: 7e-06 | D7: 5e-06 | E7: 0.019028 | F7: 0.000165 | G7: 0.001223 | H7: 7e-06 | I7: 0.004299 | J7: 0.003078 | K7: 0.021664 | L7: 0.006732 | M7: 4.2e-05 | N7: 0.000493 | O7: 0.000309 | P7: 0 | Q7: 0 | R7: 0.000142 | S7: 3e-06 | T7: 0.037132 | U7: 0.373038 | V7: 0.055232 | W7: 0.060189 | X7: 0.004949 | Y7: 2.602684 | Z7: 0.757977 | AA7: 0.345539 | AB7: 0.002058 | AC7: 0.002441 | AD7: 0.000399 | AE7: 0.000664 | AF7: 0.001303 | AG7: 1e-05 | AH7: 0.711104 | AI7: 0.0257 | AJ7: 0.015159 | AK7: 0.000212 | AL7: 2.2e-05 | AM7: 4e-06 | AN7: 0.000512 | AO7: 0.002804 | AP7: 0.000897 | AQ7: 0.002083 | AR7: 0.0001 | AS7: 0.000623 | AT7: 0.003378 | AU7: 0.079728 | AV7: 0.042082 | AW7: 0.034943 | AX7: 0.013028 | AY7: 0.001005 | AZ7: 0.000736 | BA7: 0.005003 | BB7: 0.009685 | BC7: 0.001287 | BD7: 0.020579 | BE7: 0.004389 | BF7: 0.088768 | BG7: 0.383803 | BH7: 0.000308 | BI7: 0.00044 | BJ7: 5.4e-05 | BK7: 0.013411 | BL7: 0.000601 | BM7: 8.1e-05 | BN7: 3e-05 | BO7: 0.003138 | BP7: 0.013053 | BQ7: 0.021515 | BR7: 0.4005 | BS7: 0.006401 | BT7: 0.002534 | BU7: 0.001031 | BV7: 6.212027 | BX7: =AV7/$AV$74 -> 2.0030443e-05 | BY7: =AX7/$AX$74 -> 8.5582209e-06 | BZ7: =AY7/$AY$74 -> 2.0971455e-05 | CA7: =BB7/$BB$74 -> 8.7178367e-06
A8: 7 pfb | B8: 0.114624 | C8: 0.001772 | D8: 0.001743 | E8: 0.113838 | F8: 0.00013 | G8: 2e-05 | H8: 0.483375 | I8: 0.08161 | J8: 0.129762 | K8: 2.043488 | L8: 0.029189 | M8: 0.036725 | N8: 0.05821 | O8: 0.033892 | P8: 0 | Q8: 0 | R8: 0 | S8: 1e-06 | T8: 0.000117 | U8: 0.0018 | V8: 0.056205 | W8: 0.001338 | X8: 0.002202 | Y8: 3.1e-05 | Z8: 3.56187 | AA8: 0.01969 | AB8: 13.675428 | AC8: 0.382628 | AD8: 0.004255 | AE8: 0.001616 | AF8: 0.002115 | AG8: 1.5e-05 | AH8: 0.133276 | AI8: 0.001466 | AJ8: 0.02169 | AK8: 0.000717 | AL8: 3e-05 | AM8: 6e-06 | AN8: 0.001048 | AO8: 0.015198 | AP8: 0.016387 | AQ8: 0.021098 | AR8: 0.000196 | AS8: 3.1e-05 | AT8: 1.704839 | AU8: 0.000527 | AV8: 0.000278 | AW8: 0.000231 | AX8: 8.6e-05 | AY8: 7e-06 | AZ8: 5e-06 | BA8: 3.3e-05 | BB8: 6.4e-05 | BC8: 9e-06 | BD8: 0.001038 | BE8: 0.008053 | BF8: 0.010456 | BG8: 0.097456 | BH8: 0.000128 | BI8: 0.000192 | BJ8: 4.5e-05 | BK8: 0.003931 | BL8: 0.000202 | BM8: 0.000378 | BN8: 0.000255 | BO8: 0.00088 | BP8: 0.142305 | BQ8: 0.192897 | BR8: 0.17802 | BS8: 0.01179 | BT8: 0.001635 | BU8: 0.000388 | BV8: 23.404963 | BX8: =AV8/$AV$74 -> 1.3232411e-07 | BY8: =AX8/$AX$74 -> 5.6494243e-08 | BZ8: =AY8/$AY$74 -> 1.4606984e-07 | CA8: =BB8/$BB$74 -> 5.7608833e-08
A9: 8 ocr | B9: 4.130362 | C9: 0.063606 | D9: 0.055306 | E9: 3.813952 | F9: 0.000744 | G9: 0.001209 | H9: 0.395214 | I9: 7.492473 | J9: 1.161414 | K9: 13.619459 | L9: 0.497035 | M9: 0.036719 | N9: 2.530796 | O9: 1.494395 | P9: 0 | Q9: 0 | R9: 0.000169 | S9: 0.730863 | T9: 0.006105 | U9: 1.800141 | V9: 19.52096 | W9: 0.349205 | X9: 0.005687 | Y9: 0.000711 | Z9: 206.87671 | AA9: 32.797665 | AB9: 1.293703 | AC9: 1.064469 | AD9: 0.235853 | AE9: 0.284295 | AF9: 0.807214 | AG9: 0.446764 | AH9: 9.733463 | AI9: 45.283653 | AJ9: 2.276019 | AK9: 1.19409 | AL9: 1.402591 | AM9: 0.790947 | AN9: 1.685414 | AO9: 2.37076 | AP9: 0.748996 | AQ9: 2.559663 | AR9: 1.130874 | AS9: 0.183675 | AT9: 10.001121 | AU9: 0.318549 | AV9: 0.168163 | AW9: 0.139633 | AX9: 0.05206 | AY9: 0.004016 | AZ9: 0.002939 | BA9: 0.019992 | BB9: 0.038701 | BC9: 0.005144 | BD9: 0.587722 | BE9: 12.66799 | BF9: 8.85835 | BG9: 112.37621 | BH9: 0.678653 | BI9: 0.224258 | BJ9: 0.062141 | BK9: 2.318262 | BL9: 2.579051 | BM9: 3.311424 | BN9: 2.944999 | BO9: 0.785087 | BP9: 11.126168 | BQ9: 20.491463 | BR9: 17.272818 | BS9: 5.230567 | BT9: 171.5985 | BU9: 0.002668 | BV9: 754.73999 | BX9: =AV9/$AV$74 -> 8.0043233e-05 | BY9: =AX9/$AX$74 -> 3.4198724e-05 | BZ9: =AY9/$AY$74 -> 8.3802351e-05 | CA9: =BB9/$BB$74 -> 3.4836241e-05
A10: 9 ctl | B10: 15.107322 | C10: 0.187669 | D10: 0.167183 | E10: 17.780748 | F10: 0.052013 | G10: 0.003682 | H10: 0.096685 | I10: 1.226386 | J10: 15.849827 | K10: 5.270207 | L10: 1.001124 | M10: 0.09894 | N10: 7.095388 | O10: 3.420288 | P10: 2e-06 | Q10: 1e-06 | R10: 6.1e-05 | S10: 1.7e-05 | T10: 1373.3213 | U10: 1969.2418 | V10: 0.014822 | W10: 177.75938 | X10: 0.010142 | Y10: 0.005055 | Z10: 8.04484 | AA10: 0.56244 | AB10: 0.125394 | AC10: 0.822699 | AD10: 0.834084 | AE10: 0.001551 | AF10: 0.019425 | AG10: 0.000231 | AH10: 3.959442 | AI10: 2.071414 | AJ10: 0.468879 | AK10: 0.004705 | AL10: 0.000407 | AM10: 6.9e-05 | AN10: 0.012933 | AO10: 0.05325 | AP10: 0.027294 | AQ10: 0.038939 | AR10: 0.005519 | AS10: 0.003069 | AT10: 3.136763 | AU10: 0.010479 | AV10: 0.005533 | AW10: 0.004594 | AX10: 0.001713 | AY10: 0.000132 | AZ10: 9.7e-05 | BA10: 0.000658 | BB10: 0.001273 | BC10: 0.000169 | BD10: 0.092654 | BE10: 0.277041 | BF10: 0.218586 | BG10: 13.917237 | BH10: 0.006896 | BI10: 0.021545 | BJ10: 0.001131 | BK10: 0.258588 | BL10: 0.007294 | BM10: 0.002477 | BN10: 0.001612 | BO10: 0.017438 | BP10: 6.52196 | BQ10: 0.576975 | BR10: 9.205024 | BS10: 1.550872 | BT10: 7.088772 | BU10: 0.032165 | BV10: 3647.7263 | BX10: =AV10/$AV$74 -> 2.6336305e-06 | BY10: =AX10/$AX$74 -> 1.1252865e-06 | BZ10: =AY10/$AY$74 -> 2.7544598e-06 | CA10: =BB10/$BB$74 -> 1.1458757e-06
A11: 10 oap | B11: 30.425673 | C11: 0.488341 | D11: 0.422117 | E11: 39.005024 | F11: 0.018775 | G11: 0.00872 | H11: 0.12509 | I11: 0.994843 | J11: 4.705757 | K11: 194.10297 | L11: 2.436938 | M11: 0.194511 | N11: 18.864622 | O11: 9.151719 | P11: 3e-06 | Q11: 4e-06 | R11: 7.3e-05 | S11: 5.5e-05 | T11: 2156.2468 | U11: 5354.9321 | V11: 0.059535 | W11: 5.577849 | X11: 0.047678 | Y11: 0.0019 | Z11: 177.1863 | AA11: 1.002662 | AB11: 0.219804 | AC11: 1.606163 | AD11: 2.451217 | AE11: 0.003507 | AF11: 0.051044 | AG11: 0.000734 | AH11: 12.755547 | AI11: 3.981852 | AJ11: 1.716106 | AK11: 0.01337 | AL11: 0.001041 | AM11: 0.000173 | AN11: 0.041641 | AO11: 0.123886 | AP11: 0.037093 | AQ11: 0.056703 | AR11: 0.014749 | AS11: 0.0061 | AT11: 24.888119 | AU11: 0.017261 | AV11: 0.009111 | AW11: 0.007566 | AX11: 0.002821 | AY11: 0.000218 | AZ11: 0.000159 | BA11: 0.001083 | BB11: 0.002097 | BC11: 0.000279 | BD11: 0.309035 | BE11: 1.01551 | BF11: 0.29635 | BG11: 569.74512 | BH11: 0.013419 | BI11: 0.020456 | BJ11: 0.000729 | BK11: 0.530362 | BL11: 0.014927 | BM11: 0.007213 | BN11: 0.004984 | BO11: 0.113277 | BP11: 11.368984 | BQ11: 2.634498 | BR11: 20.111753 | BS11: 4.045336 | BT11: 36.11095 | BU11: 0.043697 | BV11: 8690.3961 | BX11: =AV11/$AV$74 -> 4.3367084e-06 | BY11: =AX11/$AX$74 -> 1.8531426e-06 | BZ11: =AY11/$AY$74 -> 4.549032e-06 | CA11: =BB11/$BB$74 -> 1.8875894e-06
A12: 11 rmk | B12: 5.95259 | C12: 0.079613 | D12: 0.06985 | E12: 6.064141 | F12: 0.01349 | G12: 0.00155 | H12: 0.363832 | I12: 0.258452 | J12: 1.796222 | K12: 2.166675 | L12: 4.563596 | M12: 0.0025 | N12: 3.073132 | O12: 1.446148 | P12: 4e-06 | Q12: 4e-06 | R12: 2.7e-05 | S12: 0.00011 | T12: 41.395596 | U12: 61.305004 | V12: 0.119518 | W12: 1330.238 | X12: 0.040568 | Y12: 0.005242 | Z12: 1.184258 | AA12: 0.120573 | AB12: 0.086092 | AC12: 0.130921 | AD12: 0.2494 | AE12: 0.009816 | AF12: 0.020413 | AG12: 0.000962 | AH12: 2.424747 | AI12: 0.095773 | AJ12: 0.080398 | AK12: 0.01374 | AL12: 0.001988 | AM12: 0.000646 | AN12: 0.029328 | AO12: 0.016253 | AP12: 0.012813 | AQ12: 0.027647 | AR12: 0.111241 | AS12: 0.037194 | AT12: 0.892537 | AU12: 0.020786 | AV12: 0.010972 | AW12: 0.009111 | AX12: 0.003397 | AY12: 0.000262 | AZ12: 0.000192 | BA12: 0.001304 | BB12: 0.002525 | BC12: 0.000336 | BD12: 0.010979 | BE12: 0.04441 | BF12: 0.240534 | BG12: 30.445326 | BH12: 0.013955 | BI12: 0.049557 | BJ12: 0.002293 | BK12: 0.488509 | BL12: 0.021233 | BM12: 0.003583 | BN12: 0.002421 | BO12: 0.171569 | BP12: 0.500091 | BQ12: 0.834749 | BR12: 17.252857 | BS12: 0.86902 | BT12: 0.123523 | BU12: 0.021839 | BV12: 1515.648 | BX12: =AV12/$AV$74 -> 5.2225183e-06 | BY12: =AX12/$AX$74 -> 2.2315226e-06 | BZ12: =AY12/$AY$74 -> 5.4671853e-06 | CA12: =BB12/$BB$74 -> 2.2728485e-06
A13: 12 wol | B13: 0.071781 | C13: 0.00289 | D13: 0.002623 | E13: 0.343521 | F13: 0.002976 | G13: 5.9e-05 | H13: 2.3e-05 | I13: 0.041359 | J13: 0.078114 | K13: 0.143535 | L13: 0.002315 | M13: 0.146274 | N13: 0.015404 | O13: 0.020619 | P13: 0 | Q13: 0 | R13: 0 | S13: 1e-06 | T13: 0.039435 | U13: 0.074999 | V13: 0.001078 | W13: 1.596346 | X13: 0.000404 | Y13: 0.000428 | Z13: 3.241829 | AA13: 0.289256 | AB13: 6.248134 | AC13: 0.443414 | AD13: 0.119157 | AE13: 0.000117 | AF13: 0.00015 | AG13: 4e-06 | AH13: 1.050247 | AI13: 1.151871 | AJ13: 0.054416 | AK13: 0.000135 | AL13: 9e-06 | AM13: 2e-06 | AN13: 0.000252 | AO13: 0.004551 | AP13: 0.003427 | AQ13: 0.0043 | AR13: 2.5e-05 | AS13: 8e-06 | AT13: 1.653275 | AU13: 0.000203 | AV13: 0.000107 | AW13: 8.9e-05 | AX13: 3.3e-05 | AY13: 3e-06 | AZ13: 2e-06 | BA13: 1.3e-05 | BB13: 2.5e-05 | BC13: 3e-06 | BD13: 0.009231 | BE13: 0.031153 | BF13: 0.008995 | BG13: 2.797723 | BH13: 9e-05 | BI13: 0.00045 | BJ13: 3.9e-05 | BK13: 0.00643 | BL13: 0.000314 | BM13: 8.1e-05 | BN13: 5.4e-05 | BO13: 0.0009 | BP13: 2.271706 | BQ13: 0.032252 | BR13: 0.337695 | BS13: 0.009089 | BT13: 3.95355 | BU13: 0.000769 | BV13: 26.309763 | BX13: =AV13/$AV$74 -> 5.0930501e-08 | BY13: =AX13/$AX$74 -> 2.1678024e-08 | BZ13: =AY13/$AY$74 -> 6.2601358e-08 | CA13: =BB13/$BB$74 -> 2.250345e-08
... A74: Total | B74: 1748.1752 | C74: 36.930282 | D74: 32.775733 | E74: 3927.8851 | F74: 182.98439 | G74: 4.100234 | H74: 27.666352 | I74: 260.91481 | J74: 2908.3066 | K74: 5834.9633 | L74: 1229.9515 | M74: 39.830352 | N74: 874.75512 | O74: 3357.0029 | P74: 63.553488 | Q74: 141.27442 | R74: 153.60707 | S74: 2830.607 | T74: 4044.3352 | U74: 11651.8 | V74: 1038.6555 | W74: 5120.8038 | X74: 5724.0444 | Y74: 144.22854 | Z74: 30252.629 | AA74: 7888.7189 | AB74: 14880.77 | AC74: 8950.092 | AD74: 2828.7001 | AE74: 4254.7408 | AF74: 17866.118 | AG74: 24540.165 | AH74: 80177.548 | AI74: 7525.3498 | AJ74: 41431.314 | AK74: 25896.186 | AL74: 47214.077 | AM74: 12928.839 | AN74: 60760.02 | AO74: 120667.76 | AP74: 49238.504 | AQ74: 80385.598 | AR74: 112662.92 | AS74: 32522.321 | AT74: 37238.843 | AU74: 4782.8422 | AV74: 2100.9022 | AW74: 2106.9748 | AX74: 1522.279 | AY74: 47.922283 | AZ74: 39.335682 | BA74: 2722.2424 | BB74: 1110.9407 | BC74: 76.106659 | BD74: 7374.1692 | BE74: 126685.13 | BF74: 98641.249 | BG74: 69179.006 | BH74: 26818.841 | BI74: 7145.9961 | BJ74: 6901.0595 | BK74: 13874.622 | BL74: 50387.546 | BM74: 25806.055 | BN74: 24241.569 | BO74: 28703.393 | BP74: 93450.795 | BQ74: 34791.718 | BR74: 23383.393 | BS74: 28208.712 | BT74: 41199.668 | BU74: 10541.68 | BV74: 1603334.5 | BX74: =AV74/$AV$74 -> 1 | BY74: =AX74/$AX$74 -> 1 | BZ74: =AY74/$AY$74 -> 1 | CA74: =BB74/$BB$74 -> 1
A76: 47 eNuclear | B76: =B48/($BV$48) -> 0.002425944 | C76: =C48/($BV$48) -> 0.00027678597 | D76: =D48/($BV$48) -> 0.00024031061 | E76: =E48/($BV$48) -> 0.0066413296 | F76: =F48/($BV$48) -> 0.0006280282 | G76: =G48/($BV$48) -> 3.6998907e-06 | H76: =H48/($BV$48) -> 6.8792183e-05 | I76: =I48/($BV$48) -> 0.00057572782 | ... BV76: =BV48/($BV$48) -> 1
A77: 49 eGas | B77: =B50/$BV$50 -> 0.0024259442 | C77: =C50/$BV$50 -> 0.00027678608 | D77: =D50/$BV$50 -> 0.00024031054 | E77: =E50/$BV$50 -> 0.0066413292 | F77: =F50/$BV$50 -> 0.00062802819 | G77: =G50/$BV$50 -> 3.6999079e-06 | H77: =H50/$BV$50 -> 6.8792218e-05 | I77: =I50/$BV$50 -> 0.00057572789 | ... BV77: =BV50/$BV$50 -> 1
A78: 50 eWind | B78: =B51/$BV$51 -> 0.0024259441 | C78: =C51/$BV$51 -> 0.00027678723 | D78: =D51/$BV$51 -> 0.0002403095 | E78: =E51/$BV$51 -> 0.0066413306 | F78: =F51/$BV$51 -> 0.00062802937 | G78: =G51/$BV$51 -> 3.7002033e-06 | H78: =H51/$BV$51 -> 6.8791054e-05 | I78: =I51/$BV$51 -> 0.00057572893 | ... BV78: =BV51/$BV$51 -> 1
A79: 53 eOther | B79: =B54/$BV$54 -> 0.0024259438 | C79: =C54/$BV$54 -> 0.00027678597 | D79: =D54/$BV$54 -> 0.00024031036 | E79: =E54/$BV$54 -> 0.0066413301 | F79: =F54/$BV$54 -> 0.00062802828 | G79: =G54/$BV$54 -> 3.6999248e-06 | H79: =H54/$BV$54 -> 6.8792284e-05 | I79: =I54/$BV$54 -> 0.00057572788 | ... BV79: =BV54/$BV$54 -> 1

Sheet VDFB_MNG
A1: VDFB | B1: 1 pdr | C1: 2 wht | D1: 3 gro | E1: 4 v_f | F1: 5 osd | G1: 6 c_b | H1: 7 pfb | I1: 8 ocr | J1: 9 ctl | K1: 10 oap | L1: 11 rmk | M1: 12 wol | N1: 13 frs | O1: 14 fsh | P1: 15 coa | Q1: 16 oil | R1: 17 gas | S1: 18 oxt | T1: 19 cmt | U1: 20 omt | V1: 21 vol | W1: 22 mil | X1: 23 pcr | Y1: 24 sgr | Z1: 25 ofd | AA1: 26 b_t | AB1: 27 tex | AC1: 28 wap | AD1: 29 lea | AE1: 30 lum | AF1: 31 ppp | AG1: 32 p_c | AH1: 33 chm | AI1: 34 bph | AJ1: 35 rpp | AK1: 36 nmm | AL1: 37 i_s | AM1: 38 nfm | AN1: 39 fmp | AO1: 40 ele | AP1: 41 eeq | AQ1: 42 ome | AR1: 43 mvh | AS1: 44 otn | AT1: 45 omf | AU1: 46 TnD | AV1: 47 eNuclear | AW1: 48 eCoal | AX1: 49 eGas | AY1: 50 eWind | AZ1: 51 eHydro | BA1: 52 eOil | BB1: 53 eOther | BC1: 54 eSolar | BD1: 55 wtr | BE1: 56 cns | BF1: 57 trd | BG1: 58 afs | BH1: 59 otp | BI1: 60 wtp | BJ1: 61 atp | BK1: 62 whs | BL1: 63 cmn | BM1: 64 ofi | BN1: 65 ins | BO1: 66 rsa | BP1: 67 obs | BQ1: 68 ros | BR1: 69 osg | BS1: 70 edu | BT1: 71 hht | BU1: 72 dwe | BV1: Total
A2: 1 pdr | B2: 0.000190845 | C2: 0.0005288834 | D2: 1.3462631e-05 | E2: 0.01150398 | F2: 0.003534865 | G2: 0.0001880274 | H2: 0.0001993374 | I2: 0.002918084 | J2: 0.05222883 | K2: 0.0003749722 | L2: 0.007291988 | M2: 0.007987074 | N2: 0.0001800778 | O2: 3.9959773e-06 | P2: 1.4702426e-06 | Q2: 1.6083512e-06 | R2: 9.7460131e-08 | S2: 5.5330906e-06 | T2: 0.002460199 | U2: 0.002045464 | V2: 1.5231057e-05 | W2: 0.001852371 | X2: 0.001853264 | Y2: 2.087817e-07 | Z2: 0.003376325 | AA2: 0.001254452 | AB2: 7.2149334e-05 | AC2: 0.000280467 | AD2: 0.0001019239 | AE2: 6.1744513e-06 | AF2: 7.9035655e-14 | AG2: 4.3903277e-08 | AH2: 3.1527929e-07 | AI2: 7.1498634e-09 | AJ2: 1.2196203e-09 | AK2: 8.2691367e-06 | AL2: 2.7127294e-09 | AM2: 2.6169766e-07 | AN2: 5.4755184e-14 | AO2: 6.6970308e-14 | AP2: 1.3525457e-13 | AQ2: 2.1287894e-13 | AR2: 2.4452886e-15 | AS2: 2.5761158e-15 | AT2: 0.0001651895 | AU2: 0.0001629688 | AV2: 0 | AW2: 0.0002913975 | AX2: 0 | AY2: 4.9323535e-06 | AZ2: 5.8585084e-07 | BA2: 4.4730559e-06 | BB2: 0 | BC2: 3.5729337e-07 | BD2: 2.3145742e-05 | BE2: 0.0001223473 | BF2: 0.002265458 | BG2: 0.03246836 | BH2: 8.4775893e-05 | BI2: 1.2069652e-05 | BJ2: 8.7345978e-07 | BK2: 0.001900586 | BL2: 9.1598777e-06 | BM2: 0.0006066668 | BN2: 2.1983155e-07 | BO2: 0.00374585 | BP2: 0.0007312439 | BQ2: 0.0009007056 | BR2: 0.04725908 | BS2: 0.000472917 | BT2: 8.3090861e-05 | BU2: 0.0007983036 | BV2: 0.192595
A3: 2 wht | B3: 0.004981538 | C3: 7.696647 | D3: 8.5388005e-05 | E3: 1.086949 | F3: 0.3349272 | G3: 0.02131265 | H3: 0.01677269 | I3: 0.2165446 | J3: 1.859303 | K3: 0.0371097 | L3: 0.728211 | M3: 0.5647824 | N3: 0.002065253 | O3: 1.8257093e-06 | P3: 1.0732276e-05 | Q3: 3.822793e-07 | R3: 1.3650839e-08 | S3: 2.5176384e-06 | T3: 0.089045 | U3: 0.05232658 | V3: 1.124194e-05 | W3: 0.03193357 | X3: 0.0001024961 | Y3: 3.8205355e-05 | Z3: 13.7911 | AA3: 0.03976065 | AB3: 2.3663213e-05 | AC3: 4.5354849e-05 | AD3: 1.2163914e-05 | AE3: 5.0965673e-06 | AF3: 6.1376312e-14 | AG3: 4.6878409e-08 | AH3: 2.9958344e-05 | AI3: 5.5562452e-07 | AJ3: 2.3083885e-10 | AK3: 0.0001082855 | AL3: 3.1188361e-09 | AM3: 7.9251095e-07 | AN3: 3.3964503e-14 | AO3: 3.954887e-15 | AP3: 7.7042127e-15 | AQ3: 1.569809e-14 | AR3: 7.0982619e-15 | AS3: 7.6251786e-15 | AT3: 0.0003937036 | AU3: 0.0001863255 | AV3: 0 | AW3: 0.0003331606 | AX3: 0 | AY3: 5.6392582e-06 | AZ3: 6.6981494e-07 | BA3: 5.1141342e-06 | BB3: 0 | BC3: 4.0850065e-07 | BD3: 4.5658858e-06 | BE3: 0.0003173955 | BF3: 0.1769312 | BG3: 0.009006065 | BH3: 2.754737e-05 | BI3: 3.5263092e-06 | BJ3: 3.8766711e-06 | BK3: 0.000338451 | BL3: 7.421474e-06 | BM3: 0.06877907 | BN3: 4.4506999e-07 | BO3: 0.2245141 | BP3: 0.0006308479 | BQ3: 0.001202314 | BR3: 0.02310848 | BS3: 8.3709747e-05 | BT3: 3.2492608e-05 | BU3: 0.2632055 | BV3: 27.34337
A4: 3 gro | B4: 0.000696376 | C4: 0.0007751722 | D4: 0.0003430803 | E4: 0.1486935 | F4: 0.04582307 | G4: 0.002918806 | H4: 0.002295504 | I4: 0.02956285 | J4: 0.1015368 | K4: 0.001547162 | L4: 0.02157188 | M4: 0.01755753 | N4: 0.0003136716 | O4: 1.0333042e-05 | P4: 3.7250306e-06 | Q4: 3.0597369e-07 | R4: 3.0555789e-08 | S4: 3.8477856e-06 | T4: 0.01282611 | U4: 0.007658679 | V4: 1.8742918e-05 | W4: 0.004468494 | X4: 5.4501659e-05 | Y4: 3.6230665e-06 | Z4: 0.02119019 | AA4: 0.003098858 | AB4: 2.5896976e-05 | AC4: 4.6454072e-05 | AD4: 2.3140474e-05 | AE4: 2.3735449e-05 | AF4: 1.1657785e-13 | AG4: 3.1034915e-08 | AH4: 4.1464982e-06 | AI4: 7.8188648e-08 | AJ4: 3.8180831e-10 | AK4: 1.544376e-05 | AL4: 2.740298e-09 | AM4: 4.8122808e-07 | AN4: 2.1494469e-14 | AO4: 9.2437265e-15 | AP4: 1.7646151e-14 | AQ4: 2.9068622e-14 | AR4: 2.8887688e-15 | AS4: 1.4991287e-14 | AT4: 9.0513029e-05 | AU4: 5.3267111e-05 | AV4: 0 | AW4: 9.5244643e-05 | AX4: 0 | AY4: 1.6121628e-06 | AZ4: 1.9148808e-07 | BA4: 1.4620393e-06 | BB4: 0 | BC4: 1.1678301e-07 | BD4: 2.9096454e-05 | BE4: 0.0001206451 | BF4: 0.02436353 | BG4: 0.004875917 | BH4: 1.879714e-05 | BI4: 4.0747414e-06 | BJ4: 1.1308109e-05 | BK4: 9.7130069e-05 | BL4: 2.5130174e-05 | BM4: 0.009404795 | BN4: 4.2647466e-07 | BO4: 0.03682797 | BP4: 0.0001458812 | BQ4: 0.0002105265 | BR4: 0.002868032 | BS4: 6.848573e-05 | BT4: 0.0001323498 | BU4: 0.02970495 | BV4: 0.5322637
A5: 4 v_f | B5: 3.034746e-06 | C5: 0.0001631736 | D5: 7.2493449e-06 | E5: 2.090952 | F5: 7.6585195e-05 | G5: 6.1889732e-06 | H5: 2.3261524e-05 | I5: 0.0001539219 | J5: 0.04980156 | K5: 0.001255229 | L5: 0.02479799 | M5: 0.02275665 | N5: 0.0002987086 | O5: 7.5398384e-06 | P5: 0.07058766 | Q5: 0.03266142 | R5: 0.0002843634 | S5: 0.1860365 | T5: 0.02305025 | U5: 0.01310957 | V5: 0.004358383 | W5: 0.008308399 | X5: 0.0005808008 | Y5: 0.000158054 | Z5: 2.813468 | AA5: 0.02293018 | AB5: 0.0007425266 | AC5: 0.0008906677 | AD5: 0.000279818 | AE5: 6.4125641e-05 | AF5: 3.4942044e-13 | AG5: 0.001026103 | AH5: 4.8473555e-07 | AI5: 1.5541212e-06 | AJ5: 1.4807963e-08 | AK5: 0.0009364705 | AL5: 6.7383924e-05 | AM5: 0.05729594 | AN5: 9.9726356e-12 | AO5: 7.1867078e-13 | AP5: 5.3349161e-14 | AQ5: 1.1775589e-13 | AR5: 1.0584291e-13 | AS5: 2.151054e-13 | AT5: 0.0008568395 | AU5: 0.001877347 | AV5: 0 | AW5: 0.003356804 | AX5: 0 | AY5: 5.6819095e-05 | AZ5: 6.7488095e-06 | BA5: 5.1528139e-05 | BB5: 0 | BC5: 4.1159024e-06 | BD5: 0.006590255 | BE5: 0.004713135 | BF5: 0.04284794 | BG5: 5.220141 | BH5: 0.009356269 | BI5: 0.001118095 | BJ5: 0.0007185877 | BK5: 0.003659685 | BL5: 0.009023354 | BM5: 0.0001281424 | BN5: 4.9030532e-06 | BO5: 0.0003334809 | BP5: 0.08113676 | BQ5: 0.05039064 | BR5: 0.04303749 | BS5: 0.3825928 | BT5: 0.1535444 | BU5: 0.0003411332 | BV5: 11.44303
A6: 5 osd | B6: 1.229829e-06 | C6: 8.9399939e-05 | D6: 5.9467698e-06 | E6: 0.0003439272 | F6: 0.02826308 | G6: 1.8637297e-06 | H6: 2.0988107e-05 | I6: 6.4720116e-05 | J6: 0.001748615 | K6: 2.0758904e-05 | L6: 0.0005382215 | M6: 0.000298993 | N6: 4.9450999e-05 | O6: 9.4480623e-07 | P6: 1.1644098e-06 | Q6: 0.000195274 | R6: 1.1138453e-07 | S6: 4.4365817e-07 | T6: 0.0002252358 | U6: 0.0001351697 | V6: 0.001980868 | W6: 9.8273784e-05 | X6: 0.000945164 | Y6: 0.0002472274 | Z6: 0.03394487 | AA6: 0.0001595556 | AB6: 0.0001159944 | AC6: 2.415042e-05 | AD6: 6.5545341e-06 | AE6: 1.8768295e-06 | AF6: 4.2616227e-15 | AG6: 8.0304892e-09 | AH6: 2.9988303e-08 | AI6: 2.3481286e-09 | AJ6: 5.0303657e-11 | AK6: 8.5320278e-07 | AL6: 6.6874212e-10 | AM6: 9.3218723e-08 | AN6: 6.1261857e-15 | AO6: 9.2678226e-16 | AP6: 1.3091748e-15 | AQ6: 3.1408632e-15 | AR6: 8.3082201e-15 | AS6: 2.2024019e-14 | AT6: 1.8066469e-06 | AU6: 0.0006381511 | AV6: 0 | AW6: 0.001141051 | AX6: 0 | AY6: 1.9314048e-05 | AZ6: 2.2940674e-06 | BA6: 1.7515536e-05 | BB6: 0 | BC6: 1.3990849e-06 | BD6: 2.7091223e-06 | BE6: 3.0017234e-05 | BF6: 0.0008556191 | BG6: 0.002669551 | BH6: 2.3490675e-06 | BI6: 4.3556881e-07 | BJ6: 1.4944517e-07 | BK6: 4.9140584e-05 | BL6: 1.128054e-06 | BM6: 1.0940537e-07 | BN6: 5.6801146e-09 | BO6: 4.8938205e-06 | BP6: 1.9968391e-05 | BQ6: 2.4897587e-05 | BR6: 0.001250409 | BS6: 1.4582206e-05 | BT6: 9.1726697e-06 | BU6: 2.8012657e-06 | BV6: 0.07629053
A7: 6 c_b | B7: 0.0001332358 | C7: 4.3474454e-05 | D7: 1.5094032e-06 | E7: 0.137945 | F7: 0.03966043 | G7: 0.002328348 | H7: 0.001526826 | I7: 0.01972294 | J7: 0.8246642 | K7: 0.01608746 | L7: 0.3158405 | M7: 0.2518343 | N7: 0.08723251 | O7: 8.9842068e-08 | P7: 7.7618206e-05 | Q7: 3.9798765e-06 | R7: 5.2851465e-06 | S7: 1.354268e-06 | T7: 0.002447473 | U7: 0.001948694 | V7: 1.2640725e-05 | W7: 0.005135519 | X7: 0.0002530615 | Y7: 0.0003651322 | Z7: 0.0096715 | AA7: 0.06203536 | AB7: 0.0002633035 | AC7: 0.0007388081 | AD7: 4.4855184e-05 | AE7: 3.5325118e-06 | AF7: 2.0390578e-14 | AG7: 5.0132769e-09 | AH7: 1.5688187e-05 | AI7: 2.7016609e-08 | AJ7: 1.6111736e-07 | AK7: 7.8690408e-07 | AL7: 3.2486827e-07 | AM7: 8.9952216e-08 | AN7: 6.0687414e-12 | AO7: 2.953246e-15 | AP7: 1.3974193e-15 | AQ7: 4.1460594e-15 | AR7: 6.7836412e-16 | AS7: 2.9865951e-14 | AT7: 5.3315566e-06 | AU7: 0.006585403 | AV7: 0 | AW7: 0.01177508 | AX7: 0 | AY7: 0.0001993114 | AZ7: 2.3673634e-05 | BA7: 0.0001807516 | BB7: 0 | BC7: 1.4437861e-05 | BD7: 0.001118777 | BE7: 6.2425352e-05 | BF7: 0.0005895129 | BG7: 0.02658363 | BH7: 1.6405829e-05 | BI7: 2.9928478e-06 | BJ7: 8.6134094e-07 | BK7: 0.0001088603 | BL7: 0.0001566521 | BM7: 7.0717334e-07 | BN7: 1.5695138e-08 | BO7: 1.0329241e-05 | BP7: 0.001600364 | BQ7: 0.0003170303 | BR7: 0.002485543 | BS7: 3.8838833e-05 | BT7: 6.938506e-06 | BU7: 9.4239977e-06 | BV7: 1.831939
A8: 7 pfb | B8: 9.6524549e-05 | C8: 0.0001623172 | D8: 6.3086864e-06 | E8: 0.09904256 | F8: 0.02839494 | G8: 0.001392007 | H8: 0.00111517 | I8: 0.01413459 | J8: 0.5926112 | K8: 0.01152151 | L8: 0.2258984 | M8: 0.182651 | N8: 0.06251159 | O8: 2.2341271e-06 | P8: 5.3753458e-05 | Q8: 1.9801685e-06 | R8: 5.6052922e-06 | S8: 6.0978402e-07 | T8: 2.6434353e-05 | U8: 2.0444484e-05 | V8: 1.3235284e-05 | W8: 0.003057759 | X8: 0.0001808664 | Y8: 4.5852055e-05 | Z8: 0.005545742 | AA8: 0.04183614 | AB8: 0.06732963 | AC8: 0.002886639 | AD8: 4.888207e-05 | AE8: 8.7915732e-06 | AF8: 3.4041065e-14 | AG8: 8.3106197e-09 | AH8: 1.1120698e-05 | AI8: 1.4607275e-08 | AJ8: 1.15896e-07 | AK8: 1.6194111e-06 | AL8: 2.3280747e-07 | AM8: 1.449304e-07 | AN8: 4.3497211e-12 | AO8: 1.6470181e-14 | AP8: 2.6259023e-14 | AQ8: 4.3221696e-14 | AR8: 1.3673967e-15 | AS8: 1.5103141e-15 | AT8: 1.6989385e-05 | AU8: 0.0009072053 | AV8: 0 | AW8: 0.001622135 | AX8: 0 | AY8: 2.7457141e-05 | AZ8: 3.2612807e-06 | BA8: 2.4900351e-05 | BB8: 0 | BC8: 1.9889601e-06 | BD8: 0.0005096817 | BE8: 8.6411899e-05 | BF8: 9.6492462e-05 | BG8: 0.01800522 | BH8: 1.1624428e-05 | BI8: 1.0765891e-06 | BJ8: 7.4584977e-07 | BK8: 3.302153e-05 | BL8: 0.0001113118 | BM8: 3.3606182e-06 | BN8: 1.3741226e-07 | BO8: 3.8127014e-06 | BP8: 0.001137791 | BQ8: 0.000210831 | BR8: 0.0008075677 | BS8: 2.1019603e-05 | BT8: 4.0920527e-06 | BU8: 4.3026898e-06 | BV8: 1.364268
A9: 8 ocr | B9: 0.001027672 | C9: 0.0003338933 | D9: 1.4366597e-05 | E9: 1.05853 | F9: 0.3042846 | G9: 0.01492054 | H9: 0.01172064 | I9: 0.1573037 | J9: 6.370244 | K9: 0.1239882 | L9: 2.457197 | M9: 1.942333 | N9: 0.6697353 | O9: 2.0343982e-06 | P9: 0.0005789308 | Q9: 2.1525066e-05 | R9: 3.132084e-05 | S9: 2.2853726e-05 | T9: 0.0006019162 | U9: 0.0004664689 | V9: 2.8333749e-05 | W9: 0.03266327 | X9: 0.001937544 | Y9: 0.0004917755 | Z9: 0.06158848 | AA9: 0.4538071 | AB9: 0.002590363 | AC9: 0.005790363 | AD9: 0.0003941877 | AE9: 5.6574794e-05 | AF9: 1.5576273e-12 | AG9: 5.6831402e-07 | AH9: 0.0001193445 | AI9: 1.8993136e-07 | AJ9: 1.3036051e-06 | AK9: 1.9925143e-05 | AL9: 2.5909308e-06 | AM9: 3.705093e-05 | AN9: 4.6789326e-11 | AO9: 1.5798415e-13 | AP9: 1.7019293e-13 | AQ9: 4.0873999e-13 | AR9: 1.7454343e-13 | AS9: 1.2542643e-12 | AT9: 0.000212201 | AU9: 0.01777767 | AV9: 0 | AW9: 0.03178749 | AX9: 0 | AY9: 0.0005380524 | AZ9: 6.3908323e-05 | BA9: 0.0004879493 | BB9: 0 | BC9: 3.8975828e-05 | BD9: 0.006354273 | BE9: 0.006749115 | BF9: 0.00162281 | BG9: 0.1985169 | BH9: 0.002696034 | BI9: 1.3238478e-05 | BJ9: 3.7879231e-06 | BK9: 0.0002266892 | BL9: 0.001212027 | BM9: 4.0525974e-05 | BN9: 8.1307053e-06 | BO9: 2.5868954e-05 | BP9: 0.01218354 | BQ9: 0.002361736 | BR9: 0.005347357 | BS9: 0.0002047574 | BT9: 0.000924726 | BU9: 3.8679693e-05 | BV9: 13.96232
A10: 9 ctl | B10: 0.0001042754 | C10: 0.0004474736 | D10: 9.5765172e-05 | E10: 0.008876203 | F10: 0.00867605 | G10: 0.0002594347 | H10: 0.0001512385 | I10: 0.01512577 | J10: 4.319543 | K10: 0.0005247705 | L10: 0.008987948 | M10: 0.007119433 | N10: 0.0001555928 | O10: 7.0181384e-05 | P10: 8.9547837e-05 | Q10: 3.6483366e-06 | R10: 6.6514272e-05 | S10: 1.1797709e-05 | T10: 281.7186 | U10: 0.4761484 | V10: 0.01298172 | W10: 0.003238321 | X10: 0.03134134 | Y10: 0.007953695 | Z10: 0.9430505 | AA10: 0.0009796183 | AB10: 0.0005003882 | AC10: 0.000795587 | AD10: 0.00535099 | AE10: 1.4398886e-05 | AF10: 5.1540315e-13 | AG10: 2.0391795e-07 | AH10: 1.586553e-06 | AI10: 1.8594388e-08 | AJ10: 4.7046651e-08 | AK10: 1.4928266e-05 | AL10: 2.2265624e-08 | AM10: 2.7858289e-06 | AN10: 3.0099062e-13 | AO10: 9.5124924e-14 | AP10: 7.2095087e-14 | AQ10: 1.3149555e-13 | AR10: 6.334689e-14 | AS10: 2.4910954e-13 | AT10: 8.2382707e-05 | AU10: 0.01732199 | AV10: 0 | AW10: 0.03097272 | AX10: 0 | AY10: 0.0005242611 | AZ10: 6.2270236e-05 | BA10: 0.0004754423 | BB10: 0 | BC10: 3.7976806e-05 | BD10: 0.005165059 | BE10: 0.003834344 | BF10: 0.002375095 | BG10: 0.1093919 | BH10: 0.0001876896 | BI10: 7.8332523e-05 | BJ10: 3.137442e-05 | BK10: 0.003684829 | BL10: 0.0009329614 | BM10: 4.0961459e-05 | BN10: 1.4331081e-06 | BO10: 7.7901801e-05 | BP10: 0.01021749 | BQ10: 0.001667999 | BR10: 0.08957508 | BS10: 0.0009306577 | BT10: 0.0002503911 | BU10: 0.0004265461 | BV10: 287.8497
A11: 10 oap | B11: 2.4495182e-06 | C11: 0.0001794889 | D11: 7.7157001e-06 | E11: 0.0009034011 | F11: 0.0004881464 | G11: 1.7851276e-05 | H11: 1.8114e-05 | I11: 0.0002221706 | J11: 0.05873449 | K11: 0.001698686 | L11: 0.02286722 | M11: 0.01871471 | N11: 0.000112717 | O11: 4.2910611e-05 | P11: 0.008307176 | Q11: 2.4138324e-06 | R11: 4.491705e-07 | S11: 0.003804625 | T11: 0.1130518 | U11: 0.3010068 | V11: 4.6731125e-06 | W11: 0.001021916 | X11: 0.007760528 | Y11: 0.001967333 | Z11: 0.234487 | AA11: 0.0006737466 | AB11: 0.01584036 | AC11: 0.5804361 | AD11: 0.909247 | AE11: 7.3011702e-06 | AF11: 2.6112635e-13 | AG11: 1.3145517e-07 | AH11: 2.0023983e-06 | AI11: 1.8666061e-08 | AJ11: 3.3188336e-08 | AK11: 1.6068963e-05 | AL11: 1.3317594e-06 | AM11: 0.001164059 | AN11: 1.8840655e-13 | AO11: 4.2661824e-14 | AP11: 1.8885892e-14 | AQ11: 3.6908356e-14 | AR11: 3.2644738e-14 | AS11: 9.5677494e-14 | AT11: 0.001626499 | AU11: 0.0004261145 | AV11: 0 | AW11: 0.0007619172 | AX11: 0 | AY11: 1.2896626e-05 | AZ11: 1.5318243e-06 | BA11: 1.16957e-05 | BB11: 0 | BC11: 9.3421505e-07 | BD11: 0.001250534 | BE11: 0.002991713 | BF11: 0.004175013 | BG11: 1.688444 | BH11: 0.0002707708 | BI11: 0.0004230231 | BJ11: 5.2940236e-06 | BK11: 0.001613194 | BL11: 3.036879e-05 | BM11: 2.6793712e-05 | BN11: 1.0315006e-06 | BO11: 0.0001237733 | BP11: 0.0008100279 | BQ11: 0.004843482 | BR11: 0.03994257 | BS11: 0.0004792355 | BT11: 0.0003497826 | BU11: 0.0001355306 | BV11: 4.03157
A12: 11 rmk | B12: 6.1782025e-06 | C12: 0.000528697 | D12: 2.9058905e-05 | E12: 0.002555483 | F12: 0.002179207 | G12: 6.9495698e-05 | H12: 6.8563771e-05 | I12: 0.0005850986 | J12: 0.01743519 | K12: 3.880959e-05 | L12: 0.9292678 | M12: 0.0004152606 | N12: 0.000181002 | O12: 1.3730384e-05 | P12: 0.0005208335 | Q12: 1.1515889e-05 | R12: 0.003217884 | S12: 6.8748508e-05 | T12: 0.01409639 | U12: 0.007023936 | V12: 4.1886993e-05 | W12: 62.38657 | X12: 0.0004549951 | Y12: 0.000115053 | Z12: 0.0184448 | AA12: 0.3160996 | AB12: 0.0006415895 | AC12: 0.001207901 | AD12: 0.001566815 | AE12: 7.9396479e-05 | AF12: 4.7137468e-13 | AG12: 7.3591417e-07 | AH12: 1.006412e-06 | AI12: 4.2197552e-08 | AJ12: 7.0188446e-09 | AK12: 3.7996182e-05 | AL12: 9.4589183e-08 | AM12: 2.2712964e-05 | AN12: 5.9314728e-13 | AO12: 2.5236569e-14 | AP12: 2.944191e-14 | AQ12: 8.1227498e-14 | AR12: 1.111686e-12 | AS12: 2.6309087e-12 | AT12: 4.520045e-05 | AU12: 0.8352994 | AV12: 0 | AW12: 1.493563 | AX12: 0 | AY12: 0.02528086 | AZ12: 0.003002789 | BA12: 0.02292673 | BB12: 0 | BC12: 0.001831313 | BD12: 0.364558 | BE12: 0.0005075872 | BF12: 0.002352128 | BG12: 0.5084676 | BH12: 0.0005556514 | BI12: 0.0001761634 | BJ12: 5.5717243e-05 | BK12: 0.006065198 | BL12: 0.0002581093 | BM12: 0.0002998009 | BN12: 1.7232969e-06 | BO12: 0.0006772048 | BP12: 0.003282668 | BQ12: 0.003517851 | BR12: 0.1607586 | BS12: 0.09332805 | BT12: 0.03696736 | BU12: 0.0002557932 | BV12: 67.26764
A13: 12 wol | B13: 7.1067518e-08 | C13: 1.3555657e-05 | D13: 5.2619225e-07 | E13: 4.2608746e-05 | F13: 5.1967622e-06 | G13: 1.6199765e-06 | H13: 6.4328952e-07 | I13: 1.9325056e-05 | J13: 0.4320759 | K13: 0.008415198 | L13: 0.1650708 | M13: 0.3719839 | N13: 4.0632503e-06 | O13: 3.6451829e-06 | P13: 2.2970203e-06 | Q13: 5.5288496e-08 | R13: 1.4572146e-09 | S13: 1.9525875e-07 | T13: 5.6127818e-05 | U13: 9.2320581e-05 | V13: 2.3070854e-07 | W13: 1.5713107e-05 | X13: 3.203948e-08 | Y13: 4.6752085e-08 | Z13: 3.8805556e-05 | AA13: 1.2204936e-05 | AB13: 3.857111 | AC13: 1.426018 | AD13: 0.0744368 | AE13: 0.0003232987 | AF13: 2.108502e-15 | AG13: 2.0948796e-09 | AH13: 8.0946129e-06 | AI13: 1.044518e-09 | AJ13: 3.0747717e-05 | AK13: 0.0006952303 | AL13: 2.5258681e-10 | AM13: 3.6089755e-08 | AN13: 3.1067934e-15 | AO13: 4.3113558e-15 | AP13: 4.8007905e-15 | AQ13: 7.7009652e-15 | AR13: 1.4954571e-16 | AS13: 3.2537254e-16 | AT13: 0.003846836 | AU13: 1.1544108e-05 | AV13: 0 | AW13: 2.0641526e-05 | AX13: 0 | AY13: 3.4938975e-07 | AZ13: 4.1499511e-08 | BA13: 3.1685479e-07 | BB13: 0 | BC13: 2.5309346e-08 | BD13: 9.4015755e-05 | BE13: 0.0002355884 | BF13: 5.1847561e-05 | BG13: 0.002376571 | BH13: 3.2294643e-05 | BI13: 6.6833973e-06 | BJ13: 0.002636366 | BK13: 5.1046867e-05 | BL13: 0.0004848898 | BM13: 6.9122081e-07 | BN13: 2.5546219e-08 | BO13: 0.001216841 | BP13: 2.7958209e-05 | BQ13: 0.002472161 | BR13: 0.001418861 | BS13: 2.5214196e-05 | BT13: 4.35744e-05 | BU13: 0.001680445 | BV13: 6.353213
... A74: Total | B74: 0.02123812 | C74: 12.45748 | D74: 0.3074148 | E74: 42.67514 | F74: 10.47765 | G74: 0.6164251 | H74: 0.5218507 | I74: 6.937309 | J74: 104.6996 | K74: 1.995152 | L74: 39.19263 | M74: 31.35292 | N74: 3.975908 | O74: 0.08462766 | P74: 920.3947 | Q74: 102.1719 | R74: 0.6341798 | S74: 682.2064 | T74: 318.4239 | U74: 13.04316 | V74: 0.2724119 | W74: 77.0215 | X74: 0.08566386 | Y74: 0.02187444 | Z74: 68.40991 | AA74: 73.42737 | AB74: 76.8087 | AC74: 52.96458 | AD74: 10.99061 | AE74: 22.85297 | AF74: 15.28781 | AG74: 5.991112 | AH74: 81.38931 | AI74: 14.07548 | AJ74: 26.98134 | AK74: 65.6061 | AL74: 69.24084 | AM74: 296.9747 | AN74: 27.30677 | AO74: 3.554974 | AP74: 2.928604 | AQ74: 5.619669 | AR74: 3.078635 | AS74: 5.384138 | AT74: 59.14578 | AU74: 255.816 | AV74: 0 | AW74: 735.5734 | AX74: 0 | AY74: 8.255378 | AZ74: 1.182436 | BA74: 9.555556 | BB74: 0 | BC74: 0.6028461 | BD74: 210.7586 | BE74: 839.9393 | BF74: 504.177 | BG74: 286.2186 | BH74: 175.6865 | BI74: 17.24648 | BJ74: 95.75783 | BK74: 59.64551 | BL74: 152.1477 | BM74: 139.6771 | BN74: 5.973038 | BO74: 78.22846 | BP74: 226.9231 | BQ74: 84.45512 | BR74: 221.1326 | BS74: 153.5532 | BT74: 79.02735 | BU74: 55.50568 | BV74: 7754.649
A76: VDFB | B76: 1 a_pdr | C76: 2 a_wht | D76: 3 a_gro | E76: 4 a_v_f | F76: 5 a_osd | G76: 6 a_c_b | H76: 7 a_pfb | I76: 8 a_ocr | J76: 9 a_ctl | K76: 10 a_oap | L76: 11 a_rmk | M76: 12 a_wol | N76: 13 a_frs | O76: 14 a_fsh | P76: 15 a_coa | Q76: 16 a_oil | R76: 17 a_gas | S76: 18 a_oxt | T76: 19 a_cmt | U76: 20 a_omt | V76: 21 a_vol | W76: 22 a_mil | X76: 23 a_pcr | Y76: 24 a_sgr | Z76: 25 a_ofd | AA76: 26 a_b_t | AB76: 27 a_tex | AC76: 28 a_wap | AD76: 29 a_lea | AE76: 30 a_lum | AF76: 31 a_ppp | AG76: 32 a_p_c | AH76: 33 a_chm | AI76: 34 a_bph | AJ76: 35 a_rpp | AK76: 36 a_nmm | AL76: 37 a_i_s | AM76: 38 a_nfm | AN76: 39 a_fmp | AO76: 40 a_ele | AP76: 41 a_eeq | AQ76: 42 a_ome | AR76: 43 a_mvh | AS76: 44 a_otn | AT76: 45 a_omf | AU76: 46 a_TnD | AV76: 47 a_eNuclear | AW76: 48 a_eCoal | AX76: 49 a_eGas | AY76: 50 a_eWind | AZ76: 51 a_eHydro | BA76: 52 a_eOil | BB76: 53 a_eOther | BC76: 54 a_eSolar | BD76: 55 a_wtr | BE76: 56 a_cns | BF76: 57 a_trd | BG76: 58 a_afs | BH76: 59 a_otp | BI76: 60 a_wtp | BJ76: 61 a_atp | BK76: 62 a_whs | BL76: 63 a_cmn | BM76: 64 a_ofi | BN76: 65 a_ins | BO76: 66 a_rsa | BP76: 67 a_obs | BQ76: 68 a_ros | BR76: 69 a_osg | BS76: 70 a_edu | BT76: 71 a_hht | BU76: 72 a_dwe
A77: 1 pdr | B77: =B2 -> 0.000190845 | C77: =C2 -> 0.0005288834 | D77: =D2 -> 1.3462631e-05 | E77: =E2 -> 0.01150398 | F77: =F2 -> 0.003534865 | G77: =G2 -> 0.0001880274 | H77: =H2 -> 0.0001993374 | I77: =I2 -> 0.002918084 | ... AU77: =AU2 -> 0.0001629688 | AV77: =$AV$149*'VDFB_ref(한국)'!BX2 -> 3.3802621e-07 | AW77: =AW2 -> 0.0002913975 | AX77: =$AX$149*'VDFB_ref(한국)'!BY2 -> 1.4441505e-07 | AY77: =AY2 -> 4.9323535e-06 | AZ77: =AZ2 -> 5.8585084e-07 | BA77: =BA2 -> 4.4730559e-06 | BB77: =$BB$149*'VDFB_ref(한국)'!CA2 -> 1.4711856e-07 | BC77: =BC2 -> 3.5729337e-07 | BD77: =BD2 -> 2.3145742e-05 | BE77: =BE2 -> 0.0001223473 | BF77: =BF2 -> 0.002265458 | BG77: =BG2 -> 0.03246836 | BH77: =BH2 -> 8.4775893e-05 | BI77: =BI2 -> 1.2069652e-05 | BJ77: =BJ2 -> 8.7345978e-07 | ... BU77: =BU2 -> 0.0007983036
A78: 2 wht | B78: =B3 -> 0.004981538 | C78: =C3 -> 7.696647 | D78: =D3 -> 8.5388005e-05 | E78: =E3 -> 1.086949 | F78: =F3 -> 0.3349272 | G78: =G3 -> 0.02131265 | H78: =H3 -> 0.01677269 | I78: =I3 -> 0.2165446 | ... AU78: =AU3 -> 0.0001863255 | AV78: =$AV$149*'VDFB_ref(한국)'!BX3 -> 2.5017824e-08 | AW78: =AW3 -> 0.0003331606 | AX78: =$AX$149*'VDFB_ref(한국)'!BY3 -> 1.0668215e-08 | AY78: =AY3 -> 5.6392582e-06 | AZ78: =AZ3 -> 6.6981494e-07 | BA78: =BA3 -> 5.1141342e-06 | BB78: =$BB$149*'VDFB_ref(한국)'!CA3 -> 1.0873667e-08 | BC78: =BC3 -> 4.0850065e-07 | BD78: =BD3 -> 4.5658858e-06 | BE78: =BE3 -> 0.0003173955 | BF78: =BF3 -> 0.1769312 | BG78: =BG3 -> 0.009006065 | BH78: =BH3 -> 2.754737e-05 | BI78: =BI3 -> 3.5263092e-06 | BJ78: =BJ3 -> 3.8766711e-06 | ... BU78: =BU3 -> 0.2632055
A79: 3 gro | B79: =B4 -> 0.000696376 | C79: =C4 -> 0.0007751722 | D79: =D4 -> 0.0003430803 | E79: =E4 -> 0.1486935 | F79: =F4 -> 0.04582307 | G79: =G4 -> 0.002918806 | H79: =H4 -> 0.002295504 | I79: =I4 -> 0.02956285 | ... AU79: =AU4 -> 5.3267111e-05 | AV79: =$AV$149*'VDFB_ref(한국)'!BX4 -> 1.0090903e-08 | AW79: =AW4 -> 9.5244643e-05 | AX79: =$AX$149*'VDFB_ref(한국)'!BY4 -> 4.3093283e-09 | AY79: =AY4 -> 1.6121628e-06 | AZ79: =AZ4 -> 1.9148808e-07 | BA79: =BA4 -> 1.4620393e-06 | BB79: =$BB$149*'VDFB_ref(한국)'!CA4 -> 4.3926735e-09 | BC79: =BC4 -> 1.1678301e-07 | BD79: =BD4 -> 2.9096454e-05 | BE79: =BE4 -> 0.0001206451 | BF79: =BF4 -> 0.02436353 | BG79: =BG4 -> 0.004875917 | BH79: =BH4 -> 1.879714e-05 | BI79: =BI4 -> 4.0747414e-06 | BJ79: =BJ4 -> 1.1308109e-05 | ... BU79: =BU4 -> 0.02970495
