Workbook

Sheet CGE_Frozen
B1: Frozen | C1: Frozen | D1: Frozen | E1: Frozen | F1: Frozen | G1: Frozen | H1: Frozen | I1: Frozen | J1: Frozen | K1: Frozen | L1: Frozen | M1: Frozen | N1: Frozen | O1: Frozen | P1: Frozen | Q1: Frozen | R1: Frozen
B2: 01_KOR | C2: 02_CHN | D2: 03_JPN | E2: 04_RUS | F2: 05_MNG | G2: 06_PRK | H2: 07_NAM | I2: 08_LAM | J2: 09_WEU | K2: 10_EEU | L2: 11_RFSU | M2: 12_MEA | N2: 13_AFR | O2: 14_RCPA | P2: 15_SAS | Q2: 16_RPAS | R2: 17_RPAO
A3: 2019 | B3: 1649.34 | C3: 14643 | D3: 5115.17 | E3: 1690.44 | F3: 14.161 | G3: 16.0363 | H3: 23243.9 | I3: 5369.37 | J3: 18893.2 | K3: 1774.9 | L3: 610.966 | M3: 3517.49 | N3: 1794.02 | O3: 380.752 | P3: 3658.47 | Q3: 3429.91 | R3: 1607.7
A4: 2020 | B4: 1638.79 | C4: 15017.2 | D4: 4921.99 | E4: 1642.65 | F4: 13.5975 | G4: 15.433 | H4: 22689.2 | I4: 5041.57 | J4: 17906.8 | K4: 1718.48 | L4: 597.998 | M4: 3421.18 | N4: 1742.29 | O4: 377.893 | P4: 3517.61 | Q4: 3276.68 | R4: 1595.68
A5: 2021 | B5: 1720.41 | C5: 16306.4 | D5: 5070.65 | E5: 1735.6 | F5: 14.1899 | G5: 15.6426 | H5: 24077.8 | I5: 5406.67 | J5: 19180.6 | K5: 1836.19 | L5: 621.996 | M5: 3567.62 | N5: 1808.5 | O5: 394.158 | P5: 3833.46 | Q5: 3407.19 | R5: 1643.18
A6: 2022 | B6: 1772.2 | C6: 16858.4 | D6: 5139.14 | E6: 1715.32 | F6: 14.6019 | G6: 15.6356 | H6: 24740.5 | I6: 5633.88 | J6: 19963.4 | K6: 1910.54 | L6: 594.19 | M6: 3800.41 | N6: 1887.96 | O6: 410.957 | P6: 4097.67 | Q6: 3576.53 | R6: 1702.95
A7: 2023 | B7: 1811.48 | C7: 17767.5 | D7: 5232.68 | E7: 1773.48 | F7: 15.6261 | G7: 16.1638 | H7: 25440.9 | I7: 5762.21 | J7: 20234.3 | K7: 1938.74 | L7: 618.905 | M7: 3822.19 | N7: 1949.9 | O7: 427.278 | P7: 4416.22 | Q7: 3733.56 | R7: 1762.3
A8: 2024 | B8: 1846.93 | C8: 18608.6 | D8: 5248.03 | E8: 1853.78 | F8: 16.2624 | G8: 16.7234 | H8: 26124.8 | I8: 5906.93 | J8: 20525.3 | K8: 1978.27 | L8: 632.958 | M8: 3924.03 | N8: 2037.58 | O8: 446.476 | P8: 4655.15 | Q8: 3886.44 | R8: 1787.56 | S8: 01_KOR | T8: 02_CHN | U8: 03_JPN | V8: 04_RUS | W8: 05_MNG | X8: 06_PRK | Y8: 07_NAM | Z8: 08_LAM | AA8: 09_WEU | AB8: 10_EEU | AC8: 11_RFSU | AD8: 12_MEA | AE8: 13_AFR | AF8: 14_RCPA | AG8: 15_SAS | AH8: 16_RPAS | AI8: 17_RPAO
A9: 2025 | B9: 1901.56 | C9: 19472.9 | D9: 5342.34 | E9: 1872.04 | F9: 16.9186 | G9: 17.4908 | H9: 26806.4 | I9: 6104.74 | J9: 21145.3 | K9: 2046.18 | L9: 641.033 | M9: 4023.35 | N9: 2114.36 | O9: 467.738 | P9: 4960.02 | Q9: 4057.61 | R9: 1841.45 | S9: =(B9-B8)/B8 -> 0.029578815 | T9: =(C9-C8)/C8 -> 0.046446267 | U9: =(D9-D8)/D8 -> 0.017970553 | V9: =(E9-E8)/E8 -> 0.009850144 | W9: =(F9-F8)/F8 -> 0.040350748 | X9: =(G9-G8)/G8 -> 0.045887798 | Y9: =(H9-H8)/H8 -> 0.026090152 | Z9: =(I9-I8)/I8 -> 0.033487785 | ... AI9: =(R9-R8)/R8 -> 0.03014724
A10: 2026 | B10: 1944.92 | C10: 20266 | D10: 5404.59 | E10: 1903.42 | F10: 17.4337 | G10: 18.2815 | H10: 27390.7 | I10: 6280.2 | J10: 21614.2 | K10: 2104.73 | L10: 659.045 | M10: 4194.52 | N10: 2208.28 | O10: 491.255 | P10: 5241.93 | Q10: 4217.19 | R10: 1888.73 | S10: =(B10-B9)/B9 -> 0.022802331 | T10: =(C10-C9)/C9 -> 0.040728397 | U10: =(D10-D9)/D9 -> 0.011652197 | V10: =(E10-E9)/E9 -> 0.016762462 | W10: =(F10-F9)/F9 -> 0.030445782 | X10: =(G10-G9)/G9 -> 0.045206623 | Y10: =(H10-H9)/H9 -> 0.021797034 | Z10: =(I10-I9)/I9 -> 0.028741601 | ... AI10: =(R10-R9)/R9 -> 0.025675419
A11: 2027 | B11: 1996.8 | C11: 21085.8 | D11: 5471.3 | E11: 1921.76 | F11: 18.0587 | G11: 19.1834 | H11: 27962 | I11: 6431.18 | J11: 22082.9 | K11: 2169.42 | L11: 677.824 | M11: 4305.47 | N11: 2292.44 | O11: 516.358 | P11: 5568.14 | Q11: 4395.01 | R11: 1940.13 | S11: =(B11-B10)/B10 -> 0.026674619 | T11: =(C11-C10)/C10 -> 0.040451989 | U11: =(D11-D10)/D10 -> 0.012343212 | V11: =(E11-E10)/E10 -> 0.0096352881 | W11: =(F11-F10)/F10 -> 0.035850106 | X11: =(G11-G10)/G10 -> 0.049334026 | Y11: =(H11-H10)/H10 -> 0.020857444 | Z11: =(I11-I10)/I10 -> 0.024040636 | ... AI11: =(R11-R10)/R10 -> 0.027214054
A12: 2028 | B12: 2035.58 | C12: 21841.4 | D12: 5521.69 | E12: 1958.17 | F12: 18.6171 | G12: 20.1276 | H12: 28496.7 | I12: 6599.77 | J12: 22490.9 | K12: 2225.63 | L12: 706.428 | M12: 4510.17 | N12: 2402.23 | O12: 543.71 | P12: 5869.25 | Q12: 4562.04 | R12: 1989.35 | S12: =(B12-B11)/B11 -> 0.019421074 | T12: =(C12-C11)/C11 -> 0.035834543 | U12: =(D12-D11)/D11 -> 0.009209877 | V12: =(E12-E11)/E11 -> 0.018946174 | W12: =(F12-F11)/F11 -> 0.030921384 | X12: =(G12-G11)/G11 -> 0.049219638 | Y12: =(H12-H11)/H11 -> 0.01912238 | Z12: =(I12-I11)/I11 -> 0.026214474 | ... AI12: =(R12-R11)/R11 -> 0.025369434
A13: 2029 | B13: 2083.55 | C13: 22632.7 | D13: 5584.79 | E13: 1979.55 | F13: 19.2736 | G13: 21.1555 | H13: 29039.1 | I13: 6755.58 | J13: 22936.3 | K13: 2288.04 | L13: 730.174 | M13: 4635.24 | N13: 2499.69 | O13: 570.896 | P13: 6213.99 | Q13: 4744.31 | R13: 2041.99 | S13: =(B13-B12)/B12 -> 0.023565765 | T13: =(C13-C12)/C12 -> 0.036229363 | U13: =(D13-D12)/D12 -> 0.011427661 | V13: =(E13-E12)/E12 -> 0.010918357 | W13: =(F13-F12)/F12 -> 0.035263279 | X13: =(G13-G12)/G12 -> 0.051069179 | Y13: =(H13-H12)/H12 -> 0.019033783 | Z13: =(I13-I12)/I12 -> 0.023608398 | ... AI13: =(R13-R12)/R12 -> 0.026460904
A14: 2030 | B14: 2122.5 | C14: 23373.3 | D14: 5642.53 | E14: 2013.82 | F14: 19.8605 | G14: 22.2035 | H14: 29566.5 | I14: 6934.9 | J14: 23365.8 | K14: 2343.28 | L14: 756.936 | M14: 4818.22 | N14: 2617.01 | O14: 598.085 | P14: 6535.51 | Q14: 4914.65 | R14: 2092.44 | S14: =(B14-B13)/B13 -> 0.018694056 | T14: =(C14-C13)/C13 -> 0.032722565 | U14: =(D14-D13)/D13 -> 0.010338795 | V14: =(E14-E13)/E13 -> 0.017312015 | W14: =(F14-F13)/F13 -> 0.03045098 | X14: =(G14-G13)/G13 -> 0.049537945 | Y14: =(H14-H13)/H13 -> 0.01816172 | Z14: =(I14-I13)/I13 -> 0.026543983 | ... AI14: =(R14-R13)/R13 -> 0.024706291
A15: 2031 | B15: 2164.2 | C15: 24130.5 | D15: 5709.7 | E15: 2043.64 | F15: 20.5329 | G15: 23.3227 | H15: 30099.2 | I15: 7119.62 | J15: 23826.4 | K15: 2400.05 | L15: 779.96 | M15: 4958.91 | N15: 2734.14 | O15: 624.855 | P15: 6880.79 | Q15: 5091.11 | R15: 2145.13 | S15: =(B15-B14)/B14 -> 0.019646643 | T15: =(C15-C14)/C14 -> 0.032395939 | U15: =(D15-D14)/D14 -> 0.011904234 | V15: =(E15-E14)/E14 -> 0.014807679 | W15: =(F15-F14)/F14 -> 0.033856147 | X15: =(G15-G14)/G14 -> 0.050406467 | Y15: =(H15-H14)/H14 -> 0.018017012 | Z15: =(I15-I14)/I14 -> 0.026636289 | ... AI15: =(R15-R14)/R14 -> 0.025181128
A16: 2032 | B16: 2197.78 | C16: 24850.9 | D16: 5772.03 | E16: 2086.37 | F16: 21.1959 | G16: 24.4954 | H16: 30615 | I16: 7326.75 | J16: 24266.2 | K16: 2451.01 | L16: 807.573 | M16: 5158.98 | N16: 2875.4 | O16: 652.792 | P16: 7205.58 | Q16: 5259.73 | R16: 2197.41 | S16: =(B16-B15)/B15 -> 0.015516126 | T16: =(C16-C15)/C15 -> 0.029854334 | U16: =(D16-D15)/D15 -> 0.01091651 | V16: =(E16-E15)/E15 -> 0.020908771 | W16: =(F16-F15)/F15 -> 0.032289642 | X16: =(G16-G15)/G15 -> 0.050281485 | Y16: =(H16-H15)/H15 -> 0.017136668 | Z16: =(I16-I15)/I15 -> 0.029092845 | ... AI16: =(R16-R15)/R15 -> 0.024371483
A17: 2033 | B17: 2237.55 | C17: 25591.1 | D17: 5843.18 | E17: 2119.66 | F17: 21.9174 | G17: 25.7584 | H17: 31135.6 | I17: 7530.19 | J17: 24735.7 | K17: 2506.05 | L17: 831.206 | M17: 5297.83 | N17: 3010.32 | O17: 680.093 | P17: 7567.37 | Q17: 5438.3 | R17: 2251.43 | S17: =(B17-B16)/B16 -> 0.018095533 | T17: =(C17-C16)/C16 -> 0.029785642 | U17: =(D17-D16)/D16 -> 0.012326686 | V17: =(E17-E16)/E16 -> 0.015955943 | W17: =(F17-F16)/F16 -> 0.034039602 | X17: =(G17-G16)/G16 -> 0.051560701 | Y17: =(H17-H16)/H16 -> 0.017004736 | Z17: =(I17-I16)/I16 -> 0.027766745 | ... AI17: =(R17-R16)/R16 -> 0.024583487
A18: 2034 | B18: 2267.76 | C18: 26267.2 | D18: 5905.01 | E18: 2165.37 | F18: 22.6015 | G18: 27.0576 | H18: 31640.8 | I18: 7754.67 | J18: 25180.4 | K18: 2554.2 | L18: 859.551 | M18: 5507.32 | N18: 3167.78 | O18: 707.875 | P18: 7902.7 | Q18: 5605.12 | R18: 2304.78 | S18: =(B18-B17)/B17 -> 0.013501374 | T18: =(C18-C17)/C17 -> 0.026419341 | U18: =(D18-D17)/D17 -> 0.010581567 | V18: =(E18-E17)/E17 -> 0.021564779 | W18: =(F18-F17)/F17 -> 0.031212644 | X18: =(G18-G17)/G17 -> 0.050437915 | Y18: =(H18-H17)/H17 -> 0.016225799 | Z18: =(I18-I17)/I17 -> 0.029810669 | ... AI18: =(R18-R17)/R17 -> 0.023696051
A19: 2035 | B19: 2303.57 | C19: 26942.5 | D19: 5972.07 | E19: 2199.22 | F19: 23.3272 | G19: 28.4414 | H19: 32154.8 | I19: 7971.45 | J19: 25655.6 | K19: 2606.26 | L19: 883.223 | M19: 5653.78 | N19: 3313.15 | O19: 734.174 | P19: 8276.57 | Q19: 5780.21 | R19: 2359.75 | S19: =(B19-B18)/B18 -> 0.015790913 | T19: =(C19-C18)/C18 -> 0.025708869 | U19: =(D19-D18)/D18 -> 0.011356458 | V19: =(E19-E18)/E18 -> 0.015632432 | W19: =(F19-F18)/F18 -> 0.032108488 | X19: =(G19-G18)/G18 -> 0.051142747 | Y19: =(H19-H18)/H18 -> 0.016244848 | Z19: =(I19-I18)/I18 -> 0.027954768 | ... AI19: =(R19-R18)/R18 -> 0.023850433
A20: 2036 | B20: 2330.97 | C20: 27542.4 | D20: 6028.65 | E20: 2243.04 | F20: 24.0091 | G20: 29.8717 | H20: 32655.1 | I20: 8207.27 | J20: 26109.8 | K20: 2652.22 | L20: 910.856 | M20: 5866.22 | N20: 3478.35 | O20: 760.461 | P20: 8625.64 | Q20: 5943.39 | R20: 2414.11 | S20: =(B20-B19)/B19 -> 0.011894581 | T20: =(C20-C19)/C19 -> 0.022265937 | U20: =(D20-D19)/D19 -> 0.0094741019 | V20: =(E20-E19)/E19 -> 0.019925246 | W20: =(F20-F19)/F19 -> 0.02923197 | X20: =(G20-G19)/G19 -> 0.050289367 | Y20: =(H20-H19)/H19 -> 0.015559108 | Z20: =(I20-I19)/I19 -> 0.029583075 | ... AI20: =(R20-R19)/R19 -> 0.023036339
... A34: 2050 | B34: 2649.92 | C34: 35122.3 | D34: 6870.76 | E34: 2811.9 | F34: 35.3361 | G34: 57.6935 | H34: 39565.2 | I34: 12164.8 | J34: 32892.4 | K34: 3196.52 | L34: 1274.73 | M34: 8785.08 | N34: 6553.17 | O34: 1092.08 | P34: 14417 | Q34: 8189.45 | R34: 3254.25 | S34: =(B34-B33)/B33 -> 0.0062426903 | T34: =(C34-C33)/C33 -> 0.014353666 | U34: =(D34-D33)/D33 -> 0.0092778659 | V34: =(E34-E33)/E33 -> 0.015434283 | W34: =(F34-F33)/F33 -> 0.026776426 | X34: =(G34-G33)/G33 -> 0.044110967 | Y34: =(H34-H33)/H33 -> 0.012534741 | Z34: =(I34-I33)/I33 -> 0.0274064 | ... AI34: =(R34-R33)/R33 -> 0.019875706
B36: Frozen | C36: Frozen | D36: Frozen | E36: Frozen | F36: Frozen | G36: Frozen | H36: Frozen | I36: Frozen | J36: Frozen | K36: Frozen | L36: Frozen | M36: Frozen | N36: Frozen | O36: Frozen | P36: Frozen | Q36: Frozen | R36: Frozen
B37: 01_KOR | C37: 02_CHN | D37: 03_JPN | E37: 04_RUS | F37: 05_MNG | G37: 06_PRK | H37: 07_NAM | I37: 08_LAM | J37: 09_WEU | K37: 10_EEU | L37: 11_RFSU | M37: 12_MEA | N37: 13_AFR | O37: 14_RCPA | P37: 15_SAS | Q37: 16_RPAS | R37: 17_RPAO
A38: 2019 | B38: 51.7648 | C38: 1415.25 | D38: 126.633 | E38: 144.406 | F38: 3.23243 | G38: 25.7554 | H38: 369.4 | I38: 612.533 | J38: 508.668 | K38: 118.257 | L38: 140.625 | M38: 500.52 | N38: 1068.94 | O38: 119.197 | P38: 1823.83 | Q38: 557.765 | R38: 30.314
A39: 2020 | B39: 51.8581 | C39: 1431.5 | D39: 125.543 | E39: 145.762 | F39: 3.26646 | G39: 25.8132 | H39: 376.696 | I39: 616.162 | J39: 507.435 | K39: 119.398 | L39: 147.826 | M39: 504.777 | N39: 1056.87 | O39: 119.766 | P39: 1833.47 | Q39: 585.766 | R39: 30.5707
A40: 2021 | B40: 51.7866 | C40: 1431.98 | D40: 124.929 | E40: 145.683 | F40: 3.3147 | G40: 25.9303 | H40: 378.164 | I40: 620.407 | J40: 508.623 | K40: 119.197 | L40: 147.378 | M40: 513.098 | N40: 1085.16 | O40: 120.787 | P40: 1851.56 | Q40: 590.513 | R40: 30.8058
A41: 2022 | B41: 51.7151 | C41: 1432.46 | D41: 124.315 | E41: 145.605 | F41: 3.36293 | G41: 26.0474 | H41: 379.631 | I41: 624.651 | J41: 509.81 | K41: 118.996 | L41: 146.93 | M41: 521.42 | N41: 1113.45 | O41: 121.809 | P41: 1869.64 | Q41: 595.261 | R41: 31.041
A42: 2023 | B42: 51.6435 | C42: 1432.94 | D42: 123.701 | E42: 145.527 | F42: 3.41117 | G42: 26.1645 | H42: 381.099 | I42: 628.896 | J42: 510.998 | K42: 118.795 | L42: 146.482 | M42: 529.741 | N42: 1141.74 | O42: 122.831 | P42: 1887.73 | Q42: 600.009 | R42: 31.2762
A43: 2024 | B43: 51.572 | C43: 1433.43 | D43: 123.087 | E43: 145.449 | F43: 3.4594 | G43: 26.2816 | H43: 382.567 | I43: 633.14 | J43: 512.185 | K43: 118.594 | L43: 146.034 | M43: 538.062 | N43: 1170.02 | O43: 123.853 | P43: 1905.81 | Q43: 604.757 | R43: 31.5114 | S43: 01_KOR | T43: 02_CHN | U43: 03_JPN | V43: 04_RUS | W43: 05_MNG | X43: 06_PRK | Y43: 07_NAM | Z43: 08_LAM | AA43: 09_WEU | AB43: 10_EEU | AC43: 11_RFSU | AD43: 12_MEA | AE43: 13_AFR | AF43: 14_RCPA | AG43: 15_SAS | AH43: 16_RPAS | AI43: 17_RPAO
A44: 2025 | B44: 51.5005 | C44: 1433.91 | D44: 122.473 | E44: 145.37 | F44: 3.50764 | G44: 26.3987 | H44: 384.035 | I44: 637.385 | J44: 513.373 | K44: 118.393 | L44: 145.586 | M44: 546.384 | N44: 1198.31 | O44: 124.875 | P44: 1923.9 | Q44: 609.505 | R44: 31.7465 | S44: =(B44-B43)/B43 -> -0.0013864112 | T44: =(C44-C43)/C43 -> 0.00033486114 | U44: =(D44-D43)/D43 -> -0.0049883416 | V44: =(E44-E43)/E43 -> -0.00054314571 | W44: =(F44-F43)/F43 -> 0.013944615 | X44: =(G44-G43)/G43 -> 0.0044555887 | Y44: =(H44-H43)/H43 -> 0.0038372364 | Z44: =(I44-I43)/I43 -> 0.0067046783 | ... AI44: =(R44-R43)/R43 -> 0.007460792
A45: 2026 | B45: 51.3967 | C45: 1431.89 | D45: 121.848 | E45: 144.976 | F45: 3.55088 | G45: 26.4254 | H45: 385.703 | I45: 641.625 | J45: 514.185 | K45: 117.85 | L45: 146.668 | M45: 554.467 | N45: 1228.65 | O45: 125.724 | P45: 1942.06 | Q45: 613.998 | R45: 31.9721 | S45: =(B45-B44)/B44 -> -0.0020155144 | T45: =(C45-C44)/C44 -> -0.0014087356 | U45: =(D45-D44)/D44 -> -0.0051031656 | V45: =(E45-E44)/E44 -> -0.0027103254 | W45: =(F45-F44)/F44 -> 0.012327377 | X45: =(G45-G44)/G44 -> 0.0010114134 | Y45: =(H45-H44)/H44 -> 0.0043433541 | Z45: =(I45-I44)/I44 -> 0.0066521804 | ... AI45: =(R45-R44)/R44 -> 0.0071062952
A46: 2027 | B46: 51.2929 | C46: 1429.87 | D46: 121.223 | E46: 144.582 | F46: 3.59412 | G46: 26.452 | H46: 387.37 | I46: 645.865 | J46: 514.997 | K46: 117.308 | L46: 147.75 | M46: 562.55 | N46: 1258.99 | O46: 126.573 | P46: 1960.22 | Q46: 618.491 | R46: 32.1976 | S46: =(B46-B45)/B45 -> -0.0020195849 | T46: =(C46-C45)/C45 -> -0.0014107229 | U46: =(D46-D45)/D45 -> -0.0051293415 | V46: =(E46-E45)/E45 -> -0.0027176912 | W46: =(F46-F45)/F45 -> 0.012177263 | X46: =(G46-G45)/G45 -> 0.0010066073 | Y46: =(H46-H45)/H45 -> 0.0043219783 | Z46: =(I46-I45)/I45 -> 0.0066082213 | ... AI46: =(R46-R45)/R45 -> 0.0070530244
A47: 2028 | B47: 51.1891 | C47: 1427.86 | D47: 120.598 | E47: 144.188 | F47: 3.63736 | G47: 26.4787 | H47: 389.038 | I47: 650.106 | J47: 515.809 | K47: 116.765 | L47: 148.832 | M47: 570.633 | N47: 1289.32 | O47: 127.421 | P47: 1978.38 | Q47: 622.983 | R47: 32.4232 | S47: =(B47-B46)/B46 -> -0.0020236719 | T47: =(C47-C46)/C46 -> -0.0014057222 | U47: =(D47-D46)/D46 -> -0.0051557873 | V47: =(E47-E46)/E46 -> -0.0027250972 | W47: =(F47-F46)/F46 -> 0.012030761 | X47: =(G47-G46)/G46 -> 0.0010093755 | Y47: =(H47-H46)/H46 -> 0.0043059607 | Z47: =(I47-I46)/I46 -> 0.0065663877 | ... AI47: =(R47-R46)/R46 -> 0.0070067334
A48: 2029 | B48: 51.0853 | C48: 1425.84 | D48: 119.973 | E48: 143.794 | F48: 3.68059 | G48: 26.5053 | H48: 390.706 | I48: 654.346 | J48: 516.621 | K48: 116.223 | L48: 149.913 | M48: 578.715 | N48: 1319.66 | O48: 128.27 | P48: 1996.55 | Q48: 627.476 | R48: 32.6487 | S48: =(B48-B47)/B47 -> -0.0020277754 | T48: =(C48-C47)/C47 -> -0.0014147045 | U48: =(D48-D47)/D47 -> -0.0051825072 | V48: =(E48-E47)/E47 -> -0.0027325436 | W48: =(F48-F47)/F47 -> 0.011884994 | X48: =(G48-G47)/G47 -> 0.001004581 | Y48: =(H48-H47)/H47 -> 0.0042874989 | Z48: =(I48-I47)/I47 -> 0.0065220133 | ... AI48: =(R48-R47)/R47 -> 0.0069548965
A49: 2030 | B49: 50.9815 | C49: 1423.82 | D49: 119.348 | E49: 143.4 | F49: 3.72383 | G49: 26.532 | H49: 392.374 | I49: 658.587 | J49: 517.433 | K49: 115.68 | L49: 150.995 | M49: 586.798 | N49: 1350 | O49: 129.119 | P49: 2014.71 | Q49: 631.969 | R49: 32.8742 | S49: =(B49-B48)/B48 -> -0.0020318957 | T49: =(C49-C48)/C48 -> -0.0014167087 | U49: =(D49-D48)/D48 -> -0.0052095055 | V49: =(E49-E48)/E48 -> -0.0027400309 | W49: =(F49-F48)/F48 -> 0.011748116 | X49: =(G49-G48)/G48 -> 0.0010073457 | Y49: =(H49-H48)/H48 -> 0.0042691947 | Z49: =(I49-I48)/I48 -> 0.0064812805 | ... AI49: =(R49-R48)/R48 -> 0.00690686
A50: 2031 | B50: 50.836 | C50: 1420.33 | D50: 118.688 | E50: 143.033 | F50: 3.76586 | G50: 26.5009 | H50: 394.002 | I50: 662.134 | J50: 518.174 | K50: 115.114 | L50: 151.873 | M50: 594.491 | N50: 1381.71 | O50: 129.766 | P50: 2030.54 | Q50: 635.695 | R50: 33.0834 | S50: =(B50-B49)/B49 -> -0.0028539764 | T50: =(C50-C49)/C49 -> -0.0024511525 | U50: =(D50-D49)/D49 -> -0.0055300466 | V50: =(E50-E49)/E49 -> -0.0025592748 | W50: =(F50-F49)/F49 -> 0.011286767 | X50: =(G50-G49)/G49 -> -0.0011721695 | Y50: =(H50-H49)/H49 -> 0.0041491026 | Z50: =(I50-I49)/I49 -> 0.0053857729 | ... AI50: =(R50-R49)/R49 -> 0.006363653
A51: 2032 | B51: 50.6905 | C51: 1416.85 | D51: 118.029 | E51: 142.667 | F51: 3.80789 | G51: 26.4698 | H51: 395.629 | I51: 665.68 | J51: 518.916 | K51: 114.548 | L51: 152.751 | M51: 602.184 | N51: 1413.42 | O51: 130.413 | P51: 2046.37 | Q51: 639.421 | R51: 33.2925 | S51: =(B51-B50)/B50 -> -0.0028621449 | T51: =(C51-C50)/C50 -> -0.0024501348 | U51: =(D51-D50)/D50 -> -0.0055523726 | V51: =(E51-E50)/E50 -> -0.0025588501 | W51: =(F51-F50)/F50 -> 0.011160797 | X51: =(G51-G50)/G50 -> -0.001173545 | Y51: =(H51-H50)/H50 -> 0.0041294207 | Z51: =(I51-I50)/I50 -> 0.0053554114 | ... AI51: =(R51-R50)/R50 -> 0.0063203903
A52: 2033 | B52: 50.545 | C52: 1413.36 | D52: 117.37 | E52: 142.301 | F52: 3.84992 | G52: 26.4387 | H52: 397.257 | I52: 669.227 | J52: 519.657 | K52: 113.981 | L52: 153.629 | M52: 609.876 | N52: 1445.14 | O52: 131.06 | P52: 2062.2 | Q52: 643.148 | R52: 33.5016 | S52: =(B52-B51)/B51 -> -0.0028703603 | T52: =(C52-C51)/C51 -> -0.0024632106 | U52: =(D52-D51)/D51 -> -0.0055833736 | V52: =(E52-E51)/E51 -> -0.0025654146 | W52: =(F52-F51)/F51 -> 0.011037609 | X52: =(G52-G51)/G51 -> -0.0011749239 | Y52: =(H52-H51)/H51 -> 0.0041149663 | Z52: =(I52-I51)/I51 -> 0.005328386 | ... AI52: =(R52-R51)/R51 -> 0.0062806938
A53: 2034 | B53: 50.3995 | C53: 1409.87 | D53: 116.71 | E53: 141.934 | F53: 3.89195 | G53: 26.4076 | H53: 398.884 | I53: 672.774 | J53: 520.399 | K53: 113.415 | L53: 154.507 | M53: 617.569 | N53: 1476.85 | O53: 131.707 | P53: 2078.02 | Q53: 646.874 | R53: 33.7107 | S53: =(B53-B52)/B52 -> -0.002878623 | T53: =(C53-C52)/C52 -> -0.002469293 | U53: =(D53-D52)/D52 -> -0.0056232427 | V53: =(E53-E52)/E52 -> -0.0025790402 | W53: =(F53-F52)/F52 -> 0.01091711 | X53: =(G53-G52)/G52 -> -0.0011763059 | Y53: =(H53-H52)/H52 -> 0.0040955855 | Z53: =(I53-I52)/I52 -> 0.0053001448 | ... AI53: =(R53-R52)/R52 -> 0.0062414929
A54: 2035 | B54: 50.254 | C54: 1406.39 | D54: 116.051 | E54: 141.568 | F54: 3.93398 | G54: 26.3765 | H54: 400.512 | I54: 676.321 | J54: 521.14 | K54: 112.849 | L54: 155.385 | M54: 625.261 | N54: 1508.56 | O54: 132.354 | P54: 2093.85 | Q54: 650.6 | R54: 33.9198 | S54: =(B54-B53)/B53 -> -0.0028869334 | T54: =(C54-C53)/C53 -> -0.0024683127 | U54: =(D54-D53)/D53 -> -0.0056464742 | V54: =(E54-E53)/E53 -> -0.0025786633 | W54: =(F54-F53)/F53 -> 0.010799214 | X54: =(G54-G53)/G53 -> -0.0011776913 | Y54: =(H54-H53)/H53 -> 0.0040813871 | Z54: =(I54-I53)/I53 -> 0.0052722014 | ... AI54: =(R54-R53)/R53 -> 0.0062027783
...

Sheet Data
C1: EDGAR IEA CO2 Emission ktCO2 | T1: World Bank POP Person | AK1: World Bank GDP constant 2021 international $ | BB1: TES (ktoe)
C2: 01_KOR | D2: 02_CHN | E2: 03_JPN | F2: 04_RUS | G2: 05_MNG | H2: 06_PRK | I2: 07_NAM | J2: 08_LAM | K2: 09_WEU | L2: 10_EEU | M2: 11_RFSU | N2: 12_MEA | O2: 13_AFR | P2: 14_RCPA | Q2: 15_SAS | R2: 16_RPAS | S2: 17_RPAO | T2: 01_KOR | U2: 02_CHN | V2: 03_JPN | W2: 04_RUS | X2: 05_MNG | Y2: 06_PRK | Z2: 07_NAM | AA2: 08_LAM | AB2: 09_WEU | AC2: 10_EEU | AD2: 11_RFSU | AE2: 12_MEA | AF2: 13_AFR | AG2: 14_RCPA | AH2: 15_SAS | AI2: 16_RPAS | AJ2: 17_RPAO | AK2: 01_KOR | AL2: 02_CHN | AM2: 03_JPN | AN2: 04_RUS | AO2: 05_MNG | AP2: 06_PRK | AQ2: 07_NAM | AR2: 08_LAM | AS2: 09_WEU | AT2: 10_EEU | AU2: 11_RFSU | AV2: 12_MEA | AW2: 13_AFR | AX2: 14_RCPA | AY2: 15_SAS | AZ2: 16_RPAS | BA2: 17_RPAO | BB2: 01_KOR | BC2: 02_CHN | BD2: 03_JPN | BE2: 04_RUS | BF2: 05_MNG | BG2: 06_PRK | BH2: 07_NAM | BI2: 08_LAM | BJ2: 09_WEU | BK2: 10_EEU | BL2: 11_RFSU | BM2: 12_MEA | BN2: 13_AFR | BO2: 14_RCPA | BP2: 15_SAS | BQ2: 16_RPAS | BR2: 17_RPAO
A3: Historical | B3: 1990 | C3: 260232.56 | D3: 2449320.5 | E3: 1162286.3 | F3: 2436269.5 | G3: 13147.885 | H3: 131964.51 | I3: 5443214.7 | J3: 950935.02 | K3: 3555586.6 | L3: 1179817 | M3: 1492441.5 | N3: 917112.56 | O3: 477656.38 | P3: 21263.409 | Q3: 689599.68 | R3: 544604.01 | S3: 302698.53 | T3: 42869283 | U3: 1140889500 | V3: 123478000 | W3: 147969406 | X3: 2098710 | Y3: 21112137 | Z3: 277759852 | AA3: 437248525 | AB3: 434508762 | AC3: 131020110 | AD3: 143965916 | AE3: 280903196 | AF3: 488052325 | AG3: 11686707 | AH3: 1129452594 | AI3: 369194554 | AJ3: 20394928 | AK3: 6.1636957e+11 | AL3: 2.0725265e+12 | AM3: 4.3553678e+12 | AN3: 4.3863451e+12 | AO3: 1.3930858e+10 | AP3: 1.9573106e+10 | AQ3: 1.2198702e+13 | AR3: 5.030829e+12 | AS3: 1.5393166e+13 | AT3: 1.9708102e+12 | AU3: 1.9762052e+12 | AV3: 3.1526616e+12 | AW3: 1.8809725e+12 | AX3: 2.8161944e+10 | AY3: 2.6223045e+12 | AZ3: 2.1091693e+12 | BA3: 7.2112341e+11 | BB3: 89512.003 | BC3: 887159.24 | BD3: 436913.56 | BE3: 879334.57 | BF3: 3493.952 | BG3: 33221.982 | BH3: 2126074.6 | BI3: 459016.56 | BJ3: 1403150.1 | BK3: 374610.73 | BL3: 501235.34 | BM3: 312863.28 | BN3: 239635.33 | BO3: 17868.358 | BP3: 347037.52 | BQ3: 249694.69 | BR3: 99108.107
B4: 1991 | C4: 292360.93 | D4: 2588695.4 | E4: 1172036.8 | F4: 2393540.5 | G4: 14858.263 | H4: 126915.61 | I4: 5393199.6 | J4: 979649.5 | K4: 3601521.6 | L4: 1072019.7 | M4: 1431030.7 | N4: 959075.29 | O4: 476328.84 | P4: 21507.377 | Q4: 737460.84 | R4: 589575.19 | S4: 305394.51 | T4: 43295704 | U4: 1156532000 | V4: 123964000 | W4: 148394216 | X4: 2165342 | Y4: 21428638 | Z4: 281470059 | AA4: 445392924 | AB4: 437283653 | AC4: 130458697 | AD4: 145408876 | AE4: 288264778 | AF4: 502131649 | AG4: 12121968 | AH4: 1155118555 | AI4: 376274496 | AJ4: 20779136 | AK4: 6.8339961e+11 | AL4: 2.2599534e+12 | AM4: 4.5088229e+12 | AN4: 4.164969e+12 | AO4: 1.2719772e+10 | AP4: 1.8708527e+10 | AQ4: 1.2163267e+13 | AR4: 5.1984352e+12 | AS4: 15693738611764 | AT4: 1.7548478e+12 | AU4: 1.8103172e+12 | AV4: 3.1950405e+12 | AW4: 1.8857577e+12 | AX4: 3.0014885e+10 | AY4: 2.6750096e+12 | AZ4: 2.2428762e+12 | BA4: 7.1762798e+11 | BB4: 97845.605 | BC4: 862048.71 | BD4: 441422.94 | BE4: 871370.01 | BF4: 3824.161 | BG4: 31703.718 | BH4: 2141300.2 | BI4: 470032.89 | BJ4: 1433702.1 | BK4: 341425.1 | BL4: 495502.66 | BM4: 328284.01 | BN4: 247089.63 | BO4: 18110.888 | BP4: 361011.07 | BQ4: 269522.07 | BR4: 98405.337
B5: 1992 | C5: 321092.19 | D5: 2713280.8 | E5: 1177372.1 | F5: 2205465.1 | G5: 12957.341 | H5: 112244.29 | I5: 5484641.9 | J5: 996489.84 | K5: 3526821.3 | L5: 985980.64 | M5: 1275412.2 | N5: 1020478.7 | O5: 478803.53 | P5: 22566.565 | Q5: 769328.16 | R5: 624591.46 | S5: 310412.88 | T5: 43747962 | U5: 1170770500 | V5: 124425000 | W5: 148538197 | X5: 2167790 | Y5: 21750911 | Z5: 285342295 | AA5: 453484566 | AB5: 440113356 | AC5: 129877934 | AD5: 147554695 | AE5: 295864932 | AF5: 516567881 | AG5: 12672729 | AH5: 1180621418 | AI5: 383346097 | AJ5: 21010335 | AK5: 7.2680636e+11 | AL5: 2.5677521e+12 | AM5: 4.5494287e+12 | AN5: 3.5597542e+12 | AO5: 1.1542371e+10 | AP5: 1.7383216e+10 | AQ5: 1.2562835e+13 | AR5: 5.3458515e+12 | AS5: 1.5929653e+13 | AT5: 1.6658229e+12 | AU5: 1.595111e+12 | AV5: 3.3818537e+12 | AW5: 1.8768141e+12 | AX5: 3.198972e+10 | AY5: 2828896832965 | AZ5: 2.3857926e+12 | BA5: 7.2140378e+11 | BB5: 111375.97 | BC5: 893025.12 | BD5: 451223.41 | BE5: 795730.56 | BF5: 3342.886 | BG5: 27712.95 | BH5: 2185011.4 | BI5: 482108.21 | BJ5: 1422061.8 | BK5: 312242.26 | BL5: 437820.09 | BM5: 359486.94 | BN5: 248067.41 | BO5: 18903.571 | BP5: 375614.44 | BQ5: 285360.18 | BR5: 100283.67
B6: 1993 | C6: 349635.31 | D6: 2934645.2 | E6: 1169827.6 | F6: 2012962.5 | G6: 11937.255 | H6: 104007.02 | I6: 5603056.8 | J6: 1029878.1 | K6: 3471941.2 | L6: 955970.87 | M6: 1114426.2 | N6: 1074708.4 | O6: 478621.92 | P6: 26303.315 | Q6: 809046.77 | R6: 677597.99 | S6: 314345.14 | T6: 44194628 | U6: 1184341000 | V6: 124829000 | W6: 148458777 | X6: 2165130 | Y6: 22073352 | Z6: 289066123 | AA6: 461533132 | AB6: 442800797 | AC6: 129477709 | AD6: 149904165 | AE6: 302603096 | AF6: 531102032 | AG6: 13301441 | AH6: 1206276498 | AI6: 390445055 | AJ6: 21207008 | AK6: 7.7764441e+11 | AL6: 2.9097739e+12 | AM6: 4.5285369e+12 | AN6: 3.2511755e+12 | AO6: 1.1176617e+10 | AP6: 1.6604637e+10 | AQ6: 1.2907496e+13 | AR6: 5.597629e+12 | AS6: 1.5972132e+13 | AT6: 1.669082e+12 | AU6: 1.3953777e+12 | AV6: 3.4611776e+12 | AW6: 1.8493115e+12 | AX6: 3.34735e+10 | AY6: 2.951963e+12 | AZ6: 2.5538382e+12 | BA6: 7.529879e+11 | BB6: 124844.01 | BC6: 944793.3 | BD6: 453936.86 | BE6: 751218.69 | BF6: 3123.808 | BG6: 25488.827 | BH6: 2226733.6 | BI6: 485746.46 | BJ6: 1426881.1 | BK6: 308299.3 | BL6: 388385.59 | BM6: 383542.35 | BN6: 256661.85 | BO6: 20510.416 | BP6: 388030.3 | BQ6: 306769.64 | BR6: 105514.72
B7: 1994 | C7: 377449.77 | D7: 3085058.9 | E7: 1223346.4 | F7: 1814911.9 | G7: 10406.291 | H7: 95190.123 | I7: 5703237.1 | J7: 1093035.9 | K7: 3476457.8 | L7: 919653.75 | M7: 962199.14 | N7: 1161081.2 | O7: 481841.51 | P7: 30821.812 | Q7: 857759.76 | R7: 731162.66 | S7: 320281.2 | T7: 44641540 | U7: 1197870400 | V7: 125178000 | W7: 148407912 | X7: 2189395 | Y7: 22393975 | Z7: 292594524 | AA7: 469500872 | AB7: 445145911 | AC7: 129286564 | AD7: 151281889 | AE7: 309232193 | AF7: 545286694 | AG7: 14048382 | AH7: 1232053600 | AI7: 397464561 | AJ7: 21425468 | AK7: 8.5052397e+11 | AL7: 3.2750338e+12 | AM7: 4.5775983e+12 | AN7: 2.8425107e+12 | AO7: 1.1415169e+10 | AP7: 1.6254156e+10 | AQ7: 1.3432828e+13 | AR7: 5.8980759e+12 | AS7: 1.6375677e+13 | AT7: 1730170845331 | AU7: 1.1300026e+12 | AV7: 3.5544809e+12 | AW7: 1.8649737e+12 | AX7: 2.6154493e+10 | AY7: 3.1284179e+12 | AZ7: 2.7476642e+12 | BA7: 7.8418811e+11 | BB7: 132540.66 | BC7: 990029.39 | BD7: 478664.55 | BE7: 657041.37 | BF7: 2695.978 | BG7: 23308.619 | BH7: 2271729.8 | BI7: 512782.71 | BJ7: 1430967.7 | BK7: 293212.26 | BL7: 341578.26 | BM7: 410723.53 | BN7: 261528.91 | BO7: 20524.894 | BP7: 405621.41 | BQ7: 322156.57 | BR7: 106114.51
B8: 1995 | C8: 407088.33 | D8: 3404402.5 | E8: 1233224.3 | F8: 1768562.2 | G8: 10343.857 | H8: 89100.934 | I8: 5769303 | J8: 1110071.3 | K8: 3531993.7 | L8: 930359.48 | M8: 910528.41 | N8: 1194933.9 | O8: 512119.9 | P8: 36266.532 | Q8: 920512.07 | R8: 800344.77 | S8: 331507.61 | T8: 45092991 | U8: 1211011100 | V8: 125472000 | W8: 148375787 | X8: 2224945 | Y8: 22669304 | Z8: 296054001 | AA8: 477446311 | AB8: 447323255 | AC8: 129143618 | AD8: 151876925 | AE8: 316208257 | AF8: 559832338 | AG8: 14947906 | AH8: 1258097812 | AI8: 404530176 | AJ8: 21678282 | AK8: 9.3333008e+11 | AL8: 3.6166248e+12 | AM8: 4.6980349e+12 | AN8: 2.7247304e+12 | AO8: 1.2143049e+10 | AP8: 1.5543137e+10 | AQ8: 1.3793398e+13 | AR8: 5.9464307e+12 | AS8: 1.684167e+13 | AT8: 1.9017749e+12 | AU8: 1.0182738e+12 | AV8: 3.6574941e+12 | AW8: 1.9228897e+12 | AX8: 2.8431444e+10 | AY8: 3.3434667e+12 | AZ8: 2.9584785e+12 | BA8: 8.1564524e+11 | BB8: 145844.17 | BC8: 1062594.4 | BD8: 491307.96 | BE8: 636759.67 | BF8: 2680.436 | BG8: 21984.934 | BH8: 2300833.3 | BI8: 516587.15 | BJ8: 1471349.8 | BK8: 306055.2 | BL8: 322310.59 | BM8: 422901.15 | BN8: 272921.75 | BO8: 24736.14 | BP8: 429329.83 | BQ8: 344323.39 | BR8: 107543.27
B9: 1996 | C9: 436496.62 | D9: 3376352.7 | E9: 1246029 | F9: 1727191.4 | G9: 8742.7979 | H9: 79057.98 | I9: 5938551.1 | J9: 1185727.7 | K9: 3640655.2 | L9: 968421.9 | M9: 813741.61 | N9: 1231365.3 | O9: 546038.7 | P9: 40833.909 | Q9: 964846.41 | R9: 860502.66 | S9: 342482.08 | T9: 45524681 | U9: 1223985500 | V9: 125757000 | W9: 148160129 | X9: 2259507 | Y9: 22895746 | Z9: 299485254 | AA9: 485330003 | AB9: 449387090 | AC9: 129083967 | AD9: 152356459 | AE9: 323099229 | AF9: 575059391 | AG9: 15846948 | AH9: 1284555740 | AI9: 411766189 | AJ9: 21956767 | AK9: 1.0079072e+12 | AL9: 3.9640841e+12 | AM9: 4.8452652e+12 | AN9: 2.6224149e+12 | AO9: 1.2414458e+10 | AP9: 1.5022054e+10 | AQ9: 1.4288379e+13 | AR9: 6185211724211 | AS9: 1.7198056e+13 | AT9: 1.9936867e+12 | AU9: 9.6864287e+11 | AV9: 3.851821e+12 | AW9: 2.02193e+12 | AX9: 3.0228518e+10 | AY9: 3.5698745e+12 | AZ9: 3.1694997e+12 | BA9: 8.4687164e+11 | BB9: 157557.38 | BC9: 1088325.6 | BD9: 501830.04 | BE9: 630361.05 | BF9: 2255.473 | BG9: 19330.781 | BH9: 2351460.8 | BI9: 539954.86 | BJ9: 1525014.4 | BK9: 318750.74 | BL9: 299759.57 | BM9: 430846.54 | BN9: 282353.35 | BO9: 26027.848 | BP9: 445743.16 | BQ9: 365032.43 | BR9: 114534.61
B10: 1997 | C10: 458862.69 | D10: 3471729.5 | E10: 1231696.8 | F10: 1607381.1 | G10: 8569.3157 | H10: 76671.966 | I10: 6227975.9 | J10: 1252429.9 | K10: 3588436.2 | L10: 946912.8 | M10: 776129.95 | N10: 1288349.2 | O10: 561018.33 | P10: 46932.466 | Q10: 1014005.1 | R10: 920270.39 | S10: 353715.2 | T10: 45953580 | U10: 1236564300 | V10: 126057000 | W10: 147915361 | X10: 2291750 | Y10: 23110830 | Z10: 303052655 | AA10: 493156466 | AB10: 451331585 | AC10: 128990732 | AD10: 152702465 | AE10: 330134532 | AF10: 590392154 | AG10: 16722993 | AH10: 1311157702 | AI10: 419070574 | AJ10: 22204337 | AK10: 1.0712258e+12 | AL10: 4.3220656e+12 | AM10: 4.8928084e+12 | AN10: 2.6591265e+12 | AO10: 1.2898213e+10 | AP10: 1.4048117e+10 | AQ10: 1.4921731e+13 | AR10: 6.5248088e+12 | AS10: 1.7756941e+13 | AT10: 2.0434743e+12 | AU10: 9.7360227e+11 | AV10: 4.0279413e+12 | AW10: 2.0920109e+12 | AX10: 3.1797325e+10 | AY10: 3.7039589e+12 | AZ10: 3.2796049e+12 | BA10: 8.7777139e+11 | BB10: 168900.94 | BC10: 1088457.3 | BD10: 507012.5 | BE10: 602112.92 | BF10: 2205.954 | BG10: 18414.924 | BH10: 2374931.6 | BI10: 563156.28 | BJ10: 1520153.3 | BK10: 313134.94 | BL10: 286973.36 | BM10: 455996.41 | BN10: 291153.79 | BO10: 27904.304 | BP10: 463990 | BQ10: 384893.83 | BR10: 117562.03
B11: 1998 | C11: 393614.15 | D11: 3564606.2 | E11: 1184390.4 | F11: 1613220.9 | G11: 8596.3138 | H11: 62868.572 | I11: 6281934.6 | J11: 1304115.2 | K11: 3640966.8 | L11: 895788.73 | M11: 777044.59 | N11: 1300422.2 | O11: 564772.57 | P11: 52432.275 | Q11: 1038921.4 | R11: 908266.2 | S11: 372570.5 | T11: 46286503 | U11: 1248478700 | V11: 126400000 | W11: 147670784 | X11: 2323809 | Y11: 23311564 | Z11: 306507357 | AA11: 500989840 | AB11: 453192778 | AC11: 128718120 | AD11: 153050558 | AE11: 337359109 | AF11: 606268459 | AG11: 17306439 | AH11: 1337928286 | AI11: 426507563 | AJ11: 22422584 | AK11: 1.0183187e+12 | AL11: 4.6291127e+12 | AM11: 4.8306535e+12 | AN11: 2.5181938e+12 | AO11: 1.3329006e+10 | AP11: 1.3921102e+10 | AQ11: 1.558306e+13 | AR11: 6.719084e+12 | AS11: 1.8284272e+13 | AT11: 2.1009295e+12 | AU11: 9.7772525e+11 | AV11: 4.2218032e+12 | AW11: 2.1453495e+12 | AX11: 3.319071e+10 | AY11: 3.9087691e+12 | AZ11: 2.9995856e+12 | BA11: 9.1398908e+11 | BB11: 156186.82 | BC11: 1096599.6 | BD11: 497798.97 | BE11: 588064.34 | BF11: 2223.701 | BG11: 17184.524 | BH11: 2391914.4 | BI11: 583720.47 | BJ11: 1546380.1 | BK11: 300277.97 | BL11: 280947.75 | BM11: 465015.52 | BN11: 293401.52 | BO11: 29779.885 | BP11: 475371.54 | BQ11: 378779.39 | BR11: 119961.12
B12: 1999 | C12: 430610.18 | D12: 3493310.9 | E12: 1225171.6 | F12: 1660911.2 | G12: 8653.9361 | H12: 68566.356 | I12: 6310488 | J12: 1293950.8 | K12: 3618063.5 | L12: 833794.89 | M12: 765713.4 | N12: 1346078.4 | O12: 553427.82 | P12: 53574.996 | Q12: 1112775.9 | R12: 951144.8 | S12: 380162.15 | T12: 46616677 | U12: 1259341500 | V12: 126631000 | W12: 147214776 | X12: 2356813 | Y12: 23497599 | Z12: 309947562 | AA12: 508748419 | AB12: 455199408 | AC12: 128335102 | AD12: 153601663 | AE12: 344767792 | AF12: 622587149 | AG12: 17606515 | AH12: 1364829186 | AI12: 433639198 | AJ12: 22647364 | AK12: 1.1366195e+12 | AL12: 4.9746806e+12 | AM12: 4.8145225e+12 | AN12: 2.6793561e+12 | AO12: 1.3738255e+10 | AP12: 1.476724e+10 | AQ12: 1.633398e+13 | AR12: 6.7515858e+12 | AS12: 1.8774506e+13 | AT12: 2.1291833e+12 | AU12: 9.9573896e+11 | AV12: 4.3455444e+12 | AW12: 2.1893802e+12 | AX12: 3.6658934e+10 | AY12: 4.2069405e+12 | AZ12: 3.0940993e+12 | BA12: 9.6039273e+11 | BB12: 170887.45 | BC12: 1119133.3 | BD12: 505792.56 | BE12: 609137.52 | BF12: 2226.752 | BG12: 18408.718 | BH12: 2456798.2 | BI12: 599353.94 | BJ12: 1546612.6 | BK12: 281921.76 | BL12: 278517.84 | BM12: 482482.07 | BN12: 297761.65 | BO12: 30646.21 | BP12: 502890.83 | BQ12: 392231.84 | BR12: 122794.23
B13: 2000 | C13: 466403.11 | D13: 3689778.3 | E13: 1243576.8 | F13: 1681152.1 | G13: 9040.4928 | H13: 73806.333 | I13: 6497071 | J13: 1333142.4 | K13: 3664963 | L13: 840541.74 | M13: 772428.62 | N13: 1407109.2 | O13: 568324.43 | P13: 59471.518 | Q13: 1152686.6 | R13: 989752.36 | S13: 386893.79 | T13: 47008111 | U13: 1269310000 | V13: 126843000 | W13: 146596869 | X13: 2388299 | Y13: 23665910 | Z13: 313359794 | AA13: 516277627 | AB13: 457445232 | AC13: 127646761 | AD13: 153992027 | AE13: 352552470 | AF13: 639184700 | AG13: 17893548 | AH13: 1392064609 | AI13: 440542431 | AJ13: 22886502 | AK13: 1.2412096e+12 | AL13: 5.3995512e+12 | AM13: 4.9476271e+12 | AN13: 2.9472935e+12 | AO13: 1.3895704e+10 | AP13: 1.4828093e+10 | AQ13: 1.7014998e+13 | AR13: 6.9986462e+12 | AS13: 1.9553439e+13 | AT13: 2.2155137e+12 | AU13: 1.0929911e+12 | AV13: 4.6171576e+12 | AW13: 2.2609754e+12 | AX13: 3.9698196e+10 | AY13: 4.3795499e+12 | AZ13: 3.270245e+12 | BA13: 9.9659484e+11 | BB13: 185793.14 | BC13: 1148088.2 | BD13: 515874.98 | BE13: 619370.25 | BF13: 2394.233 | BG13: 19716.932 | BH13: 2525241.7 | BI13: 603797.85 | BJ13: 1566683.4 | BK13: 282194.81 | BL13: 278949.5 | BM13: 495982.8 | BN13: 293612.18 | BO13: 33754.646 | BP13: 516264.13 | BQ13: 410656.06 | BR13: 125340.18
B14: 2001 | C14: 477110.97 | D14: 3866914.8 | E14: 1229989.5 | F14: 1684276.8 | G14: 9012.3217 | H14: 76673.024 | I14: 6436885.7 | J14: 1335077.6 | K14: 3697764.3 | L14: 856791.11 | M14: 767748.96 | N14: 1480690.4 | O14: 588570.5 | P14: 65308.37 | Q14: 1176570.9 | R14: 1029906.4 | S14: 395335.91 | T14: 47370164 | U14: 1278564300 | V14: 127149000 | W14: 145976482 | X14: 2417751 | Y14: 23815358 | Z14: 316502971 | AA14: 523568696 | AB14: 459924387 | AC14: 126865365 | AD14: 154268911 | AE14: 360583862 | AF14: 656336244 | AG14: 18179966 | AH14: 1419419963 | AI14: 447435050 | AJ14: 23155201 | AK14: 1.2998684e+12 | AL14: 5.8278084e+12 | AM14: 4.9667301e+12 | AN14: 3.097607e+12 | AO14: 1.4306004e+10 | AP14: 1.5385051e+10 | AQ14: 1.719124e+13 | AR14: 7.017981e+12 | AS14: 1.9901016e+13 | AT14: 2.2862112e+12 | AU14: 1.1818355e+12 | AV14: 4.7191986e+12 | AW14: 2.3574149e+12 | AX14: 4.2373825e+10 | AY14: 4.5771542e+12 | AZ14: 3.3626395e+12 | BA14: 1.0187497e+12 | BB14: 185836.99 | BC14: 1185975.1 | BD14: 507338 | BE14: 625933.77 | BF14: 2412.035 | BG14: 20369.48 | BH14: 2478366 | BI14: 604943.18 | BJ14: 1595655.5 | BK14: 290522.03 | BL14: 276283.8 | BM14: 537791.1 | BN14: 296775.29 | BO14: 35829.363 | BP14: 525722.08 | BQ14: 422438.74 | BR14: 122819.52
B15: 2002 | C15: 494470.38 | D15: 4174024.3 | E15: 1264500.9 | F15: 1675294.7 | G15: 9658.0318 | H15: 73443.086 | I15: 6300956.4 | J15: 1340822.3 | K15: 3696516.5 | L15: 844662.5 | M15: 790664.75 | N15: 1535742.1 | O15: 591070.9 | P15: 76484.171 | Q15: 1215732.1 | R15: 1062324.3 | S15: 403644.4 | T15: 47644736 | U15: 1287144100 | V15: 127445000 | W15: 145306497 | X15: 2449027 | Y15: 23943973 | Z15: 319497793 | AA15: 530681757 | AB15: 462778793 | AC15: 126158241 | AD15: 155531091 | AE15: 368226417 | AF15: 674082131 | AG15: 18466130 | AH15: 1445807345 | AI15: 454091846 | AJ15: 23443710 | AK15: 1.4005302e+12 | AL15: 6.346233e+12 | AM15: 4.9688142e+12 | AN15: 3.2431943e+12 | AO15: 1.4983104e+10 | AP15: 1.5569847e+10 | AQ15: 1.7509111e+13 | AR15: 7.0536286e+12 | AS15: 2.0152677e+13 | AT15: 2.3720873e+12 | AU15: 1.2624663e+12 | AV15: 4.827508e+12 | AW15: 2516882202715 | AX15: 4.4970909e+10 | AY15: 4.7428562e+12 | AZ15: 3.5302475e+12 | BA15: 1.0600814e+12 | BB15: 195032.6 | BC15: 1262919.3 | BD15: 508877.71 | BE15: 623283.45 | BF15: 2582.539 | BG15: 19565.581 | BH15: 2504214.2 | BI15: 627231.47 | BJ15: 1595308.1 | BK15: 292717.73 | BL15: 283376.87 | BM15: 562124.78 | BN15: 298303.62 | BO15: 38675.963 | BP15: 539355.49 | BQ15: 442213.25 | BR15: 123920.44
... B36: 2023 | C36: 590364.99 | D36: 13055361 | E36: 1002438.2 | F36: 1948302.4 | G36: 27152.554 | H36: 65658.792 | I36: 5200023.6 | J36: 1738813.4 | K36: 2730381.1 | L36: 700085.59 | M36: 748868.07 | N36: 3041205.6 | O36: 852828.67 | P36: 435385.16 | Q36: 3394417.2 | R36: 1889024.1 | S36: 409271.67 | T36: 51712619 | U36: 1418246100 | V36: 124516650 | W36: 143826130 | X36: 3481145 | Y36: 26418204 | Z36: 377375365 | AA36: 654233535 | AB36: 517657986 | AC36: 116540071 | AD36: 188493817 | AE36: 568662672 | AF36: 1181158123 | AG36: 25088873 | AH36: 1910085074 | AI36: 579133327 | AJ36: 31859922 | AK36: 2.7939989e+12 | AL36: 3.249047e+13 | AM36: 5.7101667e+12 | AN36: 5.835482e+12 | AO36: 5.6474142e+10 | AP36: 1.6297779e+10 | AQ36: 2.7282617e+13 | AR36: 1.1967382e+13 | AS36: 2.7812607e+13 | AT36: 4.5854972e+12 | AU36: 2.5826499e+12 | AV36: 9.8487115e+12 | AW36: 5.8845819e+12 | AX36: 1.8083048e+11 | AY36: 1.6585661e+13 | AZ36: 8.9479489e+12 | BA36: 1.8752993e+12 | BB36: 275986.38 | BC36: 4033290.5 | BD36: 378423.7 | BE36: 790799.98 | BF36: 7575.884 | BG36: 17564.581 | BH36: 2437321.7 | BI36: 861869.24 | BJ36: 1354085.6 | BK36: 284265.45 | BL36: 279216.33 | BM36: 1149380.3 | BN36: 533450.56 | BO36: 118583.93 | BP36: 1273003.8 | BQ36: 749319.79 | BR36: 150405.9
B37: 2024 | C37: 588008.9 | D37: 13159344 | E37: 972266.97 | F37: 2009154.1 | G37: 27657.81 | H37: 66239.386 | I37: 5225596.7 | J37: 1761432.4 | K37: 2699253.5 | L37: 681371.72 | M37: 750015.58 | N37: 3109592.4 | O37: 878058.08 | P37: 476321.17 | Q37: 3536777.3 | R37: 1964318 | S37: 415217.71 | T37: 51751065 | U37: 1416499100 | V37: 123975371 | W37: 143533851 | X37: 3524788 | Y37: 26498823 | Z37: 381884256 | AA37: 658805744 | AB37: 520209090 | AC37: 116232057 | AD37: 191240258 | AE37: 579884282 | AF37: 1210812164 | AG37: 25408620 | AH37: 1928653696 | AI37: 583518010 | AJ37: 32484312 | AK37: 2.8499797e+12 | AL37: 3.4095631e+13 | AM37: 5.7161229e+12 | AN37: 6.0889972e+12 | AO37: 5.9366773e+10 | AP37: 1.6901309e+10 | AQ37: 2.8016074e+13 | AR37: 12234872446897 | AS37: 2.816821e+13 | AT37: 4.6859222e+12 | AU37: 2.6222383e+12 | AV37: 9.9834038e+12 | AW37: 6.1278988e+12 | AX37: 1.9045137e+11 | AY37: 1.7563606e+13 | AZ37: 9.3455062e+12 | BA37: 1.9008365e+12
A38: Projection | B38: 2025 | T38: =T37+T37*CGE_Frozen!S44 -> 51679317 | U38: =U37+U37*CGE_Frozen!T44 -> 1.4169734e+09 | V38: =V37+V37*CGE_Frozen!U44 -> 1.2335694e+08 | W38: =W37+W37*CGE_Frozen!V44 -> 1.4345589e+08 | X38: =X37+X37*CGE_Frozen!W44 -> 3573939.8 | Y38: =Y37+Y37*CGE_Frozen!X44 -> 26616891 | Z38: =Z37+Z37*CGE_Frozen!Y44 -> 3.8334964e+08 | AA38: =AA37+AA37*CGE_Frozen!Z44 -> 6.6322282e+08 | ... AJ38: =AJ37+AJ37*CGE_Frozen!AI44 -> 32726671 | AK38: =AK37+AK37*CGE_Frozen!S9 -> 2.9342787e+12 | AL38: =AL37+AL37*CGE_Frozen!T9 -> 3.5679246e+13 | AM38: =AM37+AM37*CGE_Frozen!U9 -> 5.8188448e+12 | AN38: =AN37+AN37*CGE_Frozen!V9 -> 6.1489747e+12 | AO38: =AO37+AO37*CGE_Frozen!W9 -> 6.1762266e+10 | AP38: =AP37+AP37*CGE_Frozen!X9 -> 1.7676873e+10 | AQ38: =AQ37+AQ37*CGE_Frozen!Y9 -> 2.8747018e+13 | AR38: =AR37+AR37*CGE_Frozen!Z9 -> 1.2644591e+13 | ... BA38: =BA37+BA37*CGE_Frozen!AI9 -> 1.9581415e+12
B39: 2026 | T39: =T38+T38*CGE_Frozen!S45 -> 51575156 | U39: =U38+U38*CGE_Frozen!T45 -> 1.4149773e+09 | V39: =V38+V38*CGE_Frozen!U45 -> 1.2272743e+08 | W39: =W38+W38*CGE_Frozen!V45 -> 1.4306708e+08 | X39: =X38+X38*CGE_Frozen!W45 -> 3617997.1 | Y39: =Y38+Y38*CGE_Frozen!X45 -> 26643812 | Z39: =Z38+Z38*CGE_Frozen!Y45 -> 3.8501466e+08 | AA39: =AA38+AA38*CGE_Frozen!Z45 -> 6.676347e+08 | ... AJ39: =AJ38+AJ38*CGE_Frozen!AI45 -> 32959236 | AK39: =AK38+AK38*CGE_Frozen!S10 -> 3.0011871e+12 | AL39: =AL38+AL38*CGE_Frozen!T10 -> 3.7132404e+13 | AM39: =AM38+AM38*CGE_Frozen!U10 -> 5.8866471e+12 | AN39: =AN38+AN38*CGE_Frozen!V10 -> 6.2520466e+12 | AO39: =AO38+AO38*CGE_Frozen!W10 -> 6.3642667e+10 | AP39: =AP38+AP38*CGE_Frozen!X10 -> 1.8475984e+10 | AQ39: =AQ38+AQ38*CGE_Frozen!Y10 -> 2.9373618e+13 | AR39: =AR38+AR38*CGE_Frozen!Z10 -> 1.3008017e+13 | ... BA39: =BA38+BA38*CGE_Frozen!AI10 -> 2.0084176e+12
B40: 2027 | T40: =T39+T39*CGE_Frozen!S46 -> 51470996 | U40: =U39+U39*CGE_Frozen!T46 -> 1.4129811e+09 | V40: =V39+V39*CGE_Frozen!U46 -> 1.2209792e+08 | W40: =W39+W39*CGE_Frozen!V46 -> 1.4267827e+08 | X40: =X39+X39*CGE_Frozen!W46 -> 3662054.4 | Y40: =Y39+Y39*CGE_Frozen!X46 -> 26670631 | Z40: =Z39+Z39*CGE_Frozen!Y46 -> 3.8667868e+08 | AA40: =AA39+AA39*CGE_Frozen!Z46 -> 6.7204658e+08 | ... AJ40: =AJ39+AJ39*CGE_Frozen!AI46 -> 33191698 | AK40: =AK39+AK39*CGE_Frozen!S11 -> 3.0812427e+12 | AL40: =AL39+AL39*CGE_Frozen!T11 -> 3.8634484e+13 | AM40: =AM39+AM39*CGE_Frozen!U11 -> 5.9593072e+12 | AN40: =AN39+AN39*CGE_Frozen!V11 -> 6.3122869e+12 | AO40: =AO39+AO39*CGE_Frozen!W11 -> 6.5924263e+10 | AP40: =AP39+AP39*CGE_Frozen!X11 -> 1.9387479e+10 | AQ40: =AQ39+AQ39*CGE_Frozen!Y11 -> 2.9986276e+13 | AR40: =AR39+AR39*CGE_Frozen!Z11 -> 1.3320738e+13 | ... BA40: =BA39+BA39*CGE_Frozen!AI11 -> 2.0630748e+12
B41: 2028 | T41: =T40+T40*CGE_Frozen!S47 -> 51366836 | U41: =U40+U40*CGE_Frozen!T47 -> 1.4109949e+09 | V41: =V40+V40*CGE_Frozen!U47 -> 1.2146841e+08 | W41: =W40+W40*CGE_Frozen!V47 -> 1.4228945e+08 | X41: =X40+X40*CGE_Frozen!W47 -> 3706111.7 | Y41: =Y40+Y40*CGE_Frozen!X47 -> 26697552 | Z41: =Z40+Z40*CGE_Frozen!Y47 -> 3.8834371e+08 | AA41: =AA40+AA40*CGE_Frozen!Z47 -> 6.764595e+08 | ... AJ41: =AJ40+AJ40*CGE_Frozen!AI47 -> 33424264 | AK41: =AK40+AK40*CGE_Frozen!S12 -> 3.1410837e+12 | AL41: =AL40+AL40*CGE_Frozen!T12 -> 4.0018933e+13 | AM41: =AM40+AM40*CGE_Frozen!U12 -> 6.0141917e+12 | AN41: =AN40+AN40*CGE_Frozen!V12 -> 6.4318806e+12 | AO41: =AO40+AO40*CGE_Frozen!W12 -> 6.7962733e+10 | AP41: =AP40+AP40*CGE_Frozen!X12 -> 2.0341724e+10 | AQ41: =AQ40+AQ40*CGE_Frozen!Y12 -> 3.0559685e+13 | AR41: =AR40+AR40*CGE_Frozen!Z12 -> 1.3669934e+13 | ... BA41: =BA40+BA40*CGE_Frozen!AI12 -> 2.1154138e+12
B42: 2029 | T42: =T41+T41*CGE_Frozen!S48 -> 51262675 | U42: =U41+U41*CGE_Frozen!T48 -> 1.4089987e+09 | V42: =V41+V41*CGE_Frozen!U48 -> 1.208389e+08 | W42: =W41+W41*CGE_Frozen!V48 -> 1.4190064e+08 | X42: =X41+X41*CGE_Frozen!W48 -> 3750158.8 | Y42: =Y41+Y41*CGE_Frozen!X48 -> 26724372 | Z42: =Z41+Z41*CGE_Frozen!Y48 -> 3.9000873e+08 | AA42: =AA41+AA41*CGE_Frozen!Z48 -> 6.8087138e+08 | ... AJ42: =AJ41+AJ41*CGE_Frozen!AI48 -> 33656726 | AK42: =AK41+AK41*CGE_Frozen!S13 -> 3.2151057e+12 | AL42: =AL41+AL41*CGE_Frozen!T13 -> 4.1468794e+13 | AM42: =AM41+AM41*CGE_Frozen!U13 -> 6.0829199e+12 | AN42: =AN41+AN41*CGE_Frozen!V13 -> 6.5021062e+12 | AO42: =AO41+AO41*CGE_Frozen!W13 -> 7.0359321e+10 | AP42: =AP41+AP41*CGE_Frozen!X13 -> 2.1380559e+10 | AQ42: =AQ41+AQ41*CGE_Frozen!Y13 -> 3.1141352e+13 | AR42: =AR41+AR41*CGE_Frozen!Z13 -> 1.3992659e+13 | ... BA42: =BA41+BA41*CGE_Frozen!AI13 -> 2.1713896e+12
B43: 2030 | T43: =T42+T42*CGE_Frozen!S49 -> 51158515 | U43: =U42+U42*CGE_Frozen!T49 -> 1.4070026e+09 | V43: =V42+V42*CGE_Frozen!U49 -> 1.2020939e+08 | W43: =W42+W42*CGE_Frozen!V49 -> 1.4151183e+08 | X43: =X42+X42*CGE_Frozen!W49 -> 3794216.1 | Y43: =Y42+Y42*CGE_Frozen!X49 -> 26751293 | Z43: =Z42+Z42*CGE_Frozen!Y49 -> 3.9167375e+08 | AA43: =AA42+AA42*CGE_Frozen!Z49 -> 6.8528429e+08 | ... AJ43: =AJ42+AJ42*CGE_Frozen!AI49 -> 33889188 | AK43: =AK42+AK42*CGE_Frozen!S14 -> 3.2752091e+12 | AL43: =AL42+AL42*CGE_Frozen!T14 -> 4.2825759e+13 | AM43: =AM42+AM42*CGE_Frozen!U14 -> 6.1458099e+12 | AN43: =AN42+AN42*CGE_Frozen!V14 -> 6.6146707e+12 | AO43: =AO42+AO42*CGE_Frozen!W14 -> 7.2501832e+10 | AP43: =AP42+AP42*CGE_Frozen!X14 -> 2.2439708e+10 | AQ43: =AQ42+AQ42*CGE_Frozen!Y14 -> 3.1706932e+13 | AR43: =AR42+AR42*CGE_Frozen!Z14 -> 1.436408e+13 | ... BA43: =BA42+BA42*CGE_Frozen!AI14 -> 2.2250366e+12
B44: 2031 | T44: =T43+T43*CGE_Frozen!S50 -> 51012510 | U44: =U43+U43*CGE_Frozen!T50 -> 1.4035538e+09 | V44: =V43+V43*CGE_Frozen!U50 -> 1.1954462e+08 | W44: =W43+W43*CGE_Frozen!V50 -> 1.4114966e+08 | X44: =X43+X43*CGE_Frozen!W50 -> 3837040.6 | Y44: =Y43+Y43*CGE_Frozen!X50 -> 26719936 | Z44: =Z43+Z43*CGE_Frozen!Y50 -> 3.9329885e+08 | AA44: =AA43+AA43*CGE_Frozen!Z50 -> 6.8897508e+08 | ... AJ44: =AJ43+AJ43*CGE_Frozen!AI50 -> 34104847 | AK44: =AK43+AK43*CGE_Frozen!S15 -> 3.339556e+12 | AL44: =AL43+AL43*CGE_Frozen!T15 -> 4.421314e+13 | AM44: =AM43+AM43*CGE_Frozen!U15 -> 6.2189711e+12 | AN44: =AN43+AN43*CGE_Frozen!V15 -> 6.7126186e+12 | AO44: =AO43+AO43*CGE_Frozen!W15 -> 7.4956464e+10 | AP44: =AP43+AP43*CGE_Frozen!X15 -> 2.3570814e+10 | AQ44: =AQ43+AQ43*CGE_Frozen!Y15 -> 3.2278196e+13 | AR44: =AR43+AR43*CGE_Frozen!Z15 -> 1.4746686e+13 | ... BA44: =BA43+BA43*CGE_Frozen!AI15 -> 2.2810655e+12
B45: 2032 | T45: =T44+T44*CGE_Frozen!S51 -> 50866504 | U45: =U44+U44*CGE_Frozen!T51 -> 1.4001149e+09 | V45: =V44+V44*CGE_Frozen!U51 -> 1.1888087e+08 | W45: =W44+W44*CGE_Frozen!V51 -> 1.4078848e+08 | X45: =X44+X44*CGE_Frozen!W51 -> 3879865 | Y45: =Y44+Y44*CGE_Frozen!X51 -> 26688579 | Z45: =Z44+Z44*CGE_Frozen!Y51 -> 3.9492295e+08 | AA45: =AA44+AA44*CGE_Frozen!Z51 -> 6.9266483e+08 | ... AJ45: =AJ44+AJ44*CGE_Frozen!AI51 -> 34320403 | AK45: =AK44+AK44*CGE_Frozen!S16 -> 3.3913729e+12 | AL45: =AL44+AL44*CGE_Frozen!T16 -> 4.5533093e+13 | AM45: =AM44+AM44*CGE_Frozen!U16 -> 6.2868605e+12 | AN45: =AN44+AN44*CGE_Frozen!V16 -> 6.8529713e+12 | AO45: =AO44+AO44*CGE_Frozen!W16 -> 7.7376782e+10 | AP45: =AP44+AP44*CGE_Frozen!X16 -> 2.475599e+10 | AQ45: =AQ44+AQ44*CGE_Frozen!Y16 -> 3.2831337e+13 | AR45: =AR44+AR44*CGE_Frozen!Z16 -> 1.5175709e+13 | ... BA45: =BA44+BA44*CGE_Frozen!AI16 -> 2.3366584e+12
B46: 2033 | T46: =T45+T45*CGE_Frozen!S52 -> 50720499 | U46: =U45+U45*CGE_Frozen!T52 -> 1.3966662e+09 | V46: =V45+V45*CGE_Frozen!U52 -> 1.1821711e+08 | W46: =W45+W45*CGE_Frozen!V52 -> 1.404273e+08 | X46: =X45+X45*CGE_Frozen!W52 -> 3922689.4 | Y46: =Y45+Y45*CGE_Frozen!X52 -> 26657221 | Z46: =Z45+Z45*CGE_Frozen!Y52 -> 3.9654804e+08 | AA46: =AA45+AA45*CGE_Frozen!Z52 -> 6.9635561e+08 | ... AJ46: =AJ45+AJ45*CGE_Frozen!AI52 -> 34535959 | AK46: =AK45+AK45*CGE_Frozen!S17 -> 3.4527416e+12 | AL46: =AL45+AL45*CGE_Frozen!T17 -> 4.6889326e+13 | AM46: =AM45+AM45*CGE_Frozen!U17 -> 6.3643567e+12 | AN46: =AN45+AN45*CGE_Frozen!V17 -> 6.9623169e+12 | AO46: =AO45+AO45*CGE_Frozen!W17 -> 8.0010657e+10 | AP46: =AP45+AP45*CGE_Frozen!X17 -> 2.6032426e+10 | AQ46: =AQ45+AQ45*CGE_Frozen!Y17 -> 3.3389625e+13 | AR46: =AR45+AR45*CGE_Frozen!Z17 -> 1.5597089e+13 | ... BA46: =BA45+BA45*CGE_Frozen!AI17 -> 2.3941017e+12
B47: 2034 | T47: =T46+T46*CGE_Frozen!S53 -> 50574494 | U47: =U46+U46*CGE_Frozen!T53 -> 1.3932174e+09 | V47: =V46+V46*CGE_Frozen!U53 -> 1.1755235e+08 | W47: =W46+W46*CGE_Frozen!V53 -> 1.4006513e+08 | X47: =X46+X46*CGE_Frozen!W53 -> 3965513.9 | Y47: =Y46+Y46*CGE_Frozen!X53 -> 26625864 | Z47: =Z46+Z46*CGE_Frozen!Y53 -> 3.9817214e+08 | AA47: =AA46+AA46*CGE_Frozen!Z53 -> 7.000464e+08 | ... AJ47: =AJ46+AJ46*CGE_Frozen!AI53 -> 34751515 | AK47: =AK46+AK46*CGE_Frozen!S18 -> 3.4993584e+12 | AL47: =AL46+AL46*CGE_Frozen!T18 -> 4.8128111e+13 | AM47: =AM46+AM46*CGE_Frozen!U18 -> 6.4317016e+12 | AN47: =AN46+AN46*CGE_Frozen!V18 -> 7.1124577e+12 | AO47: =AO46+AO46*CGE_Frozen!W18 -> 8.2508001e+10 | AP47: =AP46+AP46*CGE_Frozen!X18 -> 2.7345447e+10 | AQ47: =AQ46+AQ46*CGE_Frozen!Y18 -> 3.3931399e+13 | AR47: =AR46+AR46*CGE_Frozen!Z18 -> 1.6062049e+13 | ... BA47: =BA46+BA46*CGE_Frozen!AI18 -> 2.4508324e+12
B48: 2035 | T48: =T47+T47*CGE_Frozen!S54 -> 50428489 | U48: =U47+U47*CGE_Frozen!T54 -> 1.3897785e+09 | V48: =V47+V47*CGE_Frozen!U54 -> 1.1688859e+08 | W48: =W47+W47*CGE_Frozen!V54 -> 1.3970395e+08 | X48: =X47+X47*CGE_Frozen!W54 -> 4008338.3 | Y48: =Y47+Y47*CGE_Frozen!X54 -> 26594507 | Z48: =Z47+Z47*CGE_Frozen!Y54 -> 3.9979723e+08 | AA48: =AA47+AA47*CGE_Frozen!Z54 -> 7.0373718e+08 | ... AJ48: =AJ47+AJ47*CGE_Frozen!AI54 -> 34967071 | AK48: =AK47+AK47*CGE_Frozen!S19 -> 3.5546165e+12 | AL48: =AL47+AL47*CGE_Frozen!T19 -> 4.936543e+13 | AM48: =AM47+AM47*CGE_Frozen!U19 -> 6.5047429e+12 | AN48: =AN47+AN47*CGE_Frozen!V19 -> 7.2236427e+12 | AO48: =AO47+AO47*CGE_Frozen!W19 -> 8.5157208e+10 | AP48: =AP47+AP47*CGE_Frozen!X19 -> 2.8743968e+10 | AQ48: =AQ47+AQ47*CGE_Frozen!Y19 -> 3.4482609e+13 | AR48: =AR47+AR47*CGE_Frozen!Z19 -> 1.651106e+13 | ... BA48: =BA47+BA47*CGE_Frozen!AI19 -> 2.5092858e+12
B49: 2036 | T49: =T48+T48*CGE_Frozen!S55 -> 50222275 | U49: =U48+U48*CGE_Frozen!T55 -> 1.3851933e+09 | V49: =V48+V48*CGE_Frozen!U55 -> 1.162067e+08 | W49: =W48+W48*CGE_Frozen!V55 -> 1.3943159e+08 | X49: =X48+X48*CGE_Frozen!W55 -> 4051325.8 | Y49: =Y48+Y48*CGE_Frozen!X55 -> 26534213 | Z49: =Z48+Z48*CGE_Frozen!Y55 -> 4.013225e+08 | AA49: =AA48+AA48*CGE_Frozen!Z55 -> 7.0661843e+08 | ... AJ49: =AJ48+AJ48*CGE_Frozen!AI55 -> 35170154 | AK49: =AK48+AK48*CGE_Frozen!S20 -> 3.5968971e+12 | AL49: =AL48+AL48*CGE_Frozen!T20 -> 5.0464598e+13 | AM49: =AM48+AM48*CGE_Frozen!U20 -> 6.5663695e+12 | AN49: =AN48+AN48*CGE_Frozen!V20 -> 7.3675756e+12 | AO49: =AO48+AO48*CGE_Frozen!W20 -> 8.7646521e+10 | AP49: =AP48+AP48*CGE_Frozen!X20 -> 3.0189484e+10 | AQ49: =AQ48+AQ48*CGE_Frozen!Y20 -> 3.5019128e+13 | AR49: =AR48+AR48*CGE_Frozen!Z20 -> 1.6999508e+13 | ... BA49: =BA48+BA48*CGE_Frozen!AI20 -> 2.5670906e+12
B50: 2037 | T50: =T49+T49*CGE_Frozen!S56 -> 50016062 | U50: =U49+U49*CGE_Frozen!T56 -> 1.3806081e+09 | V50: =V49+V49*CGE_Frozen!U56 -> 1.1552482e+08 | W50: =W49+W49*CGE_Frozen!V56 -> 1.3916021e+08 | X50: =X49+X49*CGE_Frozen!W56 -> 4094313.2 | Y50: =Y49+Y49*CGE_Frozen!X56 -> 26473919 | Z50: =Z49+Z49*CGE_Frozen!Y56 -> 4.0284778e+08 | AA50: =AA49+AA49*CGE_Frozen!Z56 -> 7.0950072e+08 | ... AJ50: =AJ49+AJ49*CGE_Frozen!AI56 -> 35373133 | AK50: =AK49+AK49*CGE_Frozen!S21 -> 3.6469241e+12 | AL50: =AL49+AL49*CGE_Frozen!T21 -> 5.1562483e+13 | AM50: =AM49+AM49*CGE_Frozen!U21 -> 6.6328539e+12 | AN50: =AN49+AN49*CGE_Frozen!V21 -> 7.4811912e+12 | AO50: =AO49+AO49*CGE_Frozen!W21 -> 9.0295363e+10 | AP50: =AP49+AP49*CGE_Frozen!X21 -> 3.1746373e+10 | AQ50: =AQ49+AQ49*CGE_Frozen!Y21 -> 3.5560687e+13 | AR50: =AR49+AR49*CGE_Frozen!Z21 -> 1.7482487e+13 | ... BA50: =BA49+BA49*CGE_Frozen!AI21 -> 2.6263628e+12
... B63: 2050 | T63: =T62+T62*CGE_Frozen!S69 -> 46624727 | U63: =U62+U62*CGE_Frozen!T69 -> 1.2979461e+09 | V63: =V62+V62*CGE_Frozen!U69 -> 1.0674692e+08 | W63: =W62+W62*CGE_Frozen!V69 -> 1.3692898e+08 | X63: =X62+X62*CGE_Frozen!W69 -> 4648198.3 | Y63: =Y62+Y62*CGE_Frozen!X69 -> 25419576 | Z63: =Z62+Z62*CGE_Frozen!Y69 -> 4.2110314e+08 | AA63: =AA62+AA62*CGE_Frozen!Z69 -> 7.3470877e+08 | ... AJ63: =AJ62+AJ62*CGE_Frozen!AI69 -> 37981349 | AK63: =AK62+AK62*CGE_Frozen!S34 -> 4.0890658e+12 | AL63: =AL62+AL62*CGE_Frozen!T34 -> 6.4352879e+13 | AM63: =AM62+AM62*CGE_Frozen!U34 -> 7.4835907e+12 | AN63: =AN62+AN62*CGE_Frozen!V34 -> 9.236075e+12 | AO63: =AO62+AO62*CGE_Frozen!W34 -> 1.2899635e+11 | AP63: =AP62+AP62*CGE_Frozen!X34 -> 5.8307261e+10 | AQ63: =AQ62+AQ62*CGE_Frozen!Y34 -> 4.2429476e+13 | AR63: =AR62+AR62*CGE_Frozen!Z34 -> 2.5196638e+13 | ... BA63: =BA62+BA62*CGE_Frozen!AI34 -> 3.4604697e+12

Sheet KAYA
B1: P | S1: GDP/P | AJ1: TES/GDP | BA1: E/PES
B2: 01_KOR | C2: 02_CHN | D2: 03_JPN | E2: 04_RUS | F2: 05_MNG | G2: 06_PRK | H2: 07_NAM | I2: 08_LAM | J2: 09_WEU | K2: 10_EEU | L2: 11_RFSU | M2: 12_MEA | N2: 13_AFR | O2: 14_RCPA | P2: 15_SAS | Q2: 16_RPAS | R2: 17_RPAO | S2: 01_KOR | T2: 02_CHN | U2: 03_JPN | V2: 04_RUS | W2: 05_MNG | X2: 06_PRK | Y2: 07_NAM | Z2: 08_LAM | AA2: 09_WEU | AB2: 10_EEU | AC2: 11_RFSU | AD2: 12_MEA | AE2: 13_AFR | AF2: 14_RCPA | AG2: 15_SAS | AH2: 16_RPAS | AI2: 17_RPAO | AJ2: 01_KOR | AK2: 02_CHN | AL2: 03_JPN | AM2: 04_RUS | AN2: 05_MNG | AO2: 06_PRK | AP2: 07_NAM | AQ2: 08_LAM | AR2: 09_WEU | AS2: 10_EEU | AT2: 11_RFSU | AU2: 12_MEA | AV2: 13_AFR | AW2: 14_RCPA | AX2: 15_SAS | AY2: 16_RPAS | AZ2: 17_RPAO | BA2: 01_KOR | BB2: 02_CHN | BC2: 03_JPN | BD2: 04_RUS | BE2: 05_MNG | BF2: 06_PRK | BG2: 07_NAM | BH2: 08_LAM | BI2: 09_WEU | BJ2: 10_EEU | BK2: 11_RFSU | BL2: 12_MEA | BM2: 13_AFR | BN2: 14_RCPA | BO2: 15_SAS | BP2: 16_RPAS | BQ2: 17_RPAO
A3: 1990 | B3: =Data!T3 -> 42869283 | C3: =Data!U3 -> 1140889500 | D3: =Data!V3 -> 123478000 | E3: =Data!W3 -> 147969406 | F3: =Data!X3 -> 2098710 | G3: =Data!Y3 -> 21112137 | H3: =Data!Z3 -> 277759852 | I3: =Data!AA3 -> 437248525 | ... R3: =Data!AJ3 -> 20394928 | S3: =Data!AK3/Data!T3 -> 14377.884 | T3: =Data!AL3/Data!U3 -> 1816.5883 | U3: =Data!AM3/Data!V3 -> 35272.419 | V3: =Data!AN3/Data!W3 -> 29643.595 | W3: =Data!AO3/Data!X3 -> 6637.8193 | X3: =Data!AP3/Data!Y3 -> 927.10206 | Y3: =Data!AQ3/Data!Z3 -> 43918.162 | Z3: =Data!AR3/Data!AA3 -> 11505.651 | ... AZ3: =Data!BR3/Data!BA3 -> 1.3743571e-07 | BA3: =Data!C3/Data!BB3 -> 2.9072364 | BB3: =Data!D3/Data!BC3 -> 2.7608578 | BC3: =Data!E3/Data!BD3 -> 2.6602201 | BD3: =Data!F3/Data!BE3 -> 2.7705832 | BE3: =Data!G3/Data!BF3 -> 3.763041 | BF3: =Data!H3/Data!BG3 -> 3.9722047 | BG3: =Data!I3/Data!BH3 -> 2.5602181 | BH3: =Data!J3/Data!BI3 -> 2.0716791 | ... BQ3: =Data!S3/Data!BR3 -> 3.0542257
A4: 1991 | B4: =Data!T4 -> 43295704 | C4: =Data!U4 -> 1156532000 | D4: =Data!V4 -> 123964000 | E4: =Data!W4 -> 148394216 | F4: =Data!X4 -> 2165342 | G4: =Data!Y4 -> 21428638 | H4: =Data!Z4 -> 281470059 | I4: =Data!AA4 -> 445392924 | ... R4: =Data!AJ4 -> 20779136 | S4: =Data!AK4/Data!T4 -> 15784.467 | T4: =Data!AL4/Data!U4 -> 1954.0777 | U4: =Data!AM4/Data!V4 -> 36372.035 | V4: =Data!AN4/Data!W4 -> 28066.922 | W4: =Data!AO4/Data!X4 -> 5874.2556 | X4: =Data!AP4/Data!Y4 -> 873.06188 | Y4: =Data!AQ4/Data!Z4 -> 43213.359 | Z4: =Data!AR4/Data!AA4 -> 11671.571 | ... AZ4: =Data!BR4/Data!BA4 -> 1.3712584e-07 | BA4: =Data!C4/Data!BB4 -> 2.9879822 | BB4: =Data!D4/Data!BC4 -> 3.0029572 | BC4: =Data!E4/Data!BD4 -> 2.6551334 | BD4: =Data!F4/Data!BE4 -> 2.7468704 | BE4: =Data!G4/Data!BF4 -> 3.8853655 | BF4: =Data!H4/Data!BG4 -> 4.0031774 | BG4: =Data!I4/Data!BH4 -> 2.5186565 | BH4: =Data!J4/Data!BI4 -> 2.0842148 | ... BQ4: =Data!S4/Data!BR4 -> 3.1034345
A5: 1992 | B5: =Data!T5 -> 43747962 | C5: =Data!U5 -> 1170770500 | D5: =Data!V5 -> 124425000 | E5: =Data!W5 -> 148538197 | F5: =Data!X5 -> 2167790 | G5: =Data!Y5 -> 21750911 | H5: =Data!Z5 -> 285342295 | I5: =Data!AA5 -> 453484566 | ... R5: =Data!AJ5 -> 21010335 | S5: =Data!AK5/Data!T5 -> 16613.491 | T5: =Data!AL5/Data!U5 -> 2193.2156 | U5: =Data!AM5/Data!V5 -> 36563.623 | V5: =Data!AN5/Data!W5 -> 23965.245 | W5: =Data!AO5/Data!X5 -> 5324.4876 | X5: =Data!AP5/Data!Y5 -> 799.19485 | Y5: =Data!AQ5/Data!Z5 -> 44027.243 | Z5: =Data!AR5/Data!AA5 -> 11788.387 | ... AZ5: =Data!BR5/Data!BA5 -> 1.3901184e-07 | BA5: =Data!C5/Data!BB5 -> 2.8829574 | BB5: =Data!D5/Data!BC5 -> 3.0383029 | BC5: =Data!E5/Data!BD5 -> 2.6092885 | BD5: =Data!F5/Data!BE5 -> 2.7716229 | BE5: =Data!G5/Data!BF5 -> 3.8760942 | BF5: =Data!H5/Data!BG5 -> 4.0502467 | BG5: =Data!I5/Data!BH5 -> 2.5101205 | BH5: =Data!J5/Data!BI5 -> 2.0669423 | ... BQ5: =Data!S5/Data!BR5 -> 3.0953483
A6: 1993 | B6: =Data!T6 -> 44194628 | C6: =Data!U6 -> 1184341000 | D6: =Data!V6 -> 124829000 | E6: =Data!W6 -> 148458777 | F6: =Data!X6 -> 2165130 | G6: =Data!Y6 -> 22073352 | H6: =Data!Z6 -> 289066123 | I6: =Data!AA6 -> 461533132 | ... R6: =Data!AJ6 -> 21207008 | S6: =Data!AK6/Data!T6 -> 17595.904 | T6: =Data!AL6/Data!U6 -> 2456.8717 | U6: =Data!AM6/Data!V6 -> 36277.923 | V6: =Data!AN6/Data!W6 -> 21899.517 | W6: =Data!AO6/Data!X6 -> 5162.0999 | X6: =Data!AP6/Data!Y6 -> 752.2481 | Y6: =Data!AQ6/Data!Z6 -> 44652.401 | Z6: =Data!AR6/Data!AA6 -> 12128.336 | ... AZ6: =Data!BR6/Data!BA6 -> 1.4012804e-07 | BA6: =Data!C6/Data!BB6 -> 2.8005775 | BB6: =Data!D6/Data!BC6 -> 3.106124 | BC6: =Data!E6/Data!BD6 -> 2.5770712 | BD6: =Data!F6/Data!BE6 -> 2.6795959 | BE6: =Data!G6/Data!BF6 -> 3.8213794 | BF6: =Data!H6/Data!BG6 -> 4.0804946 | BG6: =Data!I6/Data!BH6 -> 2.5162673 | BH6: =Data!J6/Data!BI6 -> 2.1201968 | ... BQ6: =Data!S6/Data!BR6 -> 2.9791591
A7: 1994 | B7: =Data!T7 -> 44641540 | C7: =Data!U7 -> 1197870400 | D7: =Data!V7 -> 125178000 | E7: =Data!W7 -> 148407912 | F7: =Data!X7 -> 2189395 | G7: =Data!Y7 -> 22393975 | H7: =Data!Z7 -> 292594524 | I7: =Data!AA7 -> 469500872 | ... R7: =Data!AJ7 -> 21425468 | S7: =Data!AK7/Data!T7 -> 19052.299 | T7: =Data!AL7/Data!U7 -> 2734.0469 | U7: =Data!AM7/Data!V7 -> 36568.712 | V7: =Data!AN7/Data!W7 -> 19153.363 | W7: =Data!AO7/Data!X7 -> 5213.8463 | X7: =Data!AP7/Data!Y7 -> 725.82721 | Y7: =Data!AQ7/Data!Z7 -> 45909.361 | Z7: =Data!AR7/Data!AA7 -> 12562.439 | ... AZ7: =Data!BR7/Data!BA7 -> 1.3531767e-07 | BA7: =Data!C7/Data!BB7 -> 2.8478035 | BB7: =Data!D7/Data!BC7 -> 3.1161286 | BC7: =Data!E7/Data!BD7 -> 2.555749 | BD7: =Data!F7/Data!BE7 -> 2.762249 | BE7: =Data!G7/Data!BF7 -> 3.8599315 | BF7: =Data!H7/Data!BG7 -> 4.0839023 | BG7: =Data!I7/Data!BH7 -> 2.5105261 | BH7: =Data!J7/Data!BI7 -> 2.1315771 | ... BQ7: =Data!S7/Data!BR7 -> 3.0182603
A8: 1995 | B8: =Data!T8 -> 45092991 | C8: =Data!U8 -> 1211011100 | D8: =Data!V8 -> 125472000 | E8: =Data!W8 -> 148375787 | F8: =Data!X8 -> 2224945 | G8: =Data!Y8 -> 22669304 | H8: =Data!Z8 -> 296054001 | I8: =Data!AA8 -> 477446311 | ... R8: =Data!AJ8 -> 21678282 | S8: =Data!AK8/Data!T8 -> 20697.897 | T8: =Data!AL8/Data!U8 -> 2986.4506 | U8: =Data!AM8/Data!V8 -> 37442.895 | V8: =Data!AN8/Data!W8 -> 18363.714 | W8: =Data!AO8/Data!X8 -> 5457.685 | X8: =Data!AP8/Data!Y8 -> 685.64684 | Y8: =Data!AQ8/Data!Z8 -> 46590.817 | Z8: =Data!AR8/Data!AA8 -> 12454.658 | ... AZ8: =Data!BR8/Data!BA8 -> 1.3185055e-07 | BA8: =Data!C8/Data!BB8 -> 2.7912555 | BB8: =Data!D8/Data!BC8 -> 3.203859 | BC8: =Data!E8/Data!BD8 -> 2.5100841 | BD8: =Data!F8/Data!BE8 -> 2.7774406 | BE8: =Data!G8/Data!BF8 -> 3.8590203 | BF8: =Data!H8/Data!BG8 -> 4.0528179 | BG8: =Data!I8/Data!BH8 -> 2.5074841 | BH8: =Data!J8/Data!BI8 -> 2.1488559 | ... BQ8: =Data!S8/Data!BR8 -> 3.0825508
A9: 1996 | B9: =Data!T9 -> 45524681 | C9: =Data!U9 -> 1223985500 | D9: =Data!V9 -> 125757000 | E9: =Data!W9 -> 148160129 | F9: =Data!X9 -> 2259507 | G9: =Data!Y9 -> 22895746 | H9: =Data!Z9 -> 299485254 | I9: =Data!AA9 -> 485330003 | ... R9: =Data!AJ9 -> 21956767 | S9: =Data!AK9/Data!T9 -> 22139.796 | T9: =Data!AL9/Data!U9 -> 3238.6692 | U9: =Data!AM9/Data!V9 -> 38528.791 | V9: =Data!AN9/Data!W9 -> 17699.869 | W9: =Data!AO9/Data!X9 -> 5494.3213 | X9: =Data!AP9/Data!Y9 -> 656.10675 | Y9: =Data!AQ9/Data!Z9 -> 47709.792 | Z9: =Data!AR9/Data!AA9 -> 12744.342 | ... AZ9: =Data!BR9/Data!BA9 -> 1.3524435e-07 | BA9: =Data!C9/Data!BB9 -> 2.7703979 | BB9: =Data!D9/Data!BC9 -> 3.1023369 | BC9: =Data!E9/Data!BD9 -> 2.4829702 | BD9: =Data!F9/Data!BE9 -> 2.7400034 | BE9: =Data!G9/Data!BF9 -> 3.8762592 | BF9: =Data!H9/Data!BG9 -> 4.0897458 | BG9: =Data!I9/Data!BH9 -> 2.5254731 | BH9: =Data!J9/Data!BI9 -> 2.1959756 | ... BQ9: =Data!S9/Data!BR9 -> 2.9902061
A10: 1997 | B10: =Data!T10 -> 45953580 | C10: =Data!U10 -> 1236564300 | D10: =Data!V10 -> 126057000 | E10: =Data!W10 -> 147915361 | F10: =Data!X10 -> 2291750 | G10: =Data!Y10 -> 23110830 | H10: =Data!Z10 -> 303052655 | I10: =Data!AA10 -> 493156466 | ... R10: =Data!AJ10 -> 22204337 | S10: =Data!AK10/Data!T10 -> 23311.042 | T10: =Data!AL10/Data!U10 -> 3495.2211 | U10: =Data!AM10/Data!V10 -> 38814.254 | V10: =Data!AN10/Data!W10 -> 17977.352 | W10: =Data!AO10/Data!X10 -> 5628.1066 | X10: =Data!AP10/Data!Y10 -> 607.85863 | Y10: =Data!AQ10/Data!Z10 -> 49238.081 | Z10: =Data!AR10/Data!AA10 -> 13230.707 | ... AZ10: =Data!BR10/Data!BA10 -> 1.339324e-07 | BA10: =Data!C10/Data!BB10 -> 2.7167563 | BB10: =Data!D10/Data!BC10 -> 3.1895873 | BC10: =Data!E10/Data!BD10 -> 2.4293223 | BD10: =Data!F10/Data!BE10 -> 2.6695676 | BE10: =Data!G10/Data!BF10 -> 3.8846303 | BF10: =Data!H10/Data!BG10 -> 4.1635776 | BG10: =Data!I10/Data!BH10 -> 2.6223812 | BH10: =Data!J10/Data!BI10 -> 2.2239474 | ... BQ10: =Data!S10/Data!BR10 -> 3.0087538
